WARNING:root:Spider warnings
INFO:scrapy.utils.log:Scrapy 2.0.1 started (bot: shopscrap)
INFO:scrapy.utils.log:Versions: lxml 4.5.0.0, libxml2 2.9.10, cssselect 1.1.0, parsel 1.5.2, w3lib 1.21.0, Twisted 20.3.0, Python 3.6.9 (default, Apr 18 2020, 01:56:04) - [GCC 8.4.0], pyOpenSSL 19.1.0 (OpenSSL 1.1.1f  31 Mar 2020), cryptography 2.9, Platform Linux-5.3.0-51-generic-x86_64-with-Ubuntu-18.04-bionic
DEBUG:scrapy.utils.log:Using reactor: twisted.internet.epollreactor.EPollReactor
INFO:scrapy.crawler:Overridden settings:
{'BOT_NAME': 'shopscrap',
 'DUPEFILTER_CLASS': 'scrapy_splash.SplashAwareDupeFilter',
 'HTTPCACHE_STORAGE': 'scrapy_splash.SplashAwareFSCacheStorage',
 'NEWSPIDER_MODULE': 'shopscrap.spiders',
 'SPIDER_MODULES': ['shopscrap.spiders'],
 'USER_AGENT': 'Mozilla/5.0 (X11; Linux x86_64) AppleWebKit/537.36 (KHTML, '
               'like Gecko) Brave Chrome/80.0.3987.163 Safari/537.36'}
INFO:scrapy.extensions.telnet:Telnet Password: ca13736d25a1239d
INFO:scrapy.middleware:Enabled extensions:
['scrapy.extensions.corestats.CoreStats',
 'scrapy.extensions.telnet.TelnetConsole',
 'scrapy.extensions.memusage.MemoryUsage',
 'scrapy.extensions.logstats.LogStats']
INFO:scrapy.middleware:Enabled downloader middlewares:
['scrapy.downloadermiddlewares.httpauth.HttpAuthMiddleware',
 'scrapy.downloadermiddlewares.downloadtimeout.DownloadTimeoutMiddleware',
 'scrapy.downloadermiddlewares.defaultheaders.DefaultHeadersMiddleware',
 'scrapy.downloadermiddlewares.useragent.UserAgentMiddleware',
 'scrapy.downloadermiddlewares.retry.RetryMiddleware',
 'scrapy.downloadermiddlewares.redirect.MetaRefreshMiddleware',
 'scrapy.downloadermiddlewares.redirect.RedirectMiddleware',
 'scrapy.downloadermiddlewares.cookies.CookiesMiddleware',
 'scrapy_splash.SplashCookiesMiddleware',
 'scrapy_splash.SplashMiddleware',
 'scrapy.downloadermiddlewares.httpproxy.HttpProxyMiddleware',
 'scrapy.downloadermiddlewares.httpcompression.HttpCompressionMiddleware',
 'scrapy.downloadermiddlewares.stats.DownloaderStats']
INFO:scrapy.middleware:Enabled spider middlewares:
['scrapy.spidermiddlewares.httperror.HttpErrorMiddleware',
 'scrapy_splash.SplashDeduplicateArgsMiddleware',
 'scrapy.spidermiddlewares.offsite.OffsiteMiddleware',
 'scrapy.spidermiddlewares.referer.RefererMiddleware',
 'scrapy.spidermiddlewares.urllength.UrlLengthMiddleware',
 'scrapy.spidermiddlewares.depth.DepthMiddleware']
INFO:scrapy.middleware:Enabled item pipelines:
['shopscrap.pipelines.ShopScrapdb']
INFO:scrapy.core.engine:Spider opened
INFO:scrapy.extensions.logstats:Crawled 0 pages (at 0 pages/min), scraped 0 items (at 0 items/min)
INFO:scrapy.extensions.telnet:Telnet console listening on 127.0.0.1:6029
WARNING:py.warnings:/home/user/.local/lib/python3.6/site-packages/scrapy_splash/request.py:41: ScrapyDeprecationWarning: Call to deprecated function to_native_str. Use to_unicode instead.
  url = to_native_str(url)

DEBUG:scrapy.core.engine:Crawled (200) <GET https://groceries.asda.com/product/cornflakes-honey-nut/kelloggs-crunchy-nut-corn-flakes/19140/ via http://0.0.0.0:8050/render.html> (referer: None)
DEBUG:scrapy.core.scraper:Scraped from <200 https://groceries.asda.com/product/cornflakes-honey-nut/kelloggs-crunchy-nut-corn-flakes/19140/>
{'Carbohydrate': '82g',
 'Date': datetime.datetime(2020, 5, 6, 9, 10, 37, 969176),
 'Energy': '1683kJ',
 'Fat': '4.5g',
 'Fibre': '2.5g',
 'Name': "Kellogg's Crunchy Nut Corn Flakes",
 'Price': '£2.00',
 'Protein': '6g',
 'Salt': '0.75g',
 'Saturates': '0.7g',
 'Sugars': '35g',
 'Supermarket': 'Asda',
 'item_url': 'https://groceries.asda.com/product/cornflakes-honey-nut/kelloggs-crunchy-nut-corn-flakes/19140/'}
DEBUG:scrapy.core.engine:Crawled (200) <GET https://groceries.asda.com/product/1639642 via http://0.0.0.0:8050/render.html> (referer: None)
DEBUG:scrapy.core.engine:Crawled (200) <GET https://groceries.asda.com/product/910000396129 via http://0.0.0.0:8050/render.html> (referer: None)
DEBUG:scrapy.core.engine:Crawled (200) <GET https://groceries.asda.com/product/24076 via http://0.0.0.0:8050/render.html> (referer: None)
DEBUG:scrapy.core.engine:Crawled (200) <GET https://groceries.asda.com/product/80975593 via http://0.0.0.0:8050/render.html> (referer: None)
DEBUG:scrapy.core.engine:Crawled (200) <GET https://groceries.asda.com/product/1217550 via http://0.0.0.0:8050/render.html> (referer: None)
DEBUG:scrapy.core.engine:Crawled (200) <GET https://groceries.asda.com/product/25857 via http://0.0.0.0:8050/render.html> (referer: None)
DEBUG:scrapy.core.scraper:Scraped from <200 https://groceries.asda.com/product/1639642>
{'Carbohydrate': '64.9g',
 'Date': datetime.datetime(2020, 5, 6, 9, 10, 49, 383170),
 'Energy': '2065kJ',
 'Fat': '23.7g',
 'Name': 'Twix Chocolate Biscuit Fingers Multipack',
 'Price': '£2.00',
 'Protein': '4.4g',
 'Salt': '0.41g',
 'Saturates': '13.7g',
 'Sugars': '49.1g',
 'Supermarket': 'Asda',
 'item_url': 'https://groceries.asda.com/product/1639642'}
DEBUG:scrapy.dupefilters:Filtered duplicate request: <GET https://groceries.asda.com/product/80975593> - no more duplicates will be shown (see DUPEFILTER_DEBUG to show all duplicates)
DEBUG:scrapy.core.scraper:Scraped from <200 https://groceries.asda.com/product/910000396129>
{'Carbohydrate': '86g',
 'Date': datetime.datetime(2020, 5, 6, 9, 10, 49, 428755),
 'Energy': '387kcal',
 'Fat': '1.2g',
 'Fibre': '2.0g',
 'Name': "Kellogg's Rice Krispies",
 'Price': '£3.00',
 'Protein': '7g',
 'Salt': '1g',
 'Saturates': '0.4g',
 'Sugars': '7.9g',
 'Supermarket': 'Asda',
 'item_url': 'https://groceries.asda.com/product/910000396129'}
DEBUG:scrapy.core.scraper:Scraped from <200 https://groceries.asda.com/product/24076>
{'Carbohydrate': '28g',
 'Date': datetime.datetime(2020, 5, 6, 9, 10, 49, 494930),
 'Energy': '566kJ 134kcal',
 'Fat': '0.9g',
 'Fibre': '0.7g',
 'Name': "Uncle Ben's Long Grain Microwave Rice",
 'Price': '£1.00',
 'Protein': '2.7g',
 'Salt': '<0.01g',
 'Saturates': '0.1g',
 'Sugars': '<0.5g',
 'Supermarket': 'Asda',
 'item_url': 'https://groceries.asda.com/product/24076'}
DEBUG:scrapy.core.scraper:Scraped from <200 https://groceries.asda.com/product/80975593>
{'Carbohydrate': '53.5',
 'Date': datetime.datetime(2020, 5, 6, 9, 10, 49, 533232),
 'Energy': '2360/566',
 'Fat': '35',
 'Name': 'Kinder Chocolate Bar 16 Pack',
 'Price': '£1.50',
 'Protein': '8.7',
 'Salt': '0.313',
 'Supermarket': 'Asda',
 'item_url': 'https://groceries.asda.com/product/80975593'}
DEBUG:scrapy.core.scraper:Scraped from <200 https://groceries.asda.com/product/1217550>
{'Carbohydrate': '79g',
 'Date': datetime.datetime(2020, 5, 6, 9, 10, 49, 580719),
 'Energy': '1588kJ',
 'Fat': '1.5g',
 'Fibre': '4.5g',
 'Name': "Kellogg's Special K Original",
 'Price': '£3.98',
 'Protein': '9g',
 'Salt': '1g',
 'Saturates': '0.3g',
 'Sugars': '15g',
 'Supermarket': 'Asda',
 'item_url': 'https://groceries.asda.com/product/1217550'}
DEBUG:scrapy.core.scraper:Scraped from <200 https://groceries.asda.com/product/25857>
{'Carbohydrate': '41.2 g',
 'Date': datetime.datetime(2020, 5, 6, 9, 10, 49, 616669),
 'Energy': '954 kJ / 226 kcal',
 'Fat': '3.5 g',
 'Fibre': '1.5 g',
 'Name': 'Old El Paso Mexican Original Smoky BBQ Fajita Kit',
 'Price': '£3.18',
 'Protein': '6.6 g',
 'Salt': '1.99 g',
 'Saturates': '0.8 g',
 'Sugars': '6.2 g',
 'Supermarket': 'Asda',
 'item_url': 'https://groceries.asda.com/product/25857'}
DEBUG:scrapy.core.engine:Crawled (200) <GET https://groceries.asda.com/product/910000020309 via http://0.0.0.0:8050/render.html> (referer: None)
DEBUG:scrapy.core.scraper:Scraped from <200 https://groceries.asda.com/product/910000020309>
{'Carbohydrate': '1.4 g',
 'Date': datetime.datetime(2020, 5, 6, 9, 10, 50, 472825),
 'Energy': '726 kcal',
 'Fat': '79 g',
 'Name': "Hellmann's Squeezy Real Mayonnaise",
 'Price': '£1.99',
 'Protein': '1.1 g',
 'Salt': '1.5 g',
 'Saturates': '6.3 g',
 'Sugars': '1.3 g',
 'Supermarket': 'Asda',
 'item_url': 'https://groceries.asda.com/product/910000020309'}
DEBUG:scrapy.core.engine:Crawled (200) <GET https://groceries.asda.com/product/910000057722 via http://0.0.0.0:8050/render.html> (referer: None)
DEBUG:scrapy.core.scraper:Scraped from <200 https://groceries.asda.com/product/910000057722>
{'Carbohydrate': '1.3 g',
 'Date': datetime.datetime(2020, 5, 6, 9, 10, 51, 633638),
 'Energy': '721 kcal',
 'Fat': '79 g',
 'Name': "Hellmann's Real Mayonnaise",
 'Price': '£3.00',
 'Protein': '1.1 g',
 'Salt': '1.5 g',
 'Saturates': '6.2 g',
 'Sugars': '1.3 g',
 'Supermarket': 'Asda',
 'item_url': 'https://groceries.asda.com/product/910000057722'}
DEBUG:scrapy.core.engine:Crawled (200) <GET https://groceries.asda.com/product/910000212250 via http://0.0.0.0:8050/render.html> (referer: None)
DEBUG:scrapy.core.scraper:Scraped from <200 https://groceries.asda.com/product/910000212250>
{'Carbohydrate': '1.4 g',
 'Date': datetime.datetime(2020, 5, 6, 9, 11, 0, 378133),
 'Energy': '726 kcal',
 'Fat': '79 g',
 'Name': "Hellmann's Real Squeezy Mayonnaise",
 'Price': '£2.00',
 'Protein': '1.1 g',
 'Salt': '1.5 g',
 'Saturates': '6.3 g',
 'Sugars': '1.3 g',
 'Supermarket': 'Asda',
 'item_url': 'https://groceries.asda.com/product/910000212250'}
DEBUG:scrapy.core.engine:Crawled (200) <GET https://groceries.asda.com/product/910001192935 via http://0.0.0.0:8050/render.html> (referer: None)
DEBUG:scrapy.core.scraper:Scraped from <200 https://groceries.asda.com/product/910001192935>
{'Carbohydrate': '56.0g',
 'Date': datetime.datetime(2020, 5, 6, 9, 11, 0, 616099),
 'Energy': '2280kJ',
 'Fat': '32.4g',
 'Name': 'Galaxy Smooth Milk Chocolate Bars Multipack',
 'Price': '£1.50',
 'Protein': '6.7g',
 'Salt': '0.25g',
 'Saturates': '19.6g',
 'Sugars': '55.4g',
 'Supermarket': 'Asda',
 'item_url': 'https://groceries.asda.com/product/910001192935'}
DEBUG:scrapy.core.engine:Crawled (200) <GET https://groceries.asda.com/product/910000539461 via http://0.0.0.0:8050/render.html> (referer: None)
DEBUG:scrapy.core.engine:Crawled (200) <GET https://groceries.asda.com/product/19140 via http://0.0.0.0:8050/render.html> (referer: None)
INFO:scrapy.crawler:Received SIGINT, shutting down gracefully. Send again to force 
INFO:scrapy.core.engine:Closing spider (shutdown)
DEBUG:scrapy.core.scraper:Scraped from <200 https://groceries.asda.com/product/910000539461>
{'Carbohydrate': '58.5g',
 'Date': datetime.datetime(2020, 5, 6, 9, 11, 0, 842230),
 'Energy': '2042kJ',
 'Fat': '26.0g',
 'Name': 'Bounty Coconut Milk Chocolate Twin Bars Multipack',
 'Price': '£1.50',
 'Protein': '3.8g',
 'Salt': '0.26g',
 'Saturates': '21.4g',
 'Sugars': '47.9g',
 'Supermarket': 'Asda',
 'item_url': 'https://groceries.asda.com/product/910000539461'}
DEBUG:scrapy.core.scraper:Scraped from <200 https://groceries.asda.com/product/19140>
{'Carbohydrate': '82g',
 'Date': datetime.datetime(2020, 5, 6, 9, 11, 0, 880165),
 'Energy': '1683kJ',
 'Fat': '4.5g',
 'Fibre': '2.5g',
 'Name': "Kellogg's Crunchy Nut Corn Flakes",
 'Price': '£2.00',
 'Protein': '6g',
 'Salt': '0.75g',
 'Saturates': '0.7g',
 'Sugars': '35g',
 'Supermarket': 'Asda',
 'item_url': 'https://groceries.asda.com/product/19140'}
INFO:scrapy.crawler:Received SIGINT twice, forcing unclean shutdown
DEBUG:scrapy.downloadermiddlewares.retry:Retrying <GET https://groceries.asda.com/product/910000026780 via http://0.0.0.0:8050/render.html> (failed 1 times): [<twisted.python.failure.Failure twisted.internet.error.ConnectionLost: Connection to the other side was lost in a non-clean fashion: Connection lost.>]
DEBUG:scrapy.downloadermiddlewares.retry:Retrying <GET https://groceries.asda.com/product/24152059 via http://0.0.0.0:8050/render.html> (failed 1 times): [<twisted.python.failure.Failure twisted.internet.error.ConnectionLost: Connection to the other side was lost in a non-clean fashion: Connection lost.>]
DEBUG:scrapy.downloadermiddlewares.retry:Retrying <GET https://groceries.asda.com/product/910001818810 via http://0.0.0.0:8050/render.html> (failed 1 times): [<twisted.python.failure.Failure twisted.internet.error.ConnectionLost: Connection to the other side was lost in a non-clean fashion: Connection lost.>]
DEBUG:scrapy.downloadermiddlewares.retry:Retrying <GET https://groceries.asda.com/product/63716560 via http://0.0.0.0:8050/render.html> (failed 1 times): [<twisted.python.failure.Failure twisted.internet.error.ConnectionLost: Connection to the other side was lost in a non-clean fashion: Connection lost.>]
DEBUG:scrapy.downloadermiddlewares.retry:Retrying <GET https://groceries.asda.com/product/1000178911415 via http://0.0.0.0:8050/render.html> (failed 1 times): [<twisted.python.failure.Failure twisted.internet.error.ConnectionLost: Connection to the other side was lost in a non-clean fashion: Connection lost.>]
DEBUG:scrapy.downloadermiddlewares.retry:Retrying <GET https://groceries.asda.com/product/910000043501 via http://0.0.0.0:8050/render.html> (failed 1 times): [<twisted.python.failure.Failure twisted.internet.error.ConnectionLost: Connection to the other side was lost in a non-clean fashion: Connection lost.>]
DEBUG:scrapy.downloadermiddlewares.retry:Retrying <GET https://groceries.asda.com/product/1000178911419 via http://0.0.0.0:8050/render.html> (failed 1 times): [<twisted.python.failure.Failure twisted.internet.error.ConnectionLost: Connection to the other side was lost in a non-clean fashion: Connection lost.>]
DEBUG:scrapy.downloadermiddlewares.retry:Retrying <GET https://groceries.asda.com/product/68021675 via http://0.0.0.0:8050/render.html> (failed 1 times): [<twisted.python.failure.Failure twisted.internet.error.ConnectionLost: Connection to the other side was lost in a non-clean fashion: Connection lost.>]
WARNING:root:Spider warnings
INFO:scrapy.utils.log:Scrapy 2.0.1 started (bot: shopscrap)
INFO:scrapy.utils.log:Versions: lxml 4.5.0.0, libxml2 2.9.10, cssselect 1.1.0, parsel 1.5.2, w3lib 1.21.0, Twisted 20.3.0, Python 3.6.9 (default, Apr 18 2020, 01:56:04) - [GCC 8.4.0], pyOpenSSL 19.1.0 (OpenSSL 1.1.1f  31 Mar 2020), cryptography 2.9, Platform Linux-5.3.0-51-generic-x86_64-with-Ubuntu-18.04-bionic
DEBUG:scrapy.utils.log:Using reactor: twisted.internet.epollreactor.EPollReactor
INFO:scrapy.crawler:Overridden settings:
{'BOT_NAME': 'shopscrap',
 'DUPEFILTER_CLASS': 'scrapy_splash.SplashAwareDupeFilter',
 'HTTPCACHE_STORAGE': 'scrapy_splash.SplashAwareFSCacheStorage',
 'NEWSPIDER_MODULE': 'shopscrap.spiders',
 'SPIDER_MODULES': ['shopscrap.spiders'],
 'USER_AGENT': 'Mozilla/5.0 (X11; Linux x86_64) AppleWebKit/537.36 (KHTML, '
               'like Gecko) Brave Chrome/80.0.3987.163 Safari/537.36'}
INFO:scrapy.extensions.telnet:Telnet Password: 966e8b977e568acd
INFO:scrapy.middleware:Enabled extensions:
['scrapy.extensions.corestats.CoreStats',
 'scrapy.extensions.telnet.TelnetConsole',
 'scrapy.extensions.memusage.MemoryUsage',
 'scrapy.extensions.logstats.LogStats']
INFO:scrapy.middleware:Enabled downloader middlewares:
['scrapy.downloadermiddlewares.httpauth.HttpAuthMiddleware',
 'scrapy.downloadermiddlewares.downloadtimeout.DownloadTimeoutMiddleware',
 'scrapy.downloadermiddlewares.defaultheaders.DefaultHeadersMiddleware',
 'scrapy.downloadermiddlewares.useragent.UserAgentMiddleware',
 'scrapy.downloadermiddlewares.retry.RetryMiddleware',
 'scrapy.downloadermiddlewares.redirect.MetaRefreshMiddleware',
 'scrapy.downloadermiddlewares.redirect.RedirectMiddleware',
 'scrapy.downloadermiddlewares.cookies.CookiesMiddleware',
 'scrapy_splash.SplashCookiesMiddleware',
 'scrapy_splash.SplashMiddleware',
 'scrapy.downloadermiddlewares.httpproxy.HttpProxyMiddleware',
 'scrapy.downloadermiddlewares.httpcompression.HttpCompressionMiddleware',
 'scrapy.downloadermiddlewares.stats.DownloaderStats']
INFO:scrapy.middleware:Enabled spider middlewares:
['scrapy.spidermiddlewares.httperror.HttpErrorMiddleware',
 'scrapy_splash.SplashDeduplicateArgsMiddleware',
 'scrapy.spidermiddlewares.offsite.OffsiteMiddleware',
 'scrapy.spidermiddlewares.referer.RefererMiddleware',
 'scrapy.spidermiddlewares.urllength.UrlLengthMiddleware',
 'scrapy.spidermiddlewares.depth.DepthMiddleware']
INFO:scrapy.middleware:Enabled item pipelines:
['shopscrap.pipelines.ShopScrapdb']
INFO:scrapy.core.engine:Spider opened
INFO:scrapy.extensions.logstats:Crawled 0 pages (at 0 pages/min), scraped 0 items (at 0 items/min)
INFO:scrapy.extensions.telnet:Telnet console listening on 127.0.0.1:6029
WARNING:py.warnings:/home/user/.local/lib/python3.6/site-packages/scrapy_splash/request.py:41: ScrapyDeprecationWarning: Call to deprecated function to_native_str. Use to_unicode instead.
  url = to_native_str(url)

DEBUG:scrapy.core.engine:Crawled (200) <GET https://groceries.asda.com/product/cornflakes-honey-nut/kelloggs-crunchy-nut-corn-flakes/19140/ via http://0.0.0.0:8050/render.html> (referer: None)
DEBUG:scrapy.core.scraper:Scraped from <200 https://groceries.asda.com/product/cornflakes-honey-nut/kelloggs-crunchy-nut-corn-flakes/19140/>
<generator object ShopScrapdb.process_item at 0x7ff93825aaf0>
DEBUG:scrapy.core.engine:Crawled (200) <GET https://groceries.asda.com/product/910001818810 via http://0.0.0.0:8050/render.html> (referer: None)
DEBUG:scrapy.core.engine:Crawled (200) <GET https://groceries.asda.com/product/910000396129 via http://0.0.0.0:8050/render.html> (referer: None)
DEBUG:scrapy.core.engine:Crawled (200) <GET https://groceries.asda.com/product/1217550 via http://0.0.0.0:8050/render.html> (referer: None)
DEBUG:scrapy.core.engine:Crawled (200) <GET https://groceries.asda.com/product/1639642 via http://0.0.0.0:8050/render.html> (referer: None)
DEBUG:scrapy.core.engine:Crawled (200) <GET https://groceries.asda.com/product/910000212250 via http://0.0.0.0:8050/render.html> (referer: None)
DEBUG:scrapy.core.engine:Crawled (200) <GET https://groceries.asda.com/product/910000020309 via http://0.0.0.0:8050/render.html> (referer: None)
DEBUG:scrapy.core.engine:Crawled (200) <GET https://groceries.asda.com/product/1000178911415 via http://0.0.0.0:8050/render.html> (referer: None)
DEBUG:scrapy.core.scraper:Scraped from <200 https://groceries.asda.com/product/910001818810>
<generator object ShopScrapdb.process_item at 0x7ff938230bf8>
DEBUG:scrapy.dupefilters:Filtered duplicate request: <GET https://groceries.asda.com/product/25857> - no more duplicates will be shown (see DUPEFILTER_DEBUG to show all duplicates)
DEBUG:scrapy.core.scraper:Scraped from <200 https://groceries.asda.com/product/910000396129>
<generator object ShopScrapdb.process_item at 0x7ff9380cd6d0>
DEBUG:scrapy.core.scraper:Scraped from <200 https://groceries.asda.com/product/1217550>
<generator object ShopScrapdb.process_item at 0x7ff9380d1a98>
DEBUG:scrapy.core.scraper:Scraped from <200 https://groceries.asda.com/product/1639642>
<generator object ShopScrapdb.process_item at 0x7ff9380d8150>
DEBUG:scrapy.core.scraper:Scraped from <200 https://groceries.asda.com/product/910000212250>
<generator object ShopScrapdb.process_item at 0x7ff9380dc780>
DEBUG:scrapy.core.scraper:Scraped from <200 https://groceries.asda.com/product/910000020309>
<generator object ShopScrapdb.process_item at 0x7ff9380e1bf8>
DEBUG:scrapy.core.scraper:Scraped from <200 https://groceries.asda.com/product/1000178911415>
<generator object ShopScrapdb.process_item at 0x7ff9380e1ca8>
DEBUG:scrapy.core.engine:Crawled (200) <GET https://groceries.asda.com/product/1000178911419 via http://0.0.0.0:8050/render.html> (referer: None)
DEBUG:scrapy.core.scraper:Scraped from <200 https://groceries.asda.com/product/1000178911419>
<generator object ShopScrapdb.process_item at 0x7ff938230f10>
DEBUG:scrapy.core.engine:Crawled (200) <GET https://groceries.asda.com/product/910001423910 via http://0.0.0.0:8050/render.html> (referer: None)
DEBUG:scrapy.core.engine:Crawled (200) <GET https://groceries.asda.com/product/910000043501 via http://0.0.0.0:8050/render.html> (referer: None)
DEBUG:scrapy.core.scraper:Scraped from <200 https://groceries.asda.com/product/910001423910>
<generator object ShopScrapdb.process_item at 0x7ff938123ca8>
DEBUG:scrapy.core.engine:Crawled (200) <GET https://groceries.asda.com/product/910003062153 via http://0.0.0.0:8050/render.html> (referer: None)
DEBUG:scrapy.core.scraper:Scraped from <200 https://groceries.asda.com/product/910000043501>
<generator object ShopScrapdb.process_item at 0x7ff93810e468>
DEBUG:scrapy.core.scraper:Scraped from <200 https://groceries.asda.com/product/910003062153>
<generator object ShopScrapdb.process_item at 0x7ff9381237d8>
DEBUG:scrapy.core.engine:Crawled (200) <GET https://groceries.asda.com/product/1000039942582 via http://0.0.0.0:8050/render.html> (referer: None)
DEBUG:scrapy.core.engine:Crawled (200) <GET https://groceries.asda.com/product/1000161632988 via http://0.0.0.0:8050/render.html> (referer: None)
DEBUG:scrapy.core.scraper:Scraped from <200 https://groceries.asda.com/product/1000039942582>
<generator object ShopScrapdb.process_item at 0x7ff93825a048>
DEBUG:scrapy.core.scraper:Scraped from <200 https://groceries.asda.com/product/1000161632988>
<generator object ShopScrapdb.process_item at 0x7ff938164990>
DEBUG:scrapy.core.engine:Crawled (200) <GET https://groceries.asda.com/product/25857 via http://0.0.0.0:8050/render.html> (referer: None)
DEBUG:scrapy.core.engine:Crawled (200) <GET https://groceries.asda.com/product/8667410 via http://0.0.0.0:8050/render.html> (referer: None)
DEBUG:scrapy.core.scraper:Scraped from <200 https://groceries.asda.com/product/25857>
<generator object ShopScrapdb.process_item at 0x7ff938110830>
DEBUG:scrapy.core.scraper:Scraped from <200 https://groceries.asda.com/product/8667410>
<generator object ShopScrapdb.process_item at 0x7ff9381f5a40>
DEBUG:scrapy.core.engine:Crawled (200) <GET https://groceries.asda.com/product/1000203231946 via http://0.0.0.0:8050/render.html> (referer: None)
DEBUG:scrapy.core.scraper:Scraped from <200 https://groceries.asda.com/product/1000203231946>
<generator object ShopScrapdb.process_item at 0x7ff9381f5af0>
DEBUG:scrapy.core.engine:Crawled (200) <GET https://groceries.asda.com/product/910000057676 via http://0.0.0.0:8050/render.html> (referer: None)
DEBUG:scrapy.core.scraper:Scraped from <200 https://groceries.asda.com/product/910000057676>
<generator object ShopScrapdb.process_item at 0x7ff9381dabf8>
DEBUG:scrapy.core.engine:Crawled (200) <GET https://groceries.asda.com/product/910000057722 via http://0.0.0.0:8050/render.html> (referer: None)
DEBUG:scrapy.core.scraper:Scraped from <200 https://groceries.asda.com/product/910000057722>
<generator object ShopScrapdb.process_item at 0x7ff938221308>
DEBUG:scrapy.core.engine:Crawled (200) <GET https://groceries.asda.com/product/910001192935 via http://0.0.0.0:8050/render.html> (referer: None)
DEBUG:scrapy.core.scraper:Scraped from <200 https://groceries.asda.com/product/910001192935>
<generator object ShopScrapdb.process_item at 0x7ff93821d5c8>
DEBUG:scrapy.core.engine:Crawled (200) <GET https://groceries.asda.com/product/24152059 via http://0.0.0.0:8050/render.html> (referer: None)
DEBUG:scrapy.core.scraper:Scraped from <200 https://groceries.asda.com/product/24152059>
<generator object ShopScrapdb.process_item at 0x7ff9381daba0>
DEBUG:scrapy.core.engine:Crawled (200) <GET https://groceries.asda.com/product/19140 via http://0.0.0.0:8050/render.html> (referer: None)
DEBUG:scrapy.core.scraper:Scraped from <200 https://groceries.asda.com/product/19140>
<generator object ShopScrapdb.process_item at 0x7ff938110570>
DEBUG:scrapy.core.engine:Crawled (200) <GET https://groceries.asda.com/product/910000026780 via http://0.0.0.0:8050/render.html> (referer: None)
DEBUG:scrapy.core.scraper:Scraped from <200 https://groceries.asda.com/product/910000026780>
<generator object ShopScrapdb.process_item at 0x7ff9381123b8>
DEBUG:scrapy.core.engine:Crawled (200) <GET https://groceries.asda.com/product/910000020342 via http://0.0.0.0:8050/render.html> (referer: None)
DEBUG:scrapy.core.engine:Crawled (200) <GET https://groceries.asda.com/product/910000539461 via http://0.0.0.0:8050/render.html> (referer: None)
DEBUG:scrapy.core.scraper:Scraped from <200 https://groceries.asda.com/product/910000020342>
<generator object ShopScrapdb.process_item at 0x7ff93810f990>
DEBUG:scrapy.core.scraper:Scraped from <200 https://groceries.asda.com/product/910000539461>
<generator object ShopScrapdb.process_item at 0x7ff9381e5048>
INFO:scrapy.crawler:Received SIGINT, shutting down gracefully. Send again to force 
INFO:scrapy.core.engine:Closing spider (shutdown)
INFO:scrapy.crawler:Received SIGINT twice, forcing unclean shutdown
DEBUG:scrapy.downloadermiddlewares.retry:Retrying <GET https://groceries.asda.com/product/1000132169251 via http://0.0.0.0:8050/render.html> (failed 1 times): [<twisted.python.failure.Failure twisted.internet.error.ConnectionLost: Connection to the other side was lost in a non-clean fashion: Connection lost.>]
DEBUG:scrapy.downloadermiddlewares.retry:Retrying <GET https://groceries.asda.com/product/910000254290 via http://0.0.0.0:8050/render.html> (failed 1 times): [<twisted.python.failure.Failure twisted.internet.error.ConnectionLost: Connection to the other side was lost in a non-clean fashion: Connection lost.>]
DEBUG:scrapy.downloadermiddlewares.retry:Retrying <GET https://groceries.asda.com/product/1000003093677 via http://0.0.0.0:8050/render.html> (failed 1 times): [<twisted.python.failure.Failure twisted.internet.error.ConnectionLost: Connection to the other side was lost in a non-clean fashion: Connection lost.>]
DEBUG:scrapy.downloadermiddlewares.retry:Retrying <GET https://groceries.asda.com/product/1000136120510 via http://0.0.0.0:8050/render.html> (failed 1 times): [<twisted.python.failure.Failure twisted.internet.error.ConnectionLost: Connection to the other side was lost in a non-clean fashion: Connection lost.>]
DEBUG:scrapy.downloadermiddlewares.retry:Retrying <GET https://groceries.asda.com/product/80975593 via http://0.0.0.0:8050/render.html> (failed 1 times): [<twisted.python.failure.Failure twisted.internet.error.ConnectionLost: Connection to the other side was lost in a non-clean fashion: Connection lost.>]
DEBUG:scrapy.downloadermiddlewares.retry:Retrying <GET https://groceries.asda.com/product/1000202268801 via http://0.0.0.0:8050/render.html> (failed 1 times): [<twisted.python.failure.Failure twisted.internet.error.ConnectionLost: Connection to the other side was lost in a non-clean fashion: Connection lost.>]
DEBUG:scrapy.downloadermiddlewares.retry:Retrying <GET https://groceries.asda.com/product/26170 via http://0.0.0.0:8050/render.html> (failed 1 times): [<twisted.python.failure.Failure twisted.internet.error.ConnectionLost: Connection to the other side was lost in a non-clean fashion: Connection lost.>]
DEBUG:scrapy.downloadermiddlewares.retry:Retrying <GET https://groceries.asda.com/product/910003061587 via http://0.0.0.0:8050/render.html> (failed 1 times): [<twisted.python.failure.Failure twisted.internet.error.ConnectionLost: Connection to the other side was lost in a non-clean fashion: Connection lost.>]
WARNING:root:Spider warnings
INFO:scrapy.utils.log:Scrapy 2.0.1 started (bot: shopscrap)
INFO:scrapy.utils.log:Versions: lxml 4.5.0.0, libxml2 2.9.10, cssselect 1.1.0, parsel 1.5.2, w3lib 1.21.0, Twisted 20.3.0, Python 3.6.9 (default, Apr 18 2020, 01:56:04) - [GCC 8.4.0], pyOpenSSL 19.1.0 (OpenSSL 1.1.1f  31 Mar 2020), cryptography 2.9, Platform Linux-5.3.0-51-generic-x86_64-with-Ubuntu-18.04-bionic
DEBUG:scrapy.utils.log:Using reactor: twisted.internet.epollreactor.EPollReactor
INFO:scrapy.crawler:Overridden settings:
{'BOT_NAME': 'shopscrap',
 'DUPEFILTER_CLASS': 'scrapy_splash.SplashAwareDupeFilter',
 'HTTPCACHE_STORAGE': 'scrapy_splash.SplashAwareFSCacheStorage',
 'NEWSPIDER_MODULE': 'shopscrap.spiders',
 'SPIDER_MODULES': ['shopscrap.spiders'],
 'USER_AGENT': 'Mozilla/5.0 (X11; Linux x86_64) AppleWebKit/537.36 (KHTML, '
               'like Gecko) Brave Chrome/80.0.3987.163 Safari/537.36'}
INFO:scrapy.extensions.telnet:Telnet Password: da8a9166d2b677ef
INFO:scrapy.middleware:Enabled extensions:
['scrapy.extensions.corestats.CoreStats',
 'scrapy.extensions.telnet.TelnetConsole',
 'scrapy.extensions.memusage.MemoryUsage',
 'scrapy.extensions.logstats.LogStats']
INFO:scrapy.middleware:Enabled downloader middlewares:
['scrapy.downloadermiddlewares.httpauth.HttpAuthMiddleware',
 'scrapy.downloadermiddlewares.downloadtimeout.DownloadTimeoutMiddleware',
 'scrapy.downloadermiddlewares.defaultheaders.DefaultHeadersMiddleware',
 'scrapy.downloadermiddlewares.useragent.UserAgentMiddleware',
 'scrapy.downloadermiddlewares.retry.RetryMiddleware',
 'scrapy.downloadermiddlewares.redirect.MetaRefreshMiddleware',
 'scrapy.downloadermiddlewares.redirect.RedirectMiddleware',
 'scrapy.downloadermiddlewares.cookies.CookiesMiddleware',
 'scrapy_splash.SplashCookiesMiddleware',
 'scrapy_splash.SplashMiddleware',
 'scrapy.downloadermiddlewares.httpproxy.HttpProxyMiddleware',
 'scrapy.downloadermiddlewares.httpcompression.HttpCompressionMiddleware',
 'scrapy.downloadermiddlewares.stats.DownloaderStats']
INFO:scrapy.middleware:Enabled spider middlewares:
['scrapy.spidermiddlewares.httperror.HttpErrorMiddleware',
 'scrapy_splash.SplashDeduplicateArgsMiddleware',
 'scrapy.spidermiddlewares.offsite.OffsiteMiddleware',
 'scrapy.spidermiddlewares.referer.RefererMiddleware',
 'scrapy.spidermiddlewares.urllength.UrlLengthMiddleware',
 'scrapy.spidermiddlewares.depth.DepthMiddleware']
INFO:scrapy.middleware:Enabled item pipelines:
['shopscrap.pipelines.ShopScrapdb']
INFO:scrapy.core.engine:Spider opened
INFO:scrapy.extensions.logstats:Crawled 0 pages (at 0 pages/min), scraped 0 items (at 0 items/min)
INFO:scrapy.extensions.telnet:Telnet console listening on 127.0.0.1:6029
WARNING:py.warnings:/home/user/.local/lib/python3.6/site-packages/scrapy_splash/request.py:41: ScrapyDeprecationWarning: Call to deprecated function to_native_str. Use to_unicode instead.
  url = to_native_str(url)

DEBUG:scrapy.core.engine:Crawled (200) <GET https://groceries.asda.com/product/cornflakes-honey-nut/kelloggs-crunchy-nut-corn-flakes/19140/ via http://0.0.0.0:8050/render.html> (referer: None)
DEBUG:scrapy.core.scraper:Scraped from <200 https://groceries.asda.com/product/cornflakes-honey-nut/kelloggs-crunchy-nut-corn-flakes/19140/>
<generator object ShopScrapdb.process_item at 0x7f4222850af0>
DEBUG:scrapy.core.engine:Crawled (200) <GET https://groceries.asda.com/product/1639642 via http://0.0.0.0:8050/render.html> (referer: None)
DEBUG:scrapy.core.engine:Crawled (200) <GET https://groceries.asda.com/product/910000396129 via http://0.0.0.0:8050/render.html> (referer: None)
DEBUG:scrapy.core.engine:Crawled (200) <GET https://groceries.asda.com/product/1000178911419 via http://0.0.0.0:8050/render.html> (referer: None)
DEBUG:scrapy.core.engine:Crawled (200) <GET https://groceries.asda.com/product/1000178911415 via http://0.0.0.0:8050/render.html> (referer: None)
DEBUG:scrapy.core.engine:Crawled (200) <GET https://groceries.asda.com/product/910000020309 via http://0.0.0.0:8050/render.html> (referer: None)
DEBUG:scrapy.core.engine:Crawled (200) <GET https://groceries.asda.com/product/910000212250 via http://0.0.0.0:8050/render.html> (referer: None)
DEBUG:scrapy.core.engine:Crawled (200) <GET https://groceries.asda.com/product/1217550 via http://0.0.0.0:8050/render.html> (referer: None)
DEBUG:scrapy.core.scraper:Scraped from <200 https://groceries.asda.com/product/1639642>
<generator object ShopScrapdb.process_item at 0x7f422282f1a8>
DEBUG:scrapy.dupefilters:Filtered duplicate request: <GET https://groceries.asda.com/product/25857> - no more duplicates will be shown (see DUPEFILTER_DEBUG to show all duplicates)
DEBUG:scrapy.core.scraper:Scraped from <200 https://groceries.asda.com/product/910000396129>
<generator object ShopScrapdb.process_item at 0x7f42226c5d58>
DEBUG:scrapy.core.scraper:Scraped from <200 https://groceries.asda.com/product/1000178911419>
<generator object ShopScrapdb.process_item at 0x7f42226c5db0>
DEBUG:scrapy.core.scraper:Scraped from <200 https://groceries.asda.com/product/1000178911415>
<generator object ShopScrapdb.process_item at 0x7f42226cd468>
DEBUG:scrapy.core.scraper:Scraped from <200 https://groceries.asda.com/product/910000020309>
<generator object ShopScrapdb.process_item at 0x7f42226d4938>
DEBUG:scrapy.core.scraper:Scraped from <200 https://groceries.asda.com/product/910000212250>
<generator object ShopScrapdb.process_item at 0x7f42226d92b0>
DEBUG:scrapy.core.scraper:Scraped from <200 https://groceries.asda.com/product/1217550>
<generator object ShopScrapdb.process_item at 0x7f42226de728>
DEBUG:scrapy.core.engine:Crawled (200) <GET https://groceries.asda.com/product/910001818810 via http://0.0.0.0:8050/render.html> (referer: None)
DEBUG:scrapy.core.scraper:Scraped from <200 https://groceries.asda.com/product/910001818810>
<generator object ShopScrapdb.process_item at 0x7f42226fc518>
INFO:scrapy.crawler:Received SIGINT, shutting down gracefully. Send again to force 
INFO:scrapy.core.engine:Closing spider (shutdown)
INFO:scrapy.crawler:Received SIGINT twice, forcing unclean shutdown
DEBUG:scrapy.downloadermiddlewares.retry:Retrying <GET https://groceries.asda.com/product/910000539461 via http://0.0.0.0:8050/render.html> (failed 1 times): [<twisted.python.failure.Failure twisted.internet.error.ConnectionLost: Connection to the other side was lost in a non-clean fashion: Connection lost.>]
DEBUG:scrapy.downloadermiddlewares.retry:Retrying <GET https://groceries.asda.com/product/24076 via http://0.0.0.0:8050/render.html> (failed 1 times): [<twisted.python.failure.Failure twisted.internet.error.ConnectionLost: Connection to the other side was lost in a non-clean fashion: Connection lost.>]
DEBUG:scrapy.downloadermiddlewares.retry:Retrying <GET https://groceries.asda.com/product/910001192935 via http://0.0.0.0:8050/render.html> (failed 1 times): [<twisted.python.failure.Failure twisted.internet.error.ConnectionLost: Connection to the other side was lost in a non-clean fashion: Connection lost.>]
DEBUG:scrapy.downloadermiddlewares.retry:Retrying <GET https://groceries.asda.com/product/910000026780 via http://0.0.0.0:8050/render.html> (failed 1 times): [<twisted.python.failure.Failure twisted.internet.error.ConnectionLost: Connection to the other side was lost in a non-clean fashion: Connection lost.>]
DEBUG:scrapy.downloadermiddlewares.retry:Retrying <GET https://groceries.asda.com/product/24152059 via http://0.0.0.0:8050/render.html> (failed 1 times): [<twisted.python.failure.Failure twisted.internet.error.ConnectionLost: Connection to the other side was lost in a non-clean fashion: Connection lost.>]
DEBUG:scrapy.downloadermiddlewares.retry:Retrying <GET https://groceries.asda.com/product/910000043501 via http://0.0.0.0:8050/render.html> (failed 1 times): [<twisted.python.failure.Failure twisted.internet.error.ConnectionLost: Connection to the other side was lost in a non-clean fashion: Connection lost.>]
DEBUG:scrapy.downloadermiddlewares.retry:Retrying <GET https://groceries.asda.com/product/19140 via http://0.0.0.0:8050/render.html> (failed 1 times): [<twisted.python.failure.Failure twisted.internet.error.ConnectionLost: Connection to the other side was lost in a non-clean fashion: Connection lost.>]
DEBUG:scrapy.downloadermiddlewares.retry:Retrying <GET https://groceries.asda.com/product/25857 via http://0.0.0.0:8050/render.html> (failed 1 times): [<twisted.python.failure.Failure twisted.internet.error.ConnectionLost: Connection to the other side was lost in a non-clean fashion: Connection lost.>]
WARNING:root:Spider warnings
INFO:scrapy.utils.log:Scrapy 2.0.1 started (bot: shopscrap)
INFO:scrapy.utils.log:Versions: lxml 4.5.0.0, libxml2 2.9.10, cssselect 1.1.0, parsel 1.5.2, w3lib 1.21.0, Twisted 20.3.0, Python 3.6.9 (default, Apr 18 2020, 01:56:04) - [GCC 8.4.0], pyOpenSSL 19.1.0 (OpenSSL 1.1.1f  31 Mar 2020), cryptography 2.9, Platform Linux-5.3.0-51-generic-x86_64-with-Ubuntu-18.04-bionic
DEBUG:scrapy.utils.log:Using reactor: twisted.internet.epollreactor.EPollReactor
INFO:scrapy.crawler:Overridden settings:
{'BOT_NAME': 'shopscrap',
 'DUPEFILTER_CLASS': 'scrapy_splash.SplashAwareDupeFilter',
 'HTTPCACHE_STORAGE': 'scrapy_splash.SplashAwareFSCacheStorage',
 'NEWSPIDER_MODULE': 'shopscrap.spiders',
 'SPIDER_MODULES': ['shopscrap.spiders'],
 'USER_AGENT': 'Mozilla/5.0 (X11; Linux x86_64) AppleWebKit/537.36 (KHTML, '
               'like Gecko) Brave Chrome/80.0.3987.163 Safari/537.36'}
INFO:scrapy.extensions.telnet:Telnet Password: acbba565f1d65aa7
INFO:scrapy.middleware:Enabled extensions:
['scrapy.extensions.corestats.CoreStats',
 'scrapy.extensions.telnet.TelnetConsole',
 'scrapy.extensions.memusage.MemoryUsage',
 'scrapy.extensions.logstats.LogStats']
INFO:scrapy.middleware:Enabled downloader middlewares:
['scrapy.downloadermiddlewares.httpauth.HttpAuthMiddleware',
 'scrapy.downloadermiddlewares.downloadtimeout.DownloadTimeoutMiddleware',
 'scrapy.downloadermiddlewares.defaultheaders.DefaultHeadersMiddleware',
 'scrapy.downloadermiddlewares.useragent.UserAgentMiddleware',
 'scrapy.downloadermiddlewares.retry.RetryMiddleware',
 'scrapy.downloadermiddlewares.redirect.MetaRefreshMiddleware',
 'scrapy.downloadermiddlewares.redirect.RedirectMiddleware',
 'scrapy.downloadermiddlewares.cookies.CookiesMiddleware',
 'scrapy_splash.SplashCookiesMiddleware',
 'scrapy_splash.SplashMiddleware',
 'scrapy.downloadermiddlewares.httpproxy.HttpProxyMiddleware',
 'scrapy.downloadermiddlewares.httpcompression.HttpCompressionMiddleware',
 'scrapy.downloadermiddlewares.stats.DownloaderStats']
INFO:scrapy.middleware:Enabled spider middlewares:
['scrapy.spidermiddlewares.httperror.HttpErrorMiddleware',
 'scrapy_splash.SplashDeduplicateArgsMiddleware',
 'scrapy.spidermiddlewares.offsite.OffsiteMiddleware',
 'scrapy.spidermiddlewares.referer.RefererMiddleware',
 'scrapy.spidermiddlewares.urllength.UrlLengthMiddleware',
 'scrapy.spidermiddlewares.depth.DepthMiddleware']
INFO:scrapy.middleware:Enabled item pipelines:
['shopscrap.pipelines.ShopScrapdb']
INFO:scrapy.core.engine:Spider opened
INFO:scrapy.extensions.logstats:Crawled 0 pages (at 0 pages/min), scraped 0 items (at 0 items/min)
INFO:scrapy.extensions.telnet:Telnet console listening on 127.0.0.1:6029
WARNING:py.warnings:/home/user/.local/lib/python3.6/site-packages/scrapy_splash/request.py:41: ScrapyDeprecationWarning: Call to deprecated function to_native_str. Use to_unicode instead.
  url = to_native_str(url)

DEBUG:scrapy.core.engine:Crawled (200) <GET https://groceries.asda.com/product/cornflakes-honey-nut/kelloggs-crunchy-nut-corn-flakes/19140/ via http://0.0.0.0:8050/render.html> (referer: None)
ERROR:scrapy.core.scraper:Error processing {'Carbohydrate': '82g',
 'Date': datetime.datetime(2020, 5, 6, 9, 21, 3, 246100),
 'Energy': '1683kJ',
 'Fat': '4.5g',
 'Fibre': '2.5g',
 'Name': "Kellogg's Crunchy Nut Corn Flakes",
 'Price': '£2.00',
 'Protein': '6g',
 'Salt': '0.75g',
 'Saturates': '0.7g',
 'Sugars': '35g',
 'Supermarket': 'Asda',
 'item_url': 'https://groceries.asda.com/product/cornflakes-honey-nut/kelloggs-crunchy-nut-corn-flakes/19140/'}
Traceback (most recent call last):
  File "/home/user/.local/lib/python3.6/site-packages/sqlalchemy/engine/base.py", line 1248, in _execute_context
    cursor, statement, parameters, context
  File "/home/user/.local/lib/python3.6/site-packages/sqlalchemy/engine/default.py", line 590, in do_execute
    cursor.execute(statement, parameters)
  File "/home/user/.local/lib/python3.6/site-packages/MySQLdb/cursors.py", line 209, in execute
    res = self._query(query)
  File "/home/user/.local/lib/python3.6/site-packages/MySQLdb/cursors.py", line 315, in _query
    db.query(q)
  File "/home/user/.local/lib/python3.6/site-packages/MySQLdb/connections.py", line 239, in query
    _mysql.connection.query(self, query)
MySQLdb._exceptions.OperationalError: (1048, "Column 'name' cannot be null")

The above exception was the direct cause of the following exception:

Traceback (most recent call last):
  File "/home/user/.local/lib/python3.6/site-packages/twisted/internet/defer.py", line 654, in _runCallbacks
    current.result = callback(current.result, *args, **kw)
  File "/home/user/.local/lib/python3.6/site-packages/scrapy/utils/defer.py", line 154, in f
    return deferred_from_coro(coro_f(*coro_args, **coro_kwargs))
  File "/home/user/Documents/PythonScripts/shopscrap/shopscrap/pipelines.py", line 98, in process_item
    session.flush()
  File "/home/user/.local/lib/python3.6/site-packages/sqlalchemy/orm/session.py", line 2496, in flush
    self._flush(objects)
  File "/home/user/.local/lib/python3.6/site-packages/sqlalchemy/orm/session.py", line 2637, in _flush
    transaction.rollback(_capture_exception=True)
  File "/home/user/.local/lib/python3.6/site-packages/sqlalchemy/util/langhelpers.py", line 69, in __exit__
    exc_value, with_traceback=exc_tb,
  File "/home/user/.local/lib/python3.6/site-packages/sqlalchemy/util/compat.py", line 178, in raise_
    raise exception
  File "/home/user/.local/lib/python3.6/site-packages/sqlalchemy/orm/session.py", line 2597, in _flush
    flush_context.execute()
  File "/home/user/.local/lib/python3.6/site-packages/sqlalchemy/orm/unitofwork.py", line 422, in execute
    rec.execute(self)
  File "/home/user/.local/lib/python3.6/site-packages/sqlalchemy/orm/unitofwork.py", line 589, in execute
    uow,
  File "/home/user/.local/lib/python3.6/site-packages/sqlalchemy/orm/persistence.py", line 245, in save_obj
    insert,
  File "/home/user/.local/lib/python3.6/site-packages/sqlalchemy/orm/persistence.py", line 1136, in _emit_insert_statements
    statement, params
  File "/home/user/.local/lib/python3.6/site-packages/sqlalchemy/engine/base.py", line 984, in execute
    return meth(self, multiparams, params)
  File "/home/user/.local/lib/python3.6/site-packages/sqlalchemy/sql/elements.py", line 293, in _execute_on_connection
    return connection._execute_clauseelement(self, multiparams, params)
  File "/home/user/.local/lib/python3.6/site-packages/sqlalchemy/engine/base.py", line 1103, in _execute_clauseelement
    distilled_params,
  File "/home/user/.local/lib/python3.6/site-packages/sqlalchemy/engine/base.py", line 1288, in _execute_context
    e, statement, parameters, cursor, context
  File "/home/user/.local/lib/python3.6/site-packages/sqlalchemy/engine/base.py", line 1482, in _handle_dbapi_exception
    sqlalchemy_exception, with_traceback=exc_info[2], from_=e
  File "/home/user/.local/lib/python3.6/site-packages/sqlalchemy/util/compat.py", line 178, in raise_
    raise exception
  File "/home/user/.local/lib/python3.6/site-packages/sqlalchemy/engine/base.py", line 1248, in _execute_context
    cursor, statement, parameters, context
  File "/home/user/.local/lib/python3.6/site-packages/sqlalchemy/engine/default.py", line 590, in do_execute
    cursor.execute(statement, parameters)
  File "/home/user/.local/lib/python3.6/site-packages/MySQLdb/cursors.py", line 209, in execute
    res = self._query(query)
  File "/home/user/.local/lib/python3.6/site-packages/MySQLdb/cursors.py", line 315, in _query
    db.query(q)
  File "/home/user/.local/lib/python3.6/site-packages/MySQLdb/connections.py", line 239, in query
    _mysql.connection.query(self, query)
sqlalchemy.exc.OperationalError: (MySQLdb._exceptions.OperationalError) (1048, "Column 'name' cannot be null")
[SQL: INSERT INTO stock (name, energy, carbohydrates, sugars, fats, saturates, protein, fibre, salt) VALUES (%s, %s, %s, %s, %s, %s, %s, %s, %s)]
[parameters: (None, None, None, None, None, None, None, None, None)]
(Background on this error at: http://sqlalche.me/e/e3q8)
DEBUG:scrapy.core.engine:Crawled (200) <GET https://groceries.asda.com/product/910000020309 via http://0.0.0.0:8050/render.html> (referer: None)
DEBUG:scrapy.core.engine:Crawled (200) <GET https://groceries.asda.com/product/1639642 via http://0.0.0.0:8050/render.html> (referer: None)
DEBUG:scrapy.core.engine:Crawled (200) <GET https://groceries.asda.com/product/910000396129 via http://0.0.0.0:8050/render.html> (referer: None)
DEBUG:scrapy.core.engine:Crawled (200) <GET https://groceries.asda.com/product/25857 via http://0.0.0.0:8050/render.html> (referer: None)
DEBUG:scrapy.core.engine:Crawled (200) <GET https://groceries.asda.com/product/910000057722 via http://0.0.0.0:8050/render.html> (referer: None)
DEBUG:scrapy.core.engine:Crawled (200) <GET https://groceries.asda.com/product/1217550 via http://0.0.0.0:8050/render.html> (referer: None)
DEBUG:scrapy.core.engine:Crawled (200) <GET https://groceries.asda.com/product/80975593 via http://0.0.0.0:8050/render.html> (referer: None)
ERROR:scrapy.core.scraper:Error processing {'Carbohydrate': '1.4 g',
 'Date': datetime.datetime(2020, 5, 6, 9, 21, 14, 438386),
 'Energy': '726 kcal',
 'Fat': '79 g',
 'Name': "Hellmann's Squeezy Real Mayonnaise",
 'Price': '£1.99',
 'Protein': '1.1 g',
 'Salt': '1.5 g',
 'Saturates': '6.3 g',
 'Sugars': '1.3 g',
 'Supermarket': 'Asda',
 'item_url': 'https://groceries.asda.com/product/910000020309'}
Traceback (most recent call last):
  File "/home/user/.local/lib/python3.6/site-packages/sqlalchemy/engine/base.py", line 1248, in _execute_context
    cursor, statement, parameters, context
  File "/home/user/.local/lib/python3.6/site-packages/sqlalchemy/engine/default.py", line 590, in do_execute
    cursor.execute(statement, parameters)
  File "/home/user/.local/lib/python3.6/site-packages/MySQLdb/cursors.py", line 209, in execute
    res = self._query(query)
  File "/home/user/.local/lib/python3.6/site-packages/MySQLdb/cursors.py", line 315, in _query
    db.query(q)
  File "/home/user/.local/lib/python3.6/site-packages/MySQLdb/connections.py", line 239, in query
    _mysql.connection.query(self, query)
MySQLdb._exceptions.OperationalError: (1048, "Column 'name' cannot be null")

The above exception was the direct cause of the following exception:

Traceback (most recent call last):
  File "/home/user/.local/lib/python3.6/site-packages/twisted/internet/defer.py", line 654, in _runCallbacks
    current.result = callback(current.result, *args, **kw)
  File "/home/user/.local/lib/python3.6/site-packages/scrapy/utils/defer.py", line 154, in f
    return deferred_from_coro(coro_f(*coro_args, **coro_kwargs))
  File "/home/user/Documents/PythonScripts/shopscrap/shopscrap/pipelines.py", line 98, in process_item
    session.flush()
  File "/home/user/.local/lib/python3.6/site-packages/sqlalchemy/orm/session.py", line 2496, in flush
    self._flush(objects)
  File "/home/user/.local/lib/python3.6/site-packages/sqlalchemy/orm/session.py", line 2637, in _flush
    transaction.rollback(_capture_exception=True)
  File "/home/user/.local/lib/python3.6/site-packages/sqlalchemy/util/langhelpers.py", line 69, in __exit__
    exc_value, with_traceback=exc_tb,
  File "/home/user/.local/lib/python3.6/site-packages/sqlalchemy/util/compat.py", line 178, in raise_
    raise exception
  File "/home/user/.local/lib/python3.6/site-packages/sqlalchemy/orm/session.py", line 2597, in _flush
    flush_context.execute()
  File "/home/user/.local/lib/python3.6/site-packages/sqlalchemy/orm/unitofwork.py", line 422, in execute
    rec.execute(self)
  File "/home/user/.local/lib/python3.6/site-packages/sqlalchemy/orm/unitofwork.py", line 589, in execute
    uow,
  File "/home/user/.local/lib/python3.6/site-packages/sqlalchemy/orm/persistence.py", line 245, in save_obj
    insert,
  File "/home/user/.local/lib/python3.6/site-packages/sqlalchemy/orm/persistence.py", line 1136, in _emit_insert_statements
    statement, params
  File "/home/user/.local/lib/python3.6/site-packages/sqlalchemy/engine/base.py", line 984, in execute
    return meth(self, multiparams, params)
  File "/home/user/.local/lib/python3.6/site-packages/sqlalchemy/sql/elements.py", line 293, in _execute_on_connection
    return connection._execute_clauseelement(self, multiparams, params)
  File "/home/user/.local/lib/python3.6/site-packages/sqlalchemy/engine/base.py", line 1103, in _execute_clauseelement
    distilled_params,
  File "/home/user/.local/lib/python3.6/site-packages/sqlalchemy/engine/base.py", line 1288, in _execute_context
    e, statement, parameters, cursor, context
  File "/home/user/.local/lib/python3.6/site-packages/sqlalchemy/engine/base.py", line 1482, in _handle_dbapi_exception
    sqlalchemy_exception, with_traceback=exc_info[2], from_=e
  File "/home/user/.local/lib/python3.6/site-packages/sqlalchemy/util/compat.py", line 178, in raise_
    raise exception
  File "/home/user/.local/lib/python3.6/site-packages/sqlalchemy/engine/base.py", line 1248, in _execute_context
    cursor, statement, parameters, context
  File "/home/user/.local/lib/python3.6/site-packages/sqlalchemy/engine/default.py", line 590, in do_execute
    cursor.execute(statement, parameters)
  File "/home/user/.local/lib/python3.6/site-packages/MySQLdb/cursors.py", line 209, in execute
    res = self._query(query)
  File "/home/user/.local/lib/python3.6/site-packages/MySQLdb/cursors.py", line 315, in _query
    db.query(q)
  File "/home/user/.local/lib/python3.6/site-packages/MySQLdb/connections.py", line 239, in query
    _mysql.connection.query(self, query)
sqlalchemy.exc.OperationalError: (MySQLdb._exceptions.OperationalError) (1048, "Column 'name' cannot be null")
[SQL: INSERT INTO stock (name, energy, carbohydrates, sugars, fats, saturates, protein, fibre, salt) VALUES (%s, %s, %s, %s, %s, %s, %s, %s, %s)]
[parameters: (None, None, None, None, None, None, None, None, None)]
(Background on this error at: http://sqlalche.me/e/e3q8)
DEBUG:scrapy.dupefilters:Filtered duplicate request: <GET https://groceries.asda.com/product/910000212250> - no more duplicates will be shown (see DUPEFILTER_DEBUG to show all duplicates)
ERROR:scrapy.core.scraper:Error processing {'Carbohydrate': '64.9g',
 'Date': datetime.datetime(2020, 5, 6, 9, 21, 14, 483757),
 'Energy': '2065kJ',
 'Fat': '23.7g',
 'Name': 'Twix Chocolate Biscuit Fingers Multipack',
 'Price': '£2.00',
 'Protein': '4.4g',
 'Salt': '0.41g',
 'Saturates': '13.7g',
 'Sugars': '49.1g',
 'Supermarket': 'Asda',
 'item_url': 'https://groceries.asda.com/product/1639642'}
Traceback (most recent call last):
  File "/home/user/.local/lib/python3.6/site-packages/sqlalchemy/engine/base.py", line 1248, in _execute_context
    cursor, statement, parameters, context
  File "/home/user/.local/lib/python3.6/site-packages/sqlalchemy/engine/default.py", line 590, in do_execute
    cursor.execute(statement, parameters)
  File "/home/user/.local/lib/python3.6/site-packages/MySQLdb/cursors.py", line 209, in execute
    res = self._query(query)
  File "/home/user/.local/lib/python3.6/site-packages/MySQLdb/cursors.py", line 315, in _query
    db.query(q)
  File "/home/user/.local/lib/python3.6/site-packages/MySQLdb/connections.py", line 239, in query
    _mysql.connection.query(self, query)
MySQLdb._exceptions.OperationalError: (1048, "Column 'name' cannot be null")

The above exception was the direct cause of the following exception:

Traceback (most recent call last):
  File "/home/user/.local/lib/python3.6/site-packages/twisted/internet/defer.py", line 654, in _runCallbacks
    current.result = callback(current.result, *args, **kw)
  File "/home/user/.local/lib/python3.6/site-packages/scrapy/utils/defer.py", line 154, in f
    return deferred_from_coro(coro_f(*coro_args, **coro_kwargs))
  File "/home/user/Documents/PythonScripts/shopscrap/shopscrap/pipelines.py", line 98, in process_item
    session.flush()
  File "/home/user/.local/lib/python3.6/site-packages/sqlalchemy/orm/session.py", line 2496, in flush
    self._flush(objects)
  File "/home/user/.local/lib/python3.6/site-packages/sqlalchemy/orm/session.py", line 2637, in _flush
    transaction.rollback(_capture_exception=True)
  File "/home/user/.local/lib/python3.6/site-packages/sqlalchemy/util/langhelpers.py", line 69, in __exit__
    exc_value, with_traceback=exc_tb,
  File "/home/user/.local/lib/python3.6/site-packages/sqlalchemy/util/compat.py", line 178, in raise_
    raise exception
  File "/home/user/.local/lib/python3.6/site-packages/sqlalchemy/orm/session.py", line 2597, in _flush
    flush_context.execute()
  File "/home/user/.local/lib/python3.6/site-packages/sqlalchemy/orm/unitofwork.py", line 422, in execute
    rec.execute(self)
  File "/home/user/.local/lib/python3.6/site-packages/sqlalchemy/orm/unitofwork.py", line 589, in execute
    uow,
  File "/home/user/.local/lib/python3.6/site-packages/sqlalchemy/orm/persistence.py", line 245, in save_obj
    insert,
  File "/home/user/.local/lib/python3.6/site-packages/sqlalchemy/orm/persistence.py", line 1136, in _emit_insert_statements
    statement, params
  File "/home/user/.local/lib/python3.6/site-packages/sqlalchemy/engine/base.py", line 984, in execute
    return meth(self, multiparams, params)
  File "/home/user/.local/lib/python3.6/site-packages/sqlalchemy/sql/elements.py", line 293, in _execute_on_connection
    return connection._execute_clauseelement(self, multiparams, params)
  File "/home/user/.local/lib/python3.6/site-packages/sqlalchemy/engine/base.py", line 1103, in _execute_clauseelement
    distilled_params,
  File "/home/user/.local/lib/python3.6/site-packages/sqlalchemy/engine/base.py", line 1288, in _execute_context
    e, statement, parameters, cursor, context
  File "/home/user/.local/lib/python3.6/site-packages/sqlalchemy/engine/base.py", line 1482, in _handle_dbapi_exception
    sqlalchemy_exception, with_traceback=exc_info[2], from_=e
  File "/home/user/.local/lib/python3.6/site-packages/sqlalchemy/util/compat.py", line 178, in raise_
    raise exception
  File "/home/user/.local/lib/python3.6/site-packages/sqlalchemy/engine/base.py", line 1248, in _execute_context
    cursor, statement, parameters, context
  File "/home/user/.local/lib/python3.6/site-packages/sqlalchemy/engine/default.py", line 590, in do_execute
    cursor.execute(statement, parameters)
  File "/home/user/.local/lib/python3.6/site-packages/MySQLdb/cursors.py", line 209, in execute
    res = self._query(query)
  File "/home/user/.local/lib/python3.6/site-packages/MySQLdb/cursors.py", line 315, in _query
    db.query(q)
  File "/home/user/.local/lib/python3.6/site-packages/MySQLdb/connections.py", line 239, in query
    _mysql.connection.query(self, query)
sqlalchemy.exc.OperationalError: (MySQLdb._exceptions.OperationalError) (1048, "Column 'name' cannot be null")
[SQL: INSERT INTO stock (name, energy, carbohydrates, sugars, fats, saturates, protein, fibre, salt) VALUES (%s, %s, %s, %s, %s, %s, %s, %s, %s)]
[parameters: (None, None, None, None, None, None, None, None, None)]
(Background on this error at: http://sqlalche.me/e/e3q8)
ERROR:scrapy.core.scraper:Error processing {'Carbohydrate': '86g',
 'Date': datetime.datetime(2020, 5, 6, 9, 21, 14, 509711),
 'Energy': '387kcal',
 'Fat': '1.2g',
 'Fibre': '2.0g',
 'Name': "Kellogg's Rice Krispies",
 'Price': '£3.00',
 'Protein': '7g',
 'Salt': '1g',
 'Saturates': '0.4g',
 'Sugars': '7.9g',
 'Supermarket': 'Asda',
 'item_url': 'https://groceries.asda.com/product/910000396129'}
Traceback (most recent call last):
  File "/home/user/.local/lib/python3.6/site-packages/sqlalchemy/engine/base.py", line 1248, in _execute_context
    cursor, statement, parameters, context
  File "/home/user/.local/lib/python3.6/site-packages/sqlalchemy/engine/default.py", line 590, in do_execute
    cursor.execute(statement, parameters)
  File "/home/user/.local/lib/python3.6/site-packages/MySQLdb/cursors.py", line 209, in execute
    res = self._query(query)
  File "/home/user/.local/lib/python3.6/site-packages/MySQLdb/cursors.py", line 315, in _query
    db.query(q)
  File "/home/user/.local/lib/python3.6/site-packages/MySQLdb/connections.py", line 239, in query
    _mysql.connection.query(self, query)
MySQLdb._exceptions.OperationalError: (1048, "Column 'name' cannot be null")

The above exception was the direct cause of the following exception:

Traceback (most recent call last):
  File "/home/user/.local/lib/python3.6/site-packages/twisted/internet/defer.py", line 654, in _runCallbacks
    current.result = callback(current.result, *args, **kw)
  File "/home/user/.local/lib/python3.6/site-packages/scrapy/utils/defer.py", line 154, in f
    return deferred_from_coro(coro_f(*coro_args, **coro_kwargs))
  File "/home/user/Documents/PythonScripts/shopscrap/shopscrap/pipelines.py", line 98, in process_item
    session.flush()
  File "/home/user/.local/lib/python3.6/site-packages/sqlalchemy/orm/session.py", line 2496, in flush
    self._flush(objects)
  File "/home/user/.local/lib/python3.6/site-packages/sqlalchemy/orm/session.py", line 2637, in _flush
    transaction.rollback(_capture_exception=True)
  File "/home/user/.local/lib/python3.6/site-packages/sqlalchemy/util/langhelpers.py", line 69, in __exit__
    exc_value, with_traceback=exc_tb,
  File "/home/user/.local/lib/python3.6/site-packages/sqlalchemy/util/compat.py", line 178, in raise_
    raise exception
  File "/home/user/.local/lib/python3.6/site-packages/sqlalchemy/orm/session.py", line 2597, in _flush
    flush_context.execute()
  File "/home/user/.local/lib/python3.6/site-packages/sqlalchemy/orm/unitofwork.py", line 422, in execute
    rec.execute(self)
  File "/home/user/.local/lib/python3.6/site-packages/sqlalchemy/orm/unitofwork.py", line 589, in execute
    uow,
  File "/home/user/.local/lib/python3.6/site-packages/sqlalchemy/orm/persistence.py", line 245, in save_obj
    insert,
  File "/home/user/.local/lib/python3.6/site-packages/sqlalchemy/orm/persistence.py", line 1136, in _emit_insert_statements
    statement, params
  File "/home/user/.local/lib/python3.6/site-packages/sqlalchemy/engine/base.py", line 984, in execute
    return meth(self, multiparams, params)
  File "/home/user/.local/lib/python3.6/site-packages/sqlalchemy/sql/elements.py", line 293, in _execute_on_connection
    return connection._execute_clauseelement(self, multiparams, params)
  File "/home/user/.local/lib/python3.6/site-packages/sqlalchemy/engine/base.py", line 1103, in _execute_clauseelement
    distilled_params,
  File "/home/user/.local/lib/python3.6/site-packages/sqlalchemy/engine/base.py", line 1288, in _execute_context
    e, statement, parameters, cursor, context
  File "/home/user/.local/lib/python3.6/site-packages/sqlalchemy/engine/base.py", line 1482, in _handle_dbapi_exception
    sqlalchemy_exception, with_traceback=exc_info[2], from_=e
  File "/home/user/.local/lib/python3.6/site-packages/sqlalchemy/util/compat.py", line 178, in raise_
    raise exception
  File "/home/user/.local/lib/python3.6/site-packages/sqlalchemy/engine/base.py", line 1248, in _execute_context
    cursor, statement, parameters, context
  File "/home/user/.local/lib/python3.6/site-packages/sqlalchemy/engine/default.py", line 590, in do_execute
    cursor.execute(statement, parameters)
  File "/home/user/.local/lib/python3.6/site-packages/MySQLdb/cursors.py", line 209, in execute
    res = self._query(query)
  File "/home/user/.local/lib/python3.6/site-packages/MySQLdb/cursors.py", line 315, in _query
    db.query(q)
  File "/home/user/.local/lib/python3.6/site-packages/MySQLdb/connections.py", line 239, in query
    _mysql.connection.query(self, query)
sqlalchemy.exc.OperationalError: (MySQLdb._exceptions.OperationalError) (1048, "Column 'name' cannot be null")
[SQL: INSERT INTO stock (name, energy, carbohydrates, sugars, fats, saturates, protein, fibre, salt) VALUES (%s, %s, %s, %s, %s, %s, %s, %s, %s)]
[parameters: (None, None, None, None, None, None, None, None, None)]
(Background on this error at: http://sqlalche.me/e/e3q8)
ERROR:scrapy.core.scraper:Error processing {'Carbohydrate': '41.2 g',
 'Date': datetime.datetime(2020, 5, 6, 9, 21, 14, 546575),
 'Energy': '954 kJ / 226 kcal',
 'Fat': '3.5 g',
 'Fibre': '1.5 g',
 'Name': 'Old El Paso Mexican Original Smoky BBQ Fajita Kit',
 'Price': '£3.18',
 'Protein': '6.6 g',
 'Salt': '1.99 g',
 'Saturates': '0.8 g',
 'Sugars': '6.2 g',
 'Supermarket': 'Asda',
 'item_url': 'https://groceries.asda.com/product/25857'}
Traceback (most recent call last):
  File "/home/user/.local/lib/python3.6/site-packages/sqlalchemy/engine/base.py", line 1248, in _execute_context
    cursor, statement, parameters, context
  File "/home/user/.local/lib/python3.6/site-packages/sqlalchemy/engine/default.py", line 590, in do_execute
    cursor.execute(statement, parameters)
  File "/home/user/.local/lib/python3.6/site-packages/MySQLdb/cursors.py", line 209, in execute
    res = self._query(query)
  File "/home/user/.local/lib/python3.6/site-packages/MySQLdb/cursors.py", line 315, in _query
    db.query(q)
  File "/home/user/.local/lib/python3.6/site-packages/MySQLdb/connections.py", line 239, in query
    _mysql.connection.query(self, query)
MySQLdb._exceptions.OperationalError: (1048, "Column 'name' cannot be null")

The above exception was the direct cause of the following exception:

Traceback (most recent call last):
  File "/home/user/.local/lib/python3.6/site-packages/twisted/internet/defer.py", line 654, in _runCallbacks
    current.result = callback(current.result, *args, **kw)
  File "/home/user/.local/lib/python3.6/site-packages/scrapy/utils/defer.py", line 154, in f
    return deferred_from_coro(coro_f(*coro_args, **coro_kwargs))
  File "/home/user/Documents/PythonScripts/shopscrap/shopscrap/pipelines.py", line 98, in process_item
    session.flush()
  File "/home/user/.local/lib/python3.6/site-packages/sqlalchemy/orm/session.py", line 2496, in flush
    self._flush(objects)
  File "/home/user/.local/lib/python3.6/site-packages/sqlalchemy/orm/session.py", line 2637, in _flush
    transaction.rollback(_capture_exception=True)
  File "/home/user/.local/lib/python3.6/site-packages/sqlalchemy/util/langhelpers.py", line 69, in __exit__
    exc_value, with_traceback=exc_tb,
  File "/home/user/.local/lib/python3.6/site-packages/sqlalchemy/util/compat.py", line 178, in raise_
    raise exception
  File "/home/user/.local/lib/python3.6/site-packages/sqlalchemy/orm/session.py", line 2597, in _flush
    flush_context.execute()
  File "/home/user/.local/lib/python3.6/site-packages/sqlalchemy/orm/unitofwork.py", line 422, in execute
    rec.execute(self)
  File "/home/user/.local/lib/python3.6/site-packages/sqlalchemy/orm/unitofwork.py", line 589, in execute
    uow,
  File "/home/user/.local/lib/python3.6/site-packages/sqlalchemy/orm/persistence.py", line 245, in save_obj
    insert,
  File "/home/user/.local/lib/python3.6/site-packages/sqlalchemy/orm/persistence.py", line 1136, in _emit_insert_statements
    statement, params
  File "/home/user/.local/lib/python3.6/site-packages/sqlalchemy/engine/base.py", line 984, in execute
    return meth(self, multiparams, params)
  File "/home/user/.local/lib/python3.6/site-packages/sqlalchemy/sql/elements.py", line 293, in _execute_on_connection
    return connection._execute_clauseelement(self, multiparams, params)
  File "/home/user/.local/lib/python3.6/site-packages/sqlalchemy/engine/base.py", line 1103, in _execute_clauseelement
    distilled_params,
  File "/home/user/.local/lib/python3.6/site-packages/sqlalchemy/engine/base.py", line 1288, in _execute_context
    e, statement, parameters, cursor, context
  File "/home/user/.local/lib/python3.6/site-packages/sqlalchemy/engine/base.py", line 1482, in _handle_dbapi_exception
    sqlalchemy_exception, with_traceback=exc_info[2], from_=e
  File "/home/user/.local/lib/python3.6/site-packages/sqlalchemy/util/compat.py", line 178, in raise_
    raise exception
  File "/home/user/.local/lib/python3.6/site-packages/sqlalchemy/engine/base.py", line 1248, in _execute_context
    cursor, statement, parameters, context
  File "/home/user/.local/lib/python3.6/site-packages/sqlalchemy/engine/default.py", line 590, in do_execute
    cursor.execute(statement, parameters)
  File "/home/user/.local/lib/python3.6/site-packages/MySQLdb/cursors.py", line 209, in execute
    res = self._query(query)
  File "/home/user/.local/lib/python3.6/site-packages/MySQLdb/cursors.py", line 315, in _query
    db.query(q)
  File "/home/user/.local/lib/python3.6/site-packages/MySQLdb/connections.py", line 239, in query
    _mysql.connection.query(self, query)
sqlalchemy.exc.OperationalError: (MySQLdb._exceptions.OperationalError) (1048, "Column 'name' cannot be null")
[SQL: INSERT INTO stock (name, energy, carbohydrates, sugars, fats, saturates, protein, fibre, salt) VALUES (%s, %s, %s, %s, %s, %s, %s, %s, %s)]
[parameters: (None, None, None, None, None, None, None, None, None)]
(Background on this error at: http://sqlalche.me/e/e3q8)
ERROR:scrapy.core.scraper:Error processing {'Carbohydrate': '1.3 g',
 'Date': datetime.datetime(2020, 5, 6, 9, 21, 14, 580790),
 'Energy': '721 kcal',
 'Fat': '79 g',
 'Name': "Hellmann's Real Mayonnaise",
 'Price': '£3.00',
 'Protein': '1.1 g',
 'Salt': '1.5 g',
 'Saturates': '6.2 g',
 'Sugars': '1.3 g',
 'Supermarket': 'Asda',
 'item_url': 'https://groceries.asda.com/product/910000057722'}
Traceback (most recent call last):
  File "/home/user/.local/lib/python3.6/site-packages/sqlalchemy/engine/base.py", line 1248, in _execute_context
    cursor, statement, parameters, context
  File "/home/user/.local/lib/python3.6/site-packages/sqlalchemy/engine/default.py", line 590, in do_execute
    cursor.execute(statement, parameters)
  File "/home/user/.local/lib/python3.6/site-packages/MySQLdb/cursors.py", line 209, in execute
    res = self._query(query)
  File "/home/user/.local/lib/python3.6/site-packages/MySQLdb/cursors.py", line 315, in _query
    db.query(q)
  File "/home/user/.local/lib/python3.6/site-packages/MySQLdb/connections.py", line 239, in query
    _mysql.connection.query(self, query)
MySQLdb._exceptions.OperationalError: (1048, "Column 'name' cannot be null")

The above exception was the direct cause of the following exception:

Traceback (most recent call last):
  File "/home/user/.local/lib/python3.6/site-packages/twisted/internet/defer.py", line 654, in _runCallbacks
    current.result = callback(current.result, *args, **kw)
  File "/home/user/.local/lib/python3.6/site-packages/scrapy/utils/defer.py", line 154, in f
    return deferred_from_coro(coro_f(*coro_args, **coro_kwargs))
  File "/home/user/Documents/PythonScripts/shopscrap/shopscrap/pipelines.py", line 98, in process_item
    session.flush()
  File "/home/user/.local/lib/python3.6/site-packages/sqlalchemy/orm/session.py", line 2496, in flush
    self._flush(objects)
  File "/home/user/.local/lib/python3.6/site-packages/sqlalchemy/orm/session.py", line 2637, in _flush
    transaction.rollback(_capture_exception=True)
  File "/home/user/.local/lib/python3.6/site-packages/sqlalchemy/util/langhelpers.py", line 69, in __exit__
    exc_value, with_traceback=exc_tb,
  File "/home/user/.local/lib/python3.6/site-packages/sqlalchemy/util/compat.py", line 178, in raise_
    raise exception
  File "/home/user/.local/lib/python3.6/site-packages/sqlalchemy/orm/session.py", line 2597, in _flush
    flush_context.execute()
  File "/home/user/.local/lib/python3.6/site-packages/sqlalchemy/orm/unitofwork.py", line 422, in execute
    rec.execute(self)
  File "/home/user/.local/lib/python3.6/site-packages/sqlalchemy/orm/unitofwork.py", line 589, in execute
    uow,
  File "/home/user/.local/lib/python3.6/site-packages/sqlalchemy/orm/persistence.py", line 245, in save_obj
    insert,
  File "/home/user/.local/lib/python3.6/site-packages/sqlalchemy/orm/persistence.py", line 1136, in _emit_insert_statements
    statement, params
  File "/home/user/.local/lib/python3.6/site-packages/sqlalchemy/engine/base.py", line 984, in execute
    return meth(self, multiparams, params)
  File "/home/user/.local/lib/python3.6/site-packages/sqlalchemy/sql/elements.py", line 293, in _execute_on_connection
    return connection._execute_clauseelement(self, multiparams, params)
  File "/home/user/.local/lib/python3.6/site-packages/sqlalchemy/engine/base.py", line 1103, in _execute_clauseelement
    distilled_params,
  File "/home/user/.local/lib/python3.6/site-packages/sqlalchemy/engine/base.py", line 1288, in _execute_context
    e, statement, parameters, cursor, context
  File "/home/user/.local/lib/python3.6/site-packages/sqlalchemy/engine/base.py", line 1482, in _handle_dbapi_exception
    sqlalchemy_exception, with_traceback=exc_info[2], from_=e
  File "/home/user/.local/lib/python3.6/site-packages/sqlalchemy/util/compat.py", line 178, in raise_
    raise exception
  File "/home/user/.local/lib/python3.6/site-packages/sqlalchemy/engine/base.py", line 1248, in _execute_context
    cursor, statement, parameters, context
  File "/home/user/.local/lib/python3.6/site-packages/sqlalchemy/engine/default.py", line 590, in do_execute
    cursor.execute(statement, parameters)
  File "/home/user/.local/lib/python3.6/site-packages/MySQLdb/cursors.py", line 209, in execute
    res = self._query(query)
  File "/home/user/.local/lib/python3.6/site-packages/MySQLdb/cursors.py", line 315, in _query
    db.query(q)
  File "/home/user/.local/lib/python3.6/site-packages/MySQLdb/connections.py", line 239, in query
    _mysql.connection.query(self, query)
sqlalchemy.exc.OperationalError: (MySQLdb._exceptions.OperationalError) (1048, "Column 'name' cannot be null")
[SQL: INSERT INTO stock (name, energy, carbohydrates, sugars, fats, saturates, protein, fibre, salt) VALUES (%s, %s, %s, %s, %s, %s, %s, %s, %s)]
[parameters: (None, None, None, None, None, None, None, None, None)]
(Background on this error at: http://sqlalche.me/e/e3q8)
ERROR:scrapy.core.scraper:Error processing {'Carbohydrate': '79g',
 'Date': datetime.datetime(2020, 5, 6, 9, 21, 14, 601509),
 'Energy': '1588kJ',
 'Fat': '1.5g',
 'Fibre': '4.5g',
 'Name': "Kellogg's Special K Original",
 'Price': '£3.98',
 'Protein': '9g',
 'Salt': '1g',
 'Saturates': '0.3g',
 'Sugars': '15g',
 'Supermarket': 'Asda',
 'item_url': 'https://groceries.asda.com/product/1217550'}
Traceback (most recent call last):
  File "/home/user/.local/lib/python3.6/site-packages/sqlalchemy/engine/base.py", line 1248, in _execute_context
    cursor, statement, parameters, context
  File "/home/user/.local/lib/python3.6/site-packages/sqlalchemy/engine/default.py", line 590, in do_execute
    cursor.execute(statement, parameters)
  File "/home/user/.local/lib/python3.6/site-packages/MySQLdb/cursors.py", line 209, in execute
    res = self._query(query)
  File "/home/user/.local/lib/python3.6/site-packages/MySQLdb/cursors.py", line 315, in _query
    db.query(q)
  File "/home/user/.local/lib/python3.6/site-packages/MySQLdb/connections.py", line 239, in query
    _mysql.connection.query(self, query)
MySQLdb._exceptions.OperationalError: (1048, "Column 'name' cannot be null")

The above exception was the direct cause of the following exception:

Traceback (most recent call last):
  File "/home/user/.local/lib/python3.6/site-packages/twisted/internet/defer.py", line 654, in _runCallbacks
    current.result = callback(current.result, *args, **kw)
  File "/home/user/.local/lib/python3.6/site-packages/scrapy/utils/defer.py", line 154, in f
    return deferred_from_coro(coro_f(*coro_args, **coro_kwargs))
  File "/home/user/Documents/PythonScripts/shopscrap/shopscrap/pipelines.py", line 98, in process_item
    session.flush()
  File "/home/user/.local/lib/python3.6/site-packages/sqlalchemy/orm/session.py", line 2496, in flush
    self._flush(objects)
  File "/home/user/.local/lib/python3.6/site-packages/sqlalchemy/orm/session.py", line 2637, in _flush
    transaction.rollback(_capture_exception=True)
  File "/home/user/.local/lib/python3.6/site-packages/sqlalchemy/util/langhelpers.py", line 69, in __exit__
    exc_value, with_traceback=exc_tb,
  File "/home/user/.local/lib/python3.6/site-packages/sqlalchemy/util/compat.py", line 178, in raise_
    raise exception
  File "/home/user/.local/lib/python3.6/site-packages/sqlalchemy/orm/session.py", line 2597, in _flush
    flush_context.execute()
  File "/home/user/.local/lib/python3.6/site-packages/sqlalchemy/orm/unitofwork.py", line 422, in execute
    rec.execute(self)
  File "/home/user/.local/lib/python3.6/site-packages/sqlalchemy/orm/unitofwork.py", line 589, in execute
    uow,
  File "/home/user/.local/lib/python3.6/site-packages/sqlalchemy/orm/persistence.py", line 245, in save_obj
    insert,
  File "/home/user/.local/lib/python3.6/site-packages/sqlalchemy/orm/persistence.py", line 1136, in _emit_insert_statements
    statement, params
  File "/home/user/.local/lib/python3.6/site-packages/sqlalchemy/engine/base.py", line 984, in execute
    return meth(self, multiparams, params)
  File "/home/user/.local/lib/python3.6/site-packages/sqlalchemy/sql/elements.py", line 293, in _execute_on_connection
    return connection._execute_clauseelement(self, multiparams, params)
  File "/home/user/.local/lib/python3.6/site-packages/sqlalchemy/engine/base.py", line 1103, in _execute_clauseelement
    distilled_params,
  File "/home/user/.local/lib/python3.6/site-packages/sqlalchemy/engine/base.py", line 1288, in _execute_context
    e, statement, parameters, cursor, context
  File "/home/user/.local/lib/python3.6/site-packages/sqlalchemy/engine/base.py", line 1482, in _handle_dbapi_exception
    sqlalchemy_exception, with_traceback=exc_info[2], from_=e
  File "/home/user/.local/lib/python3.6/site-packages/sqlalchemy/util/compat.py", line 178, in raise_
    raise exception
  File "/home/user/.local/lib/python3.6/site-packages/sqlalchemy/engine/base.py", line 1248, in _execute_context
    cursor, statement, parameters, context
  File "/home/user/.local/lib/python3.6/site-packages/sqlalchemy/engine/default.py", line 590, in do_execute
    cursor.execute(statement, parameters)
  File "/home/user/.local/lib/python3.6/site-packages/MySQLdb/cursors.py", line 209, in execute
    res = self._query(query)
  File "/home/user/.local/lib/python3.6/site-packages/MySQLdb/cursors.py", line 315, in _query
    db.query(q)
  File "/home/user/.local/lib/python3.6/site-packages/MySQLdb/connections.py", line 239, in query
    _mysql.connection.query(self, query)
sqlalchemy.exc.OperationalError: (MySQLdb._exceptions.OperationalError) (1048, "Column 'name' cannot be null")
[SQL: INSERT INTO stock (name, energy, carbohydrates, sugars, fats, saturates, protein, fibre, salt) VALUES (%s, %s, %s, %s, %s, %s, %s, %s, %s)]
[parameters: (None, None, None, None, None, None, None, None, None)]
(Background on this error at: http://sqlalche.me/e/e3q8)
ERROR:scrapy.core.scraper:Error processing {'Carbohydrate': '53.5',
 'Date': datetime.datetime(2020, 5, 6, 9, 21, 14, 627633),
 'Energy': '2360/566',
 'Fat': '35',
 'Name': 'Kinder Chocolate Bar 16 Pack',
 'Price': '£1.50',
 'Protein': '8.7',
 'Salt': '0.313',
 'Supermarket': 'Asda',
 'item_url': 'https://groceries.asda.com/product/80975593'}
Traceback (most recent call last):
  File "/home/user/.local/lib/python3.6/site-packages/sqlalchemy/engine/base.py", line 1248, in _execute_context
    cursor, statement, parameters, context
  File "/home/user/.local/lib/python3.6/site-packages/sqlalchemy/engine/default.py", line 590, in do_execute
    cursor.execute(statement, parameters)
  File "/home/user/.local/lib/python3.6/site-packages/MySQLdb/cursors.py", line 209, in execute
    res = self._query(query)
  File "/home/user/.local/lib/python3.6/site-packages/MySQLdb/cursors.py", line 315, in _query
    db.query(q)
  File "/home/user/.local/lib/python3.6/site-packages/MySQLdb/connections.py", line 239, in query
    _mysql.connection.query(self, query)
MySQLdb._exceptions.OperationalError: (1048, "Column 'name' cannot be null")

The above exception was the direct cause of the following exception:

Traceback (most recent call last):
  File "/home/user/.local/lib/python3.6/site-packages/twisted/internet/defer.py", line 654, in _runCallbacks
    current.result = callback(current.result, *args, **kw)
  File "/home/user/.local/lib/python3.6/site-packages/scrapy/utils/defer.py", line 154, in f
    return deferred_from_coro(coro_f(*coro_args, **coro_kwargs))
  File "/home/user/Documents/PythonScripts/shopscrap/shopscrap/pipelines.py", line 98, in process_item
    session.flush()
  File "/home/user/.local/lib/python3.6/site-packages/sqlalchemy/orm/session.py", line 2496, in flush
    self._flush(objects)
  File "/home/user/.local/lib/python3.6/site-packages/sqlalchemy/orm/session.py", line 2637, in _flush
    transaction.rollback(_capture_exception=True)
  File "/home/user/.local/lib/python3.6/site-packages/sqlalchemy/util/langhelpers.py", line 69, in __exit__
    exc_value, with_traceback=exc_tb,
  File "/home/user/.local/lib/python3.6/site-packages/sqlalchemy/util/compat.py", line 178, in raise_
    raise exception
  File "/home/user/.local/lib/python3.6/site-packages/sqlalchemy/orm/session.py", line 2597, in _flush
    flush_context.execute()
  File "/home/user/.local/lib/python3.6/site-packages/sqlalchemy/orm/unitofwork.py", line 422, in execute
    rec.execute(self)
  File "/home/user/.local/lib/python3.6/site-packages/sqlalchemy/orm/unitofwork.py", line 589, in execute
    uow,
  File "/home/user/.local/lib/python3.6/site-packages/sqlalchemy/orm/persistence.py", line 245, in save_obj
    insert,
  File "/home/user/.local/lib/python3.6/site-packages/sqlalchemy/orm/persistence.py", line 1136, in _emit_insert_statements
    statement, params
  File "/home/user/.local/lib/python3.6/site-packages/sqlalchemy/engine/base.py", line 984, in execute
    return meth(self, multiparams, params)
  File "/home/user/.local/lib/python3.6/site-packages/sqlalchemy/sql/elements.py", line 293, in _execute_on_connection
    return connection._execute_clauseelement(self, multiparams, params)
  File "/home/user/.local/lib/python3.6/site-packages/sqlalchemy/engine/base.py", line 1103, in _execute_clauseelement
    distilled_params,
  File "/home/user/.local/lib/python3.6/site-packages/sqlalchemy/engine/base.py", line 1288, in _execute_context
    e, statement, parameters, cursor, context
  File "/home/user/.local/lib/python3.6/site-packages/sqlalchemy/engine/base.py", line 1482, in _handle_dbapi_exception
    sqlalchemy_exception, with_traceback=exc_info[2], from_=e
  File "/home/user/.local/lib/python3.6/site-packages/sqlalchemy/util/compat.py", line 178, in raise_
    raise exception
  File "/home/user/.local/lib/python3.6/site-packages/sqlalchemy/engine/base.py", line 1248, in _execute_context
    cursor, statement, parameters, context
  File "/home/user/.local/lib/python3.6/site-packages/sqlalchemy/engine/default.py", line 590, in do_execute
    cursor.execute(statement, parameters)
  File "/home/user/.local/lib/python3.6/site-packages/MySQLdb/cursors.py", line 209, in execute
    res = self._query(query)
  File "/home/user/.local/lib/python3.6/site-packages/MySQLdb/cursors.py", line 315, in _query
    db.query(q)
  File "/home/user/.local/lib/python3.6/site-packages/MySQLdb/connections.py", line 239, in query
    _mysql.connection.query(self, query)
sqlalchemy.exc.OperationalError: (MySQLdb._exceptions.OperationalError) (1048, "Column 'name' cannot be null")
[SQL: INSERT INTO stock (name, energy, carbohydrates, sugars, fats, saturates, protein, fibre, salt) VALUES (%s, %s, %s, %s, %s, %s, %s, %s, %s)]
[parameters: (None, None, None, None, None, None, None, None, None)]
(Background on this error at: http://sqlalche.me/e/e3q8)
DEBUG:scrapy.core.engine:Crawled (200) <GET https://groceries.asda.com/product/24076 via http://0.0.0.0:8050/render.html> (referer: None)
ERROR:scrapy.core.scraper:Error processing {'Carbohydrate': '28g',
 'Date': datetime.datetime(2020, 5, 6, 9, 21, 16, 2325),
 'Energy': '566kJ 134kcal',
 'Fat': '0.9g',
 'Fibre': '0.7g',
 'Name': "Uncle Ben's Long Grain Microwave Rice",
 'Price': '£1.00',
 'Protein': '2.7g',
 'Salt': '<0.01g',
 'Saturates': '0.1g',
 'Sugars': '<0.5g',
 'Supermarket': 'Asda',
 'item_url': 'https://groceries.asda.com/product/24076'}
Traceback (most recent call last):
  File "/home/user/.local/lib/python3.6/site-packages/sqlalchemy/engine/base.py", line 1248, in _execute_context
    cursor, statement, parameters, context
  File "/home/user/.local/lib/python3.6/site-packages/sqlalchemy/engine/default.py", line 590, in do_execute
    cursor.execute(statement, parameters)
  File "/home/user/.local/lib/python3.6/site-packages/MySQLdb/cursors.py", line 209, in execute
    res = self._query(query)
  File "/home/user/.local/lib/python3.6/site-packages/MySQLdb/cursors.py", line 315, in _query
    db.query(q)
  File "/home/user/.local/lib/python3.6/site-packages/MySQLdb/connections.py", line 239, in query
    _mysql.connection.query(self, query)
MySQLdb._exceptions.OperationalError: (1048, "Column 'name' cannot be null")

The above exception was the direct cause of the following exception:

Traceback (most recent call last):
  File "/home/user/.local/lib/python3.6/site-packages/twisted/internet/defer.py", line 654, in _runCallbacks
    current.result = callback(current.result, *args, **kw)
  File "/home/user/.local/lib/python3.6/site-packages/scrapy/utils/defer.py", line 154, in f
    return deferred_from_coro(coro_f(*coro_args, **coro_kwargs))
  File "/home/user/Documents/PythonScripts/shopscrap/shopscrap/pipelines.py", line 98, in process_item
    session.flush()
  File "/home/user/.local/lib/python3.6/site-packages/sqlalchemy/orm/session.py", line 2496, in flush
    self._flush(objects)
  File "/home/user/.local/lib/python3.6/site-packages/sqlalchemy/orm/session.py", line 2637, in _flush
    transaction.rollback(_capture_exception=True)
  File "/home/user/.local/lib/python3.6/site-packages/sqlalchemy/util/langhelpers.py", line 69, in __exit__
    exc_value, with_traceback=exc_tb,
  File "/home/user/.local/lib/python3.6/site-packages/sqlalchemy/util/compat.py", line 178, in raise_
    raise exception
  File "/home/user/.local/lib/python3.6/site-packages/sqlalchemy/orm/session.py", line 2597, in _flush
    flush_context.execute()
  File "/home/user/.local/lib/python3.6/site-packages/sqlalchemy/orm/unitofwork.py", line 422, in execute
    rec.execute(self)
  File "/home/user/.local/lib/python3.6/site-packages/sqlalchemy/orm/unitofwork.py", line 589, in execute
    uow,
  File "/home/user/.local/lib/python3.6/site-packages/sqlalchemy/orm/persistence.py", line 245, in save_obj
    insert,
  File "/home/user/.local/lib/python3.6/site-packages/sqlalchemy/orm/persistence.py", line 1136, in _emit_insert_statements
    statement, params
  File "/home/user/.local/lib/python3.6/site-packages/sqlalchemy/engine/base.py", line 984, in execute
    return meth(self, multiparams, params)
  File "/home/user/.local/lib/python3.6/site-packages/sqlalchemy/sql/elements.py", line 293, in _execute_on_connection
    return connection._execute_clauseelement(self, multiparams, params)
  File "/home/user/.local/lib/python3.6/site-packages/sqlalchemy/engine/base.py", line 1103, in _execute_clauseelement
    distilled_params,
  File "/home/user/.local/lib/python3.6/site-packages/sqlalchemy/engine/base.py", line 1288, in _execute_context
    e, statement, parameters, cursor, context
  File "/home/user/.local/lib/python3.6/site-packages/sqlalchemy/engine/base.py", line 1482, in _handle_dbapi_exception
    sqlalchemy_exception, with_traceback=exc_info[2], from_=e
  File "/home/user/.local/lib/python3.6/site-packages/sqlalchemy/util/compat.py", line 178, in raise_
    raise exception
  File "/home/user/.local/lib/python3.6/site-packages/sqlalchemy/engine/base.py", line 1248, in _execute_context
    cursor, statement, parameters, context
  File "/home/user/.local/lib/python3.6/site-packages/sqlalchemy/engine/default.py", line 590, in do_execute
    cursor.execute(statement, parameters)
  File "/home/user/.local/lib/python3.6/site-packages/MySQLdb/cursors.py", line 209, in execute
    res = self._query(query)
  File "/home/user/.local/lib/python3.6/site-packages/MySQLdb/cursors.py", line 315, in _query
    db.query(q)
  File "/home/user/.local/lib/python3.6/site-packages/MySQLdb/connections.py", line 239, in query
    _mysql.connection.query(self, query)
sqlalchemy.exc.OperationalError: (MySQLdb._exceptions.OperationalError) (1048, "Column 'name' cannot be null")
[SQL: INSERT INTO stock (name, energy, carbohydrates, sugars, fats, saturates, protein, fibre, salt) VALUES (%s, %s, %s, %s, %s, %s, %s, %s, %s)]
[parameters: (None, None, None, None, None, None, None, None, None)]
(Background on this error at: http://sqlalche.me/e/e3q8)
DEBUG:scrapy.core.engine:Crawled (200) <GET https://groceries.asda.com/product/910000043501 via http://0.0.0.0:8050/render.html> (referer: None)
ERROR:scrapy.core.scraper:Error processing {'Carbohydrate': '84g',
 'Date': datetime.datetime(2020, 5, 6, 9, 21, 25, 571991),
 'Energy': '1604kJ',
 'Fat': '0.9g',
 'Fibre': '3g',
 'Name': "Kellogg's Corn Flakes Big Pack",
 'Price': '£3.00',
 'Protein': '7g',
 'Salt': '1.13g',
 'Saturates': '0.2g',
 'Sugars': '8g',
 'Supermarket': 'Asda',
 'item_url': 'https://groceries.asda.com/product/910000043501'}
Traceback (most recent call last):
  File "/home/user/.local/lib/python3.6/site-packages/sqlalchemy/engine/base.py", line 1248, in _execute_context
    cursor, statement, parameters, context
  File "/home/user/.local/lib/python3.6/site-packages/sqlalchemy/engine/default.py", line 590, in do_execute
    cursor.execute(statement, parameters)
  File "/home/user/.local/lib/python3.6/site-packages/MySQLdb/cursors.py", line 209, in execute
    res = self._query(query)
  File "/home/user/.local/lib/python3.6/site-packages/MySQLdb/cursors.py", line 315, in _query
    db.query(q)
  File "/home/user/.local/lib/python3.6/site-packages/MySQLdb/connections.py", line 239, in query
    _mysql.connection.query(self, query)
MySQLdb._exceptions.OperationalError: (1048, "Column 'name' cannot be null")

The above exception was the direct cause of the following exception:

Traceback (most recent call last):
  File "/home/user/.local/lib/python3.6/site-packages/twisted/internet/defer.py", line 654, in _runCallbacks
    current.result = callback(current.result, *args, **kw)
  File "/home/user/.local/lib/python3.6/site-packages/scrapy/utils/defer.py", line 154, in f
    return deferred_from_coro(coro_f(*coro_args, **coro_kwargs))
  File "/home/user/Documents/PythonScripts/shopscrap/shopscrap/pipelines.py", line 98, in process_item
    session.flush()
  File "/home/user/.local/lib/python3.6/site-packages/sqlalchemy/orm/session.py", line 2496, in flush
    self._flush(objects)
  File "/home/user/.local/lib/python3.6/site-packages/sqlalchemy/orm/session.py", line 2637, in _flush
    transaction.rollback(_capture_exception=True)
  File "/home/user/.local/lib/python3.6/site-packages/sqlalchemy/util/langhelpers.py", line 69, in __exit__
    exc_value, with_traceback=exc_tb,
  File "/home/user/.local/lib/python3.6/site-packages/sqlalchemy/util/compat.py", line 178, in raise_
    raise exception
  File "/home/user/.local/lib/python3.6/site-packages/sqlalchemy/orm/session.py", line 2597, in _flush
    flush_context.execute()
  File "/home/user/.local/lib/python3.6/site-packages/sqlalchemy/orm/unitofwork.py", line 422, in execute
    rec.execute(self)
  File "/home/user/.local/lib/python3.6/site-packages/sqlalchemy/orm/unitofwork.py", line 589, in execute
    uow,
  File "/home/user/.local/lib/python3.6/site-packages/sqlalchemy/orm/persistence.py", line 245, in save_obj
    insert,
  File "/home/user/.local/lib/python3.6/site-packages/sqlalchemy/orm/persistence.py", line 1136, in _emit_insert_statements
    statement, params
  File "/home/user/.local/lib/python3.6/site-packages/sqlalchemy/engine/base.py", line 984, in execute
    return meth(self, multiparams, params)
  File "/home/user/.local/lib/python3.6/site-packages/sqlalchemy/sql/elements.py", line 293, in _execute_on_connection
    return connection._execute_clauseelement(self, multiparams, params)
  File "/home/user/.local/lib/python3.6/site-packages/sqlalchemy/engine/base.py", line 1103, in _execute_clauseelement
    distilled_params,
  File "/home/user/.local/lib/python3.6/site-packages/sqlalchemy/engine/base.py", line 1288, in _execute_context
    e, statement, parameters, cursor, context
  File "/home/user/.local/lib/python3.6/site-packages/sqlalchemy/engine/base.py", line 1482, in _handle_dbapi_exception
    sqlalchemy_exception, with_traceback=exc_info[2], from_=e
  File "/home/user/.local/lib/python3.6/site-packages/sqlalchemy/util/compat.py", line 178, in raise_
    raise exception
  File "/home/user/.local/lib/python3.6/site-packages/sqlalchemy/engine/base.py", line 1248, in _execute_context
    cursor, statement, parameters, context
  File "/home/user/.local/lib/python3.6/site-packages/sqlalchemy/engine/default.py", line 590, in do_execute
    cursor.execute(statement, parameters)
  File "/home/user/.local/lib/python3.6/site-packages/MySQLdb/cursors.py", line 209, in execute
    res = self._query(query)
  File "/home/user/.local/lib/python3.6/site-packages/MySQLdb/cursors.py", line 315, in _query
    db.query(q)
  File "/home/user/.local/lib/python3.6/site-packages/MySQLdb/connections.py", line 239, in query
    _mysql.connection.query(self, query)
sqlalchemy.exc.OperationalError: (MySQLdb._exceptions.OperationalError) (1048, "Column 'name' cannot be null")
[SQL: INSERT INTO stock (name, energy, carbohydrates, sugars, fats, saturates, protein, fibre, salt) VALUES (%s, %s, %s, %s, %s, %s, %s, %s, %s)]
[parameters: (None, None, None, None, None, None, None, None, None)]
(Background on this error at: http://sqlalche.me/e/e3q8)
DEBUG:scrapy.core.engine:Crawled (200) <GET https://groceries.asda.com/product/8667410 via http://0.0.0.0:8050/render.html> (referer: None)
ERROR:scrapy.core.scraper:Error processing {'Carbohydrate': '66.6g',
 'Date': datetime.datetime(2020, 5, 6, 9, 21, 26, 716593),
 'Energy': '1444kJ/342kcal',
 'Fat': '1.2g',
 'Fibre': '15.2g',
 'Name': 'Ryvita Dark Rye Crispbread',
 'Price': '£1.25',
 'Protein': '8.5g',
 'Salt': '0.74g',
 'Saturates': '0.2g',
 'Sugars': '3.0g',
 'Supermarket': 'Asda',
 'item_url': 'https://groceries.asda.com/product/8667410'}
Traceback (most recent call last):
  File "/home/user/.local/lib/python3.6/site-packages/sqlalchemy/engine/base.py", line 1248, in _execute_context
    cursor, statement, parameters, context
  File "/home/user/.local/lib/python3.6/site-packages/sqlalchemy/engine/default.py", line 590, in do_execute
    cursor.execute(statement, parameters)
  File "/home/user/.local/lib/python3.6/site-packages/MySQLdb/cursors.py", line 209, in execute
    res = self._query(query)
  File "/home/user/.local/lib/python3.6/site-packages/MySQLdb/cursors.py", line 315, in _query
    db.query(q)
  File "/home/user/.local/lib/python3.6/site-packages/MySQLdb/connections.py", line 239, in query
    _mysql.connection.query(self, query)
MySQLdb._exceptions.OperationalError: (1048, "Column 'name' cannot be null")

The above exception was the direct cause of the following exception:

Traceback (most recent call last):
  File "/home/user/.local/lib/python3.6/site-packages/twisted/internet/defer.py", line 654, in _runCallbacks
    current.result = callback(current.result, *args, **kw)
  File "/home/user/.local/lib/python3.6/site-packages/scrapy/utils/defer.py", line 154, in f
    return deferred_from_coro(coro_f(*coro_args, **coro_kwargs))
  File "/home/user/Documents/PythonScripts/shopscrap/shopscrap/pipelines.py", line 98, in process_item
    session.flush()
  File "/home/user/.local/lib/python3.6/site-packages/sqlalchemy/orm/session.py", line 2496, in flush
    self._flush(objects)
  File "/home/user/.local/lib/python3.6/site-packages/sqlalchemy/orm/session.py", line 2637, in _flush
    transaction.rollback(_capture_exception=True)
  File "/home/user/.local/lib/python3.6/site-packages/sqlalchemy/util/langhelpers.py", line 69, in __exit__
    exc_value, with_traceback=exc_tb,
  File "/home/user/.local/lib/python3.6/site-packages/sqlalchemy/util/compat.py", line 178, in raise_
    raise exception
  File "/home/user/.local/lib/python3.6/site-packages/sqlalchemy/orm/session.py", line 2597, in _flush
    flush_context.execute()
  File "/home/user/.local/lib/python3.6/site-packages/sqlalchemy/orm/unitofwork.py", line 422, in execute
    rec.execute(self)
  File "/home/user/.local/lib/python3.6/site-packages/sqlalchemy/orm/unitofwork.py", line 589, in execute
    uow,
  File "/home/user/.local/lib/python3.6/site-packages/sqlalchemy/orm/persistence.py", line 245, in save_obj
    insert,
  File "/home/user/.local/lib/python3.6/site-packages/sqlalchemy/orm/persistence.py", line 1136, in _emit_insert_statements
    statement, params
  File "/home/user/.local/lib/python3.6/site-packages/sqlalchemy/engine/base.py", line 984, in execute
    return meth(self, multiparams, params)
  File "/home/user/.local/lib/python3.6/site-packages/sqlalchemy/sql/elements.py", line 293, in _execute_on_connection
    return connection._execute_clauseelement(self, multiparams, params)
  File "/home/user/.local/lib/python3.6/site-packages/sqlalchemy/engine/base.py", line 1103, in _execute_clauseelement
    distilled_params,
  File "/home/user/.local/lib/python3.6/site-packages/sqlalchemy/engine/base.py", line 1288, in _execute_context
    e, statement, parameters, cursor, context
  File "/home/user/.local/lib/python3.6/site-packages/sqlalchemy/engine/base.py", line 1482, in _handle_dbapi_exception
    sqlalchemy_exception, with_traceback=exc_info[2], from_=e
  File "/home/user/.local/lib/python3.6/site-packages/sqlalchemy/util/compat.py", line 178, in raise_
    raise exception
  File "/home/user/.local/lib/python3.6/site-packages/sqlalchemy/engine/base.py", line 1248, in _execute_context
    cursor, statement, parameters, context
  File "/home/user/.local/lib/python3.6/site-packages/sqlalchemy/engine/default.py", line 590, in do_execute
    cursor.execute(statement, parameters)
  File "/home/user/.local/lib/python3.6/site-packages/MySQLdb/cursors.py", line 209, in execute
    res = self._query(query)
  File "/home/user/.local/lib/python3.6/site-packages/MySQLdb/cursors.py", line 315, in _query
    db.query(q)
  File "/home/user/.local/lib/python3.6/site-packages/MySQLdb/connections.py", line 239, in query
    _mysql.connection.query(self, query)
sqlalchemy.exc.OperationalError: (MySQLdb._exceptions.OperationalError) (1048, "Column 'name' cannot be null")
[SQL: INSERT INTO stock (name, energy, carbohydrates, sugars, fats, saturates, protein, fibre, salt) VALUES (%s, %s, %s, %s, %s, %s, %s, %s, %s)]
[parameters: (None, None, None, None, None, None, None, None, None)]
(Background on this error at: http://sqlalche.me/e/e3q8)
DEBUG:scrapy.core.engine:Crawled (200) <GET https://groceries.asda.com/product/1000178911415 via http://0.0.0.0:8050/render.html> (referer: None)
ERROR:scrapy.core.scraper:Error processing {'Carbohydrate': '69g',
 'Date': datetime.datetime(2020, 5, 6, 9, 21, 26, 919766),
 'Energy': '1882kJ',
 'Fat': '17g',
 'Name': 'Mars Snacksize Chocolate Bars 9 Pack',
 'Price': '£2.00',
 'Protein': '4.3g',
 'Salt': '0.42g',
 'Saturates': '8.1g',
 'Sugars': '60g',
 'Supermarket': 'Asda',
 'item_url': 'https://groceries.asda.com/product/1000178911415'}
Traceback (most recent call last):
  File "/home/user/.local/lib/python3.6/site-packages/sqlalchemy/engine/base.py", line 1248, in _execute_context
    cursor, statement, parameters, context
  File "/home/user/.local/lib/python3.6/site-packages/sqlalchemy/engine/default.py", line 590, in do_execute
    cursor.execute(statement, parameters)
  File "/home/user/.local/lib/python3.6/site-packages/MySQLdb/cursors.py", line 209, in execute
    res = self._query(query)
  File "/home/user/.local/lib/python3.6/site-packages/MySQLdb/cursors.py", line 315, in _query
    db.query(q)
  File "/home/user/.local/lib/python3.6/site-packages/MySQLdb/connections.py", line 239, in query
    _mysql.connection.query(self, query)
MySQLdb._exceptions.OperationalError: (1048, "Column 'name' cannot be null")

The above exception was the direct cause of the following exception:

Traceback (most recent call last):
  File "/home/user/.local/lib/python3.6/site-packages/twisted/internet/defer.py", line 654, in _runCallbacks
    current.result = callback(current.result, *args, **kw)
  File "/home/user/.local/lib/python3.6/site-packages/scrapy/utils/defer.py", line 154, in f
    return deferred_from_coro(coro_f(*coro_args, **coro_kwargs))
  File "/home/user/Documents/PythonScripts/shopscrap/shopscrap/pipelines.py", line 98, in process_item
    session.flush()
  File "/home/user/.local/lib/python3.6/site-packages/sqlalchemy/orm/session.py", line 2496, in flush
    self._flush(objects)
  File "/home/user/.local/lib/python3.6/site-packages/sqlalchemy/orm/session.py", line 2637, in _flush
    transaction.rollback(_capture_exception=True)
  File "/home/user/.local/lib/python3.6/site-packages/sqlalchemy/util/langhelpers.py", line 69, in __exit__
    exc_value, with_traceback=exc_tb,
  File "/home/user/.local/lib/python3.6/site-packages/sqlalchemy/util/compat.py", line 178, in raise_
    raise exception
  File "/home/user/.local/lib/python3.6/site-packages/sqlalchemy/orm/session.py", line 2597, in _flush
    flush_context.execute()
  File "/home/user/.local/lib/python3.6/site-packages/sqlalchemy/orm/unitofwork.py", line 422, in execute
    rec.execute(self)
  File "/home/user/.local/lib/python3.6/site-packages/sqlalchemy/orm/unitofwork.py", line 589, in execute
    uow,
  File "/home/user/.local/lib/python3.6/site-packages/sqlalchemy/orm/persistence.py", line 245, in save_obj
    insert,
  File "/home/user/.local/lib/python3.6/site-packages/sqlalchemy/orm/persistence.py", line 1136, in _emit_insert_statements
    statement, params
  File "/home/user/.local/lib/python3.6/site-packages/sqlalchemy/engine/base.py", line 984, in execute
    return meth(self, multiparams, params)
  File "/home/user/.local/lib/python3.6/site-packages/sqlalchemy/sql/elements.py", line 293, in _execute_on_connection
    return connection._execute_clauseelement(self, multiparams, params)
  File "/home/user/.local/lib/python3.6/site-packages/sqlalchemy/engine/base.py", line 1103, in _execute_clauseelement
    distilled_params,
  File "/home/user/.local/lib/python3.6/site-packages/sqlalchemy/engine/base.py", line 1288, in _execute_context
    e, statement, parameters, cursor, context
  File "/home/user/.local/lib/python3.6/site-packages/sqlalchemy/engine/base.py", line 1482, in _handle_dbapi_exception
    sqlalchemy_exception, with_traceback=exc_info[2], from_=e
  File "/home/user/.local/lib/python3.6/site-packages/sqlalchemy/util/compat.py", line 178, in raise_
    raise exception
  File "/home/user/.local/lib/python3.6/site-packages/sqlalchemy/engine/base.py", line 1248, in _execute_context
    cursor, statement, parameters, context
  File "/home/user/.local/lib/python3.6/site-packages/sqlalchemy/engine/default.py", line 590, in do_execute
    cursor.execute(statement, parameters)
  File "/home/user/.local/lib/python3.6/site-packages/MySQLdb/cursors.py", line 209, in execute
    res = self._query(query)
  File "/home/user/.local/lib/python3.6/site-packages/MySQLdb/cursors.py", line 315, in _query
    db.query(q)
  File "/home/user/.local/lib/python3.6/site-packages/MySQLdb/connections.py", line 239, in query
    _mysql.connection.query(self, query)
sqlalchemy.exc.OperationalError: (MySQLdb._exceptions.OperationalError) (1048, "Column 'name' cannot be null")
[SQL: INSERT INTO stock (name, energy, carbohydrates, sugars, fats, saturates, protein, fibre, salt) VALUES (%s, %s, %s, %s, %s, %s, %s, %s, %s)]
[parameters: (None, None, None, None, None, None, None, None, None)]
(Background on this error at: http://sqlalche.me/e/e3q8)
DEBUG:scrapy.core.engine:Crawled (200) <GET https://groceries.asda.com/product/910000212250 via http://0.0.0.0:8050/render.html> (referer: None)
DEBUG:scrapy.core.engine:Crawled (200) <GET https://groceries.asda.com/product/910000020342 via http://0.0.0.0:8050/render.html> (referer: None)
ERROR:scrapy.core.scraper:Error processing {'Carbohydrate': '1.4 g',
 'Date': datetime.datetime(2020, 5, 6, 9, 21, 28, 56090),
 'Energy': '726 kcal',
 'Fat': '79 g',
 'Name': "Hellmann's Real Squeezy Mayonnaise",
 'Price': '£2.00',
 'Protein': '1.1 g',
 'Salt': '1.5 g',
 'Saturates': '6.3 g',
 'Sugars': '1.3 g',
 'Supermarket': 'Asda',
 'item_url': 'https://groceries.asda.com/product/910000212250'}
Traceback (most recent call last):
  File "/home/user/.local/lib/python3.6/site-packages/sqlalchemy/engine/base.py", line 1248, in _execute_context
    cursor, statement, parameters, context
  File "/home/user/.local/lib/python3.6/site-packages/sqlalchemy/engine/default.py", line 590, in do_execute
    cursor.execute(statement, parameters)
  File "/home/user/.local/lib/python3.6/site-packages/MySQLdb/cursors.py", line 209, in execute
    res = self._query(query)
  File "/home/user/.local/lib/python3.6/site-packages/MySQLdb/cursors.py", line 315, in _query
    db.query(q)
  File "/home/user/.local/lib/python3.6/site-packages/MySQLdb/connections.py", line 239, in query
    _mysql.connection.query(self, query)
MySQLdb._exceptions.OperationalError: (1048, "Column 'name' cannot be null")

The above exception was the direct cause of the following exception:

Traceback (most recent call last):
  File "/home/user/.local/lib/python3.6/site-packages/twisted/internet/defer.py", line 654, in _runCallbacks
    current.result = callback(current.result, *args, **kw)
  File "/home/user/.local/lib/python3.6/site-packages/scrapy/utils/defer.py", line 154, in f
    return deferred_from_coro(coro_f(*coro_args, **coro_kwargs))
  File "/home/user/Documents/PythonScripts/shopscrap/shopscrap/pipelines.py", line 98, in process_item
    session.flush()
  File "/home/user/.local/lib/python3.6/site-packages/sqlalchemy/orm/session.py", line 2496, in flush
    self._flush(objects)
  File "/home/user/.local/lib/python3.6/site-packages/sqlalchemy/orm/session.py", line 2637, in _flush
    transaction.rollback(_capture_exception=True)
  File "/home/user/.local/lib/python3.6/site-packages/sqlalchemy/util/langhelpers.py", line 69, in __exit__
    exc_value, with_traceback=exc_tb,
  File "/home/user/.local/lib/python3.6/site-packages/sqlalchemy/util/compat.py", line 178, in raise_
    raise exception
  File "/home/user/.local/lib/python3.6/site-packages/sqlalchemy/orm/session.py", line 2597, in _flush
    flush_context.execute()
  File "/home/user/.local/lib/python3.6/site-packages/sqlalchemy/orm/unitofwork.py", line 422, in execute
    rec.execute(self)
  File "/home/user/.local/lib/python3.6/site-packages/sqlalchemy/orm/unitofwork.py", line 589, in execute
    uow,
  File "/home/user/.local/lib/python3.6/site-packages/sqlalchemy/orm/persistence.py", line 245, in save_obj
    insert,
  File "/home/user/.local/lib/python3.6/site-packages/sqlalchemy/orm/persistence.py", line 1136, in _emit_insert_statements
    statement, params
  File "/home/user/.local/lib/python3.6/site-packages/sqlalchemy/engine/base.py", line 984, in execute
    return meth(self, multiparams, params)
  File "/home/user/.local/lib/python3.6/site-packages/sqlalchemy/sql/elements.py", line 293, in _execute_on_connection
    return connection._execute_clauseelement(self, multiparams, params)
  File "/home/user/.local/lib/python3.6/site-packages/sqlalchemy/engine/base.py", line 1103, in _execute_clauseelement
    distilled_params,
  File "/home/user/.local/lib/python3.6/site-packages/sqlalchemy/engine/base.py", line 1288, in _execute_context
    e, statement, parameters, cursor, context
  File "/home/user/.local/lib/python3.6/site-packages/sqlalchemy/engine/base.py", line 1482, in _handle_dbapi_exception
    sqlalchemy_exception, with_traceback=exc_info[2], from_=e
  File "/home/user/.local/lib/python3.6/site-packages/sqlalchemy/util/compat.py", line 178, in raise_
    raise exception
  File "/home/user/.local/lib/python3.6/site-packages/sqlalchemy/engine/base.py", line 1248, in _execute_context
    cursor, statement, parameters, context
  File "/home/user/.local/lib/python3.6/site-packages/sqlalchemy/engine/default.py", line 590, in do_execute
    cursor.execute(statement, parameters)
  File "/home/user/.local/lib/python3.6/site-packages/MySQLdb/cursors.py", line 209, in execute
    res = self._query(query)
  File "/home/user/.local/lib/python3.6/site-packages/MySQLdb/cursors.py", line 315, in _query
    db.query(q)
  File "/home/user/.local/lib/python3.6/site-packages/MySQLdb/connections.py", line 239, in query
    _mysql.connection.query(self, query)
sqlalchemy.exc.OperationalError: (MySQLdb._exceptions.OperationalError) (1048, "Column 'name' cannot be null")
[SQL: INSERT INTO stock (name, energy, carbohydrates, sugars, fats, saturates, protein, fibre, salt) VALUES (%s, %s, %s, %s, %s, %s, %s, %s, %s)]
[parameters: (None, None, None, None, None, None, None, None, None)]
(Background on this error at: http://sqlalche.me/e/e3q8)
ERROR:scrapy.core.scraper:Error processing {'Date': datetime.datetime(2020, 5, 6, 9, 21, 28, 107064),
 'Name': "Hellmann's Light Squeezy Mayonnaise",
 'Price': '£1.99',
 'Supermarket': 'Asda',
 'item_url': 'https://groceries.asda.com/product/910000020342'}
Traceback (most recent call last):
  File "/home/user/.local/lib/python3.6/site-packages/sqlalchemy/engine/base.py", line 1248, in _execute_context
    cursor, statement, parameters, context
  File "/home/user/.local/lib/python3.6/site-packages/sqlalchemy/engine/default.py", line 590, in do_execute
    cursor.execute(statement, parameters)
  File "/home/user/.local/lib/python3.6/site-packages/MySQLdb/cursors.py", line 209, in execute
    res = self._query(query)
  File "/home/user/.local/lib/python3.6/site-packages/MySQLdb/cursors.py", line 315, in _query
    db.query(q)
  File "/home/user/.local/lib/python3.6/site-packages/MySQLdb/connections.py", line 239, in query
    _mysql.connection.query(self, query)
MySQLdb._exceptions.OperationalError: (1048, "Column 'name' cannot be null")

The above exception was the direct cause of the following exception:

Traceback (most recent call last):
  File "/home/user/.local/lib/python3.6/site-packages/twisted/internet/defer.py", line 654, in _runCallbacks
    current.result = callback(current.result, *args, **kw)
  File "/home/user/.local/lib/python3.6/site-packages/scrapy/utils/defer.py", line 154, in f
    return deferred_from_coro(coro_f(*coro_args, **coro_kwargs))
  File "/home/user/Documents/PythonScripts/shopscrap/shopscrap/pipelines.py", line 98, in process_item
    session.flush()
  File "/home/user/.local/lib/python3.6/site-packages/sqlalchemy/orm/session.py", line 2496, in flush
    self._flush(objects)
  File "/home/user/.local/lib/python3.6/site-packages/sqlalchemy/orm/session.py", line 2637, in _flush
    transaction.rollback(_capture_exception=True)
  File "/home/user/.local/lib/python3.6/site-packages/sqlalchemy/util/langhelpers.py", line 69, in __exit__
    exc_value, with_traceback=exc_tb,
  File "/home/user/.local/lib/python3.6/site-packages/sqlalchemy/util/compat.py", line 178, in raise_
    raise exception
  File "/home/user/.local/lib/python3.6/site-packages/sqlalchemy/orm/session.py", line 2597, in _flush
    flush_context.execute()
  File "/home/user/.local/lib/python3.6/site-packages/sqlalchemy/orm/unitofwork.py", line 422, in execute
    rec.execute(self)
  File "/home/user/.local/lib/python3.6/site-packages/sqlalchemy/orm/unitofwork.py", line 589, in execute
    uow,
  File "/home/user/.local/lib/python3.6/site-packages/sqlalchemy/orm/persistence.py", line 245, in save_obj
    insert,
  File "/home/user/.local/lib/python3.6/site-packages/sqlalchemy/orm/persistence.py", line 1136, in _emit_insert_statements
    statement, params
  File "/home/user/.local/lib/python3.6/site-packages/sqlalchemy/engine/base.py", line 984, in execute
    return meth(self, multiparams, params)
  File "/home/user/.local/lib/python3.6/site-packages/sqlalchemy/sql/elements.py", line 293, in _execute_on_connection
    return connection._execute_clauseelement(self, multiparams, params)
  File "/home/user/.local/lib/python3.6/site-packages/sqlalchemy/engine/base.py", line 1103, in _execute_clauseelement
    distilled_params,
  File "/home/user/.local/lib/python3.6/site-packages/sqlalchemy/engine/base.py", line 1288, in _execute_context
    e, statement, parameters, cursor, context
  File "/home/user/.local/lib/python3.6/site-packages/sqlalchemy/engine/base.py", line 1482, in _handle_dbapi_exception
    sqlalchemy_exception, with_traceback=exc_info[2], from_=e
  File "/home/user/.local/lib/python3.6/site-packages/sqlalchemy/util/compat.py", line 178, in raise_
    raise exception
  File "/home/user/.local/lib/python3.6/site-packages/sqlalchemy/engine/base.py", line 1248, in _execute_context
    cursor, statement, parameters, context
  File "/home/user/.local/lib/python3.6/site-packages/sqlalchemy/engine/default.py", line 590, in do_execute
    cursor.execute(statement, parameters)
  File "/home/user/.local/lib/python3.6/site-packages/MySQLdb/cursors.py", line 209, in execute
    res = self._query(query)
  File "/home/user/.local/lib/python3.6/site-packages/MySQLdb/cursors.py", line 315, in _query
    db.query(q)
  File "/home/user/.local/lib/python3.6/site-packages/MySQLdb/connections.py", line 239, in query
    _mysql.connection.query(self, query)
sqlalchemy.exc.OperationalError: (MySQLdb._exceptions.OperationalError) (1048, "Column 'name' cannot be null")
[SQL: INSERT INTO stock (name, energy, carbohydrates, sugars, fats, saturates, protein, fibre, salt) VALUES (%s, %s, %s, %s, %s, %s, %s, %s, %s)]
[parameters: (None, None, None, None, None, None, None, None, None)]
(Background on this error at: http://sqlalche.me/e/e3q8)
DEBUG:scrapy.core.engine:Crawled (200) <GET https://groceries.asda.com/product/910000057676 via http://0.0.0.0:8050/render.html> (referer: None)
ERROR:scrapy.core.scraper:Error processing {'Carbohydrate': '6 g',
 'Date': datetime.datetime(2020, 5, 6, 9, 21, 28, 349106),
 'Energy': '264 kcal',
 'Fat': '26 g',
 'Name': "Hellmann's Light Mayonnaise",
 'Price': '£3.00',
 'Protein': '<0.5 g',
 'Salt': '1.7 g',
 'Saturates': '2.6 g',
 'Sugars': '2.3 g',
 'Supermarket': 'Asda',
 'item_url': 'https://groceries.asda.com/product/910000057676'}
Traceback (most recent call last):
  File "/home/user/.local/lib/python3.6/site-packages/sqlalchemy/engine/base.py", line 1248, in _execute_context
    cursor, statement, parameters, context
  File "/home/user/.local/lib/python3.6/site-packages/sqlalchemy/engine/default.py", line 590, in do_execute
    cursor.execute(statement, parameters)
  File "/home/user/.local/lib/python3.6/site-packages/MySQLdb/cursors.py", line 209, in execute
    res = self._query(query)
  File "/home/user/.local/lib/python3.6/site-packages/MySQLdb/cursors.py", line 315, in _query
    db.query(q)
  File "/home/user/.local/lib/python3.6/site-packages/MySQLdb/connections.py", line 239, in query
    _mysql.connection.query(self, query)
MySQLdb._exceptions.OperationalError: (1048, "Column 'name' cannot be null")

The above exception was the direct cause of the following exception:

Traceback (most recent call last):
  File "/home/user/.local/lib/python3.6/site-packages/twisted/internet/defer.py", line 654, in _runCallbacks
    current.result = callback(current.result, *args, **kw)
  File "/home/user/.local/lib/python3.6/site-packages/scrapy/utils/defer.py", line 154, in f
    return deferred_from_coro(coro_f(*coro_args, **coro_kwargs))
  File "/home/user/Documents/PythonScripts/shopscrap/shopscrap/pipelines.py", line 98, in process_item
    session.flush()
  File "/home/user/.local/lib/python3.6/site-packages/sqlalchemy/orm/session.py", line 2496, in flush
    self._flush(objects)
  File "/home/user/.local/lib/python3.6/site-packages/sqlalchemy/orm/session.py", line 2637, in _flush
    transaction.rollback(_capture_exception=True)
  File "/home/user/.local/lib/python3.6/site-packages/sqlalchemy/util/langhelpers.py", line 69, in __exit__
    exc_value, with_traceback=exc_tb,
  File "/home/user/.local/lib/python3.6/site-packages/sqlalchemy/util/compat.py", line 178, in raise_
    raise exception
  File "/home/user/.local/lib/python3.6/site-packages/sqlalchemy/orm/session.py", line 2597, in _flush
    flush_context.execute()
  File "/home/user/.local/lib/python3.6/site-packages/sqlalchemy/orm/unitofwork.py", line 422, in execute
    rec.execute(self)
  File "/home/user/.local/lib/python3.6/site-packages/sqlalchemy/orm/unitofwork.py", line 589, in execute
    uow,
  File "/home/user/.local/lib/python3.6/site-packages/sqlalchemy/orm/persistence.py", line 245, in save_obj
    insert,
  File "/home/user/.local/lib/python3.6/site-packages/sqlalchemy/orm/persistence.py", line 1136, in _emit_insert_statements
    statement, params
  File "/home/user/.local/lib/python3.6/site-packages/sqlalchemy/engine/base.py", line 984, in execute
    return meth(self, multiparams, params)
  File "/home/user/.local/lib/python3.6/site-packages/sqlalchemy/sql/elements.py", line 293, in _execute_on_connection
    return connection._execute_clauseelement(self, multiparams, params)
  File "/home/user/.local/lib/python3.6/site-packages/sqlalchemy/engine/base.py", line 1103, in _execute_clauseelement
    distilled_params,
  File "/home/user/.local/lib/python3.6/site-packages/sqlalchemy/engine/base.py", line 1288, in _execute_context
    e, statement, parameters, cursor, context
  File "/home/user/.local/lib/python3.6/site-packages/sqlalchemy/engine/base.py", line 1482, in _handle_dbapi_exception
    sqlalchemy_exception, with_traceback=exc_info[2], from_=e
  File "/home/user/.local/lib/python3.6/site-packages/sqlalchemy/util/compat.py", line 178, in raise_
    raise exception
  File "/home/user/.local/lib/python3.6/site-packages/sqlalchemy/engine/base.py", line 1248, in _execute_context
    cursor, statement, parameters, context
  File "/home/user/.local/lib/python3.6/site-packages/sqlalchemy/engine/default.py", line 590, in do_execute
    cursor.execute(statement, parameters)
  File "/home/user/.local/lib/python3.6/site-packages/MySQLdb/cursors.py", line 209, in execute
    res = self._query(query)
  File "/home/user/.local/lib/python3.6/site-packages/MySQLdb/cursors.py", line 315, in _query
    db.query(q)
  File "/home/user/.local/lib/python3.6/site-packages/MySQLdb/connections.py", line 239, in query
    _mysql.connection.query(self, query)
sqlalchemy.exc.OperationalError: (MySQLdb._exceptions.OperationalError) (1048, "Column 'name' cannot be null")
[SQL: INSERT INTO stock (name, energy, carbohydrates, sugars, fats, saturates, protein, fibre, salt) VALUES (%s, %s, %s, %s, %s, %s, %s, %s, %s)]
[parameters: (None, None, None, None, None, None, None, None, None)]
(Background on this error at: http://sqlalche.me/e/e3q8)
DEBUG:scrapy.core.engine:Crawled (200) <GET https://groceries.asda.com/product/19140 via http://0.0.0.0:8050/render.html> (referer: None)
ERROR:scrapy.core.scraper:Error processing {'Carbohydrate': '82g',
 'Date': datetime.datetime(2020, 5, 6, 9, 21, 29, 126536),
 'Energy': '1683kJ',
 'Fat': '4.5g',
 'Fibre': '2.5g',
 'Name': "Kellogg's Crunchy Nut Corn Flakes",
 'Price': '£2.00',
 'Protein': '6g',
 'Salt': '0.75g',
 'Saturates': '0.7g',
 'Sugars': '35g',
 'Supermarket': 'Asda',
 'item_url': 'https://groceries.asda.com/product/19140'}
Traceback (most recent call last):
  File "/home/user/.local/lib/python3.6/site-packages/sqlalchemy/engine/base.py", line 1248, in _execute_context
    cursor, statement, parameters, context
  File "/home/user/.local/lib/python3.6/site-packages/sqlalchemy/engine/default.py", line 590, in do_execute
    cursor.execute(statement, parameters)
  File "/home/user/.local/lib/python3.6/site-packages/MySQLdb/cursors.py", line 209, in execute
    res = self._query(query)
  File "/home/user/.local/lib/python3.6/site-packages/MySQLdb/cursors.py", line 315, in _query
    db.query(q)
  File "/home/user/.local/lib/python3.6/site-packages/MySQLdb/connections.py", line 239, in query
    _mysql.connection.query(self, query)
MySQLdb._exceptions.OperationalError: (1048, "Column 'name' cannot be null")

The above exception was the direct cause of the following exception:

Traceback (most recent call last):
  File "/home/user/.local/lib/python3.6/site-packages/twisted/internet/defer.py", line 654, in _runCallbacks
    current.result = callback(current.result, *args, **kw)
  File "/home/user/.local/lib/python3.6/site-packages/scrapy/utils/defer.py", line 154, in f
    return deferred_from_coro(coro_f(*coro_args, **coro_kwargs))
  File "/home/user/Documents/PythonScripts/shopscrap/shopscrap/pipelines.py", line 98, in process_item
    session.flush()
  File "/home/user/.local/lib/python3.6/site-packages/sqlalchemy/orm/session.py", line 2496, in flush
    self._flush(objects)
  File "/home/user/.local/lib/python3.6/site-packages/sqlalchemy/orm/session.py", line 2637, in _flush
    transaction.rollback(_capture_exception=True)
  File "/home/user/.local/lib/python3.6/site-packages/sqlalchemy/util/langhelpers.py", line 69, in __exit__
    exc_value, with_traceback=exc_tb,
  File "/home/user/.local/lib/python3.6/site-packages/sqlalchemy/util/compat.py", line 178, in raise_
    raise exception
  File "/home/user/.local/lib/python3.6/site-packages/sqlalchemy/orm/session.py", line 2597, in _flush
    flush_context.execute()
  File "/home/user/.local/lib/python3.6/site-packages/sqlalchemy/orm/unitofwork.py", line 422, in execute
    rec.execute(self)
  File "/home/user/.local/lib/python3.6/site-packages/sqlalchemy/orm/unitofwork.py", line 589, in execute
    uow,
  File "/home/user/.local/lib/python3.6/site-packages/sqlalchemy/orm/persistence.py", line 245, in save_obj
    insert,
  File "/home/user/.local/lib/python3.6/site-packages/sqlalchemy/orm/persistence.py", line 1136, in _emit_insert_statements
    statement, params
  File "/home/user/.local/lib/python3.6/site-packages/sqlalchemy/engine/base.py", line 984, in execute
    return meth(self, multiparams, params)
  File "/home/user/.local/lib/python3.6/site-packages/sqlalchemy/sql/elements.py", line 293, in _execute_on_connection
    return connection._execute_clauseelement(self, multiparams, params)
  File "/home/user/.local/lib/python3.6/site-packages/sqlalchemy/engine/base.py", line 1103, in _execute_clauseelement
    distilled_params,
  File "/home/user/.local/lib/python3.6/site-packages/sqlalchemy/engine/base.py", line 1288, in _execute_context
    e, statement, parameters, cursor, context
  File "/home/user/.local/lib/python3.6/site-packages/sqlalchemy/engine/base.py", line 1482, in _handle_dbapi_exception
    sqlalchemy_exception, with_traceback=exc_info[2], from_=e
  File "/home/user/.local/lib/python3.6/site-packages/sqlalchemy/util/compat.py", line 178, in raise_
    raise exception
  File "/home/user/.local/lib/python3.6/site-packages/sqlalchemy/engine/base.py", line 1248, in _execute_context
    cursor, statement, parameters, context
  File "/home/user/.local/lib/python3.6/site-packages/sqlalchemy/engine/default.py", line 590, in do_execute
    cursor.execute(statement, parameters)
  File "/home/user/.local/lib/python3.6/site-packages/MySQLdb/cursors.py", line 209, in execute
    res = self._query(query)
  File "/home/user/.local/lib/python3.6/site-packages/MySQLdb/cursors.py", line 315, in _query
    db.query(q)
  File "/home/user/.local/lib/python3.6/site-packages/MySQLdb/connections.py", line 239, in query
    _mysql.connection.query(self, query)
sqlalchemy.exc.OperationalError: (MySQLdb._exceptions.OperationalError) (1048, "Column 'name' cannot be null")
[SQL: INSERT INTO stock (name, energy, carbohydrates, sugars, fats, saturates, protein, fibre, salt) VALUES (%s, %s, %s, %s, %s, %s, %s, %s, %s)]
[parameters: (None, None, None, None, None, None, None, None, None)]
(Background on this error at: http://sqlalche.me/e/e3q8)
DEBUG:scrapy.core.engine:Crawled (200) <GET https://groceries.asda.com/product/910000261256 via http://0.0.0.0:8050/render.html> (referer: None)
ERROR:scrapy.core.scraper:Error processing {'Carbohydrate': '42.1 g',
 'Date': datetime.datetime(2020, 5, 6, 9, 21, 29, 515548),
 'Energy': '1078 kJ / 256 kcal',
 'Fat': '6.1 g',
 'Fibre': '2.1 g',
 'Name': 'Old El Paso Mexican Sizzling Extra Mild Super Tasty Fajita Kit',
 'Price': '£3.18',
 'Protein': '7.0 g',
 'Salt': '1.57 g',
 'Saturates': '1.9 g',
 'Sugars': '5.4 g',
 'Supermarket': 'Asda',
 'item_url': 'https://groceries.asda.com/product/910000261256'}
Traceback (most recent call last):
  File "/home/user/.local/lib/python3.6/site-packages/sqlalchemy/engine/base.py", line 1248, in _execute_context
    cursor, statement, parameters, context
  File "/home/user/.local/lib/python3.6/site-packages/sqlalchemy/engine/default.py", line 590, in do_execute
    cursor.execute(statement, parameters)
  File "/home/user/.local/lib/python3.6/site-packages/MySQLdb/cursors.py", line 209, in execute
    res = self._query(query)
  File "/home/user/.local/lib/python3.6/site-packages/MySQLdb/cursors.py", line 315, in _query
    db.query(q)
  File "/home/user/.local/lib/python3.6/site-packages/MySQLdb/connections.py", line 239, in query
    _mysql.connection.query(self, query)
MySQLdb._exceptions.OperationalError: (1048, "Column 'name' cannot be null")

The above exception was the direct cause of the following exception:

Traceback (most recent call last):
  File "/home/user/.local/lib/python3.6/site-packages/twisted/internet/defer.py", line 654, in _runCallbacks
    current.result = callback(current.result, *args, **kw)
  File "/home/user/.local/lib/python3.6/site-packages/scrapy/utils/defer.py", line 154, in f
    return deferred_from_coro(coro_f(*coro_args, **coro_kwargs))
  File "/home/user/Documents/PythonScripts/shopscrap/shopscrap/pipelines.py", line 98, in process_item
    session.flush()
  File "/home/user/.local/lib/python3.6/site-packages/sqlalchemy/orm/session.py", line 2496, in flush
    self._flush(objects)
  File "/home/user/.local/lib/python3.6/site-packages/sqlalchemy/orm/session.py", line 2637, in _flush
    transaction.rollback(_capture_exception=True)
  File "/home/user/.local/lib/python3.6/site-packages/sqlalchemy/util/langhelpers.py", line 69, in __exit__
    exc_value, with_traceback=exc_tb,
  File "/home/user/.local/lib/python3.6/site-packages/sqlalchemy/util/compat.py", line 178, in raise_
    raise exception
  File "/home/user/.local/lib/python3.6/site-packages/sqlalchemy/orm/session.py", line 2597, in _flush
    flush_context.execute()
  File "/home/user/.local/lib/python3.6/site-packages/sqlalchemy/orm/unitofwork.py", line 422, in execute
    rec.execute(self)
  File "/home/user/.local/lib/python3.6/site-packages/sqlalchemy/orm/unitofwork.py", line 589, in execute
    uow,
  File "/home/user/.local/lib/python3.6/site-packages/sqlalchemy/orm/persistence.py", line 245, in save_obj
    insert,
  File "/home/user/.local/lib/python3.6/site-packages/sqlalchemy/orm/persistence.py", line 1136, in _emit_insert_statements
    statement, params
  File "/home/user/.local/lib/python3.6/site-packages/sqlalchemy/engine/base.py", line 984, in execute
    return meth(self, multiparams, params)
  File "/home/user/.local/lib/python3.6/site-packages/sqlalchemy/sql/elements.py", line 293, in _execute_on_connection
    return connection._execute_clauseelement(self, multiparams, params)
  File "/home/user/.local/lib/python3.6/site-packages/sqlalchemy/engine/base.py", line 1103, in _execute_clauseelement
    distilled_params,
  File "/home/user/.local/lib/python3.6/site-packages/sqlalchemy/engine/base.py", line 1288, in _execute_context
    e, statement, parameters, cursor, context
  File "/home/user/.local/lib/python3.6/site-packages/sqlalchemy/engine/base.py", line 1482, in _handle_dbapi_exception
    sqlalchemy_exception, with_traceback=exc_info[2], from_=e
  File "/home/user/.local/lib/python3.6/site-packages/sqlalchemy/util/compat.py", line 178, in raise_
    raise exception
  File "/home/user/.local/lib/python3.6/site-packages/sqlalchemy/engine/base.py", line 1248, in _execute_context
    cursor, statement, parameters, context
  File "/home/user/.local/lib/python3.6/site-packages/sqlalchemy/engine/default.py", line 590, in do_execute
    cursor.execute(statement, parameters)
  File "/home/user/.local/lib/python3.6/site-packages/MySQLdb/cursors.py", line 209, in execute
    res = self._query(query)
  File "/home/user/.local/lib/python3.6/site-packages/MySQLdb/cursors.py", line 315, in _query
    db.query(q)
  File "/home/user/.local/lib/python3.6/site-packages/MySQLdb/connections.py", line 239, in query
    _mysql.connection.query(self, query)
sqlalchemy.exc.OperationalError: (MySQLdb._exceptions.OperationalError) (1048, "Column 'name' cannot be null")
[SQL: INSERT INTO stock (name, energy, carbohydrates, sugars, fats, saturates, protein, fibre, salt) VALUES (%s, %s, %s, %s, %s, %s, %s, %s, %s)]
[parameters: (None, None, None, None, None, None, None, None, None)]
(Background on this error at: http://sqlalche.me/e/e3q8)
DEBUG:scrapy.core.engine:Crawled (200) <GET https://groceries.asda.com/product/910001818810 via http://0.0.0.0:8050/render.html> (referer: None)
ERROR:scrapy.core.scraper:Error processing {'Carbohydrate': '54g',
 'Date': datetime.datetime(2020, 5, 6, 9, 21, 36, 670316),
 'Energy': '2130kJ',
 'Fat': '28g',
 'Name': 'Snickers Chocolate Bars Multipack 4 x 41.7g',
 'Price': '£1.50',
 'Protein': '9.5g',
 'Salt': '0.45g',
 'Saturates': '9.6g',
 'Sugars': '45g',
 'Supermarket': 'Asda',
 'item_url': 'https://groceries.asda.com/product/910001818810'}
Traceback (most recent call last):
  File "/home/user/.local/lib/python3.6/site-packages/sqlalchemy/engine/base.py", line 1248, in _execute_context
    cursor, statement, parameters, context
  File "/home/user/.local/lib/python3.6/site-packages/sqlalchemy/engine/default.py", line 590, in do_execute
    cursor.execute(statement, parameters)
  File "/home/user/.local/lib/python3.6/site-packages/MySQLdb/cursors.py", line 209, in execute
    res = self._query(query)
  File "/home/user/.local/lib/python3.6/site-packages/MySQLdb/cursors.py", line 315, in _query
    db.query(q)
  File "/home/user/.local/lib/python3.6/site-packages/MySQLdb/connections.py", line 239, in query
    _mysql.connection.query(self, query)
MySQLdb._exceptions.OperationalError: (1048, "Column 'name' cannot be null")

The above exception was the direct cause of the following exception:

Traceback (most recent call last):
  File "/home/user/.local/lib/python3.6/site-packages/twisted/internet/defer.py", line 654, in _runCallbacks
    current.result = callback(current.result, *args, **kw)
  File "/home/user/.local/lib/python3.6/site-packages/scrapy/utils/defer.py", line 154, in f
    return deferred_from_coro(coro_f(*coro_args, **coro_kwargs))
  File "/home/user/Documents/PythonScripts/shopscrap/shopscrap/pipelines.py", line 98, in process_item
    session.flush()
  File "/home/user/.local/lib/python3.6/site-packages/sqlalchemy/orm/session.py", line 2496, in flush
    self._flush(objects)
  File "/home/user/.local/lib/python3.6/site-packages/sqlalchemy/orm/session.py", line 2637, in _flush
    transaction.rollback(_capture_exception=True)
  File "/home/user/.local/lib/python3.6/site-packages/sqlalchemy/util/langhelpers.py", line 69, in __exit__
    exc_value, with_traceback=exc_tb,
  File "/home/user/.local/lib/python3.6/site-packages/sqlalchemy/util/compat.py", line 178, in raise_
    raise exception
  File "/home/user/.local/lib/python3.6/site-packages/sqlalchemy/orm/session.py", line 2597, in _flush
    flush_context.execute()
  File "/home/user/.local/lib/python3.6/site-packages/sqlalchemy/orm/unitofwork.py", line 422, in execute
    rec.execute(self)
  File "/home/user/.local/lib/python3.6/site-packages/sqlalchemy/orm/unitofwork.py", line 589, in execute
    uow,
  File "/home/user/.local/lib/python3.6/site-packages/sqlalchemy/orm/persistence.py", line 245, in save_obj
    insert,
  File "/home/user/.local/lib/python3.6/site-packages/sqlalchemy/orm/persistence.py", line 1136, in _emit_insert_statements
    statement, params
  File "/home/user/.local/lib/python3.6/site-packages/sqlalchemy/engine/base.py", line 984, in execute
    return meth(self, multiparams, params)
  File "/home/user/.local/lib/python3.6/site-packages/sqlalchemy/sql/elements.py", line 293, in _execute_on_connection
    return connection._execute_clauseelement(self, multiparams, params)
  File "/home/user/.local/lib/python3.6/site-packages/sqlalchemy/engine/base.py", line 1103, in _execute_clauseelement
    distilled_params,
  File "/home/user/.local/lib/python3.6/site-packages/sqlalchemy/engine/base.py", line 1288, in _execute_context
    e, statement, parameters, cursor, context
  File "/home/user/.local/lib/python3.6/site-packages/sqlalchemy/engine/base.py", line 1482, in _handle_dbapi_exception
    sqlalchemy_exception, with_traceback=exc_info[2], from_=e
  File "/home/user/.local/lib/python3.6/site-packages/sqlalchemy/util/compat.py", line 178, in raise_
    raise exception
  File "/home/user/.local/lib/python3.6/site-packages/sqlalchemy/engine/base.py", line 1248, in _execute_context
    cursor, statement, parameters, context
  File "/home/user/.local/lib/python3.6/site-packages/sqlalchemy/engine/default.py", line 590, in do_execute
    cursor.execute(statement, parameters)
  File "/home/user/.local/lib/python3.6/site-packages/MySQLdb/cursors.py", line 209, in execute
    res = self._query(query)
  File "/home/user/.local/lib/python3.6/site-packages/MySQLdb/cursors.py", line 315, in _query
    db.query(q)
  File "/home/user/.local/lib/python3.6/site-packages/MySQLdb/connections.py", line 239, in query
    _mysql.connection.query(self, query)
sqlalchemy.exc.OperationalError: (MySQLdb._exceptions.OperationalError) (1048, "Column 'name' cannot be null")
[SQL: INSERT INTO stock (name, energy, carbohydrates, sugars, fats, saturates, protein, fibre, salt) VALUES (%s, %s, %s, %s, %s, %s, %s, %s, %s)]
[parameters: (None, None, None, None, None, None, None, None, None)]
(Background on this error at: http://sqlalche.me/e/e3q8)
DEBUG:scrapy.core.engine:Crawled (200) <GET https://groceries.asda.com/product/24152059 via http://0.0.0.0:8050/render.html> (referer: None)
ERROR:scrapy.core.scraper:Error processing {'Carbohydrate': '20 g',
 'Date': datetime.datetime(2020, 5, 6, 9, 21, 38, 875767),
 'Energy': '143 kcal',
 'Fat': '5.5 g',
 'Fibre': '1.3 g',
 'Name': 'Pot Noodle King Bombay Bad Boy',
 'Price': '£1.00',
 'Protein': '3.2 g',
 'Salt': '0.4 g',
 'Saturates': '2.6 g',
 'Sugars': '0.9 g',
 'Supermarket': 'Asda',
 'item_url': 'https://groceries.asda.com/product/24152059'}
Traceback (most recent call last):
  File "/home/user/.local/lib/python3.6/site-packages/sqlalchemy/engine/base.py", line 1248, in _execute_context
    cursor, statement, parameters, context
  File "/home/user/.local/lib/python3.6/site-packages/sqlalchemy/engine/default.py", line 590, in do_execute
    cursor.execute(statement, parameters)
  File "/home/user/.local/lib/python3.6/site-packages/MySQLdb/cursors.py", line 209, in execute
    res = self._query(query)
  File "/home/user/.local/lib/python3.6/site-packages/MySQLdb/cursors.py", line 315, in _query
    db.query(q)
  File "/home/user/.local/lib/python3.6/site-packages/MySQLdb/connections.py", line 239, in query
    _mysql.connection.query(self, query)
MySQLdb._exceptions.OperationalError: (1048, "Column 'name' cannot be null")

The above exception was the direct cause of the following exception:

Traceback (most recent call last):
  File "/home/user/.local/lib/python3.6/site-packages/twisted/internet/defer.py", line 654, in _runCallbacks
    current.result = callback(current.result, *args, **kw)
  File "/home/user/.local/lib/python3.6/site-packages/scrapy/utils/defer.py", line 154, in f
    return deferred_from_coro(coro_f(*coro_args, **coro_kwargs))
  File "/home/user/Documents/PythonScripts/shopscrap/shopscrap/pipelines.py", line 98, in process_item
    session.flush()
  File "/home/user/.local/lib/python3.6/site-packages/sqlalchemy/orm/session.py", line 2496, in flush
    self._flush(objects)
  File "/home/user/.local/lib/python3.6/site-packages/sqlalchemy/orm/session.py", line 2637, in _flush
    transaction.rollback(_capture_exception=True)
  File "/home/user/.local/lib/python3.6/site-packages/sqlalchemy/util/langhelpers.py", line 69, in __exit__
    exc_value, with_traceback=exc_tb,
  File "/home/user/.local/lib/python3.6/site-packages/sqlalchemy/util/compat.py", line 178, in raise_
    raise exception
  File "/home/user/.local/lib/python3.6/site-packages/sqlalchemy/orm/session.py", line 2597, in _flush
    flush_context.execute()
  File "/home/user/.local/lib/python3.6/site-packages/sqlalchemy/orm/unitofwork.py", line 422, in execute
    rec.execute(self)
  File "/home/user/.local/lib/python3.6/site-packages/sqlalchemy/orm/unitofwork.py", line 589, in execute
    uow,
  File "/home/user/.local/lib/python3.6/site-packages/sqlalchemy/orm/persistence.py", line 245, in save_obj
    insert,
  File "/home/user/.local/lib/python3.6/site-packages/sqlalchemy/orm/persistence.py", line 1136, in _emit_insert_statements
    statement, params
  File "/home/user/.local/lib/python3.6/site-packages/sqlalchemy/engine/base.py", line 984, in execute
    return meth(self, multiparams, params)
  File "/home/user/.local/lib/python3.6/site-packages/sqlalchemy/sql/elements.py", line 293, in _execute_on_connection
    return connection._execute_clauseelement(self, multiparams, params)
  File "/home/user/.local/lib/python3.6/site-packages/sqlalchemy/engine/base.py", line 1103, in _execute_clauseelement
    distilled_params,
  File "/home/user/.local/lib/python3.6/site-packages/sqlalchemy/engine/base.py", line 1288, in _execute_context
    e, statement, parameters, cursor, context
  File "/home/user/.local/lib/python3.6/site-packages/sqlalchemy/engine/base.py", line 1482, in _handle_dbapi_exception
    sqlalchemy_exception, with_traceback=exc_info[2], from_=e
  File "/home/user/.local/lib/python3.6/site-packages/sqlalchemy/util/compat.py", line 178, in raise_
    raise exception
  File "/home/user/.local/lib/python3.6/site-packages/sqlalchemy/engine/base.py", line 1248, in _execute_context
    cursor, statement, parameters, context
  File "/home/user/.local/lib/python3.6/site-packages/sqlalchemy/engine/default.py", line 590, in do_execute
    cursor.execute(statement, parameters)
  File "/home/user/.local/lib/python3.6/site-packages/MySQLdb/cursors.py", line 209, in execute
    res = self._query(query)
  File "/home/user/.local/lib/python3.6/site-packages/MySQLdb/cursors.py", line 315, in _query
    db.query(q)
  File "/home/user/.local/lib/python3.6/site-packages/MySQLdb/connections.py", line 239, in query
    _mysql.connection.query(self, query)
sqlalchemy.exc.OperationalError: (MySQLdb._exceptions.OperationalError) (1048, "Column 'name' cannot be null")
[SQL: INSERT INTO stock (name, energy, carbohydrates, sugars, fats, saturates, protein, fibre, salt) VALUES (%s, %s, %s, %s, %s, %s, %s, %s, %s)]
[parameters: (None, None, None, None, None, None, None, None, None)]
(Background on this error at: http://sqlalche.me/e/e3q8)
DEBUG:scrapy.core.engine:Crawled (200) <GET https://groceries.asda.com/product/1000178911419 via http://0.0.0.0:8050/render.html> (referer: None)
ERROR:scrapy.core.scraper:Error processing {'Carbohydrate': '59g',
 'Date': datetime.datetime(2020, 5, 6, 9, 21, 39, 99837),
 'Energy': '2035kJ',
 'Fat': '26g',
 'Name': 'Bounty Chocolate Bars 8 Pack',
 'Price': '£2.00',
 'Protein': '3.7g',
 'Salt': '0.26g',
 'Saturates': '21g',
 'Sugars': '48g',
 'Supermarket': 'Asda',
 'item_url': 'https://groceries.asda.com/product/1000178911419'}
Traceback (most recent call last):
  File "/home/user/.local/lib/python3.6/site-packages/sqlalchemy/engine/base.py", line 1248, in _execute_context
    cursor, statement, parameters, context
  File "/home/user/.local/lib/python3.6/site-packages/sqlalchemy/engine/default.py", line 590, in do_execute
    cursor.execute(statement, parameters)
  File "/home/user/.local/lib/python3.6/site-packages/MySQLdb/cursors.py", line 209, in execute
    res = self._query(query)
  File "/home/user/.local/lib/python3.6/site-packages/MySQLdb/cursors.py", line 315, in _query
    db.query(q)
  File "/home/user/.local/lib/python3.6/site-packages/MySQLdb/connections.py", line 239, in query
    _mysql.connection.query(self, query)
MySQLdb._exceptions.OperationalError: (1048, "Column 'name' cannot be null")

The above exception was the direct cause of the following exception:

Traceback (most recent call last):
  File "/home/user/.local/lib/python3.6/site-packages/twisted/internet/defer.py", line 654, in _runCallbacks
    current.result = callback(current.result, *args, **kw)
  File "/home/user/.local/lib/python3.6/site-packages/scrapy/utils/defer.py", line 154, in f
    return deferred_from_coro(coro_f(*coro_args, **coro_kwargs))
  File "/home/user/Documents/PythonScripts/shopscrap/shopscrap/pipelines.py", line 98, in process_item
    session.flush()
  File "/home/user/.local/lib/python3.6/site-packages/sqlalchemy/orm/session.py", line 2496, in flush
    self._flush(objects)
  File "/home/user/.local/lib/python3.6/site-packages/sqlalchemy/orm/session.py", line 2637, in _flush
    transaction.rollback(_capture_exception=True)
  File "/home/user/.local/lib/python3.6/site-packages/sqlalchemy/util/langhelpers.py", line 69, in __exit__
    exc_value, with_traceback=exc_tb,
  File "/home/user/.local/lib/python3.6/site-packages/sqlalchemy/util/compat.py", line 178, in raise_
    raise exception
  File "/home/user/.local/lib/python3.6/site-packages/sqlalchemy/orm/session.py", line 2597, in _flush
    flush_context.execute()
  File "/home/user/.local/lib/python3.6/site-packages/sqlalchemy/orm/unitofwork.py", line 422, in execute
    rec.execute(self)
  File "/home/user/.local/lib/python3.6/site-packages/sqlalchemy/orm/unitofwork.py", line 589, in execute
    uow,
  File "/home/user/.local/lib/python3.6/site-packages/sqlalchemy/orm/persistence.py", line 245, in save_obj
    insert,
  File "/home/user/.local/lib/python3.6/site-packages/sqlalchemy/orm/persistence.py", line 1136, in _emit_insert_statements
    statement, params
  File "/home/user/.local/lib/python3.6/site-packages/sqlalchemy/engine/base.py", line 984, in execute
    return meth(self, multiparams, params)
  File "/home/user/.local/lib/python3.6/site-packages/sqlalchemy/sql/elements.py", line 293, in _execute_on_connection
    return connection._execute_clauseelement(self, multiparams, params)
  File "/home/user/.local/lib/python3.6/site-packages/sqlalchemy/engine/base.py", line 1103, in _execute_clauseelement
    distilled_params,
  File "/home/user/.local/lib/python3.6/site-packages/sqlalchemy/engine/base.py", line 1288, in _execute_context
    e, statement, parameters, cursor, context
  File "/home/user/.local/lib/python3.6/site-packages/sqlalchemy/engine/base.py", line 1482, in _handle_dbapi_exception
    sqlalchemy_exception, with_traceback=exc_info[2], from_=e
  File "/home/user/.local/lib/python3.6/site-packages/sqlalchemy/util/compat.py", line 178, in raise_
    raise exception
  File "/home/user/.local/lib/python3.6/site-packages/sqlalchemy/engine/base.py", line 1248, in _execute_context
    cursor, statement, parameters, context
  File "/home/user/.local/lib/python3.6/site-packages/sqlalchemy/engine/default.py", line 590, in do_execute
    cursor.execute(statement, parameters)
  File "/home/user/.local/lib/python3.6/site-packages/MySQLdb/cursors.py", line 209, in execute
    res = self._query(query)
  File "/home/user/.local/lib/python3.6/site-packages/MySQLdb/cursors.py", line 315, in _query
    db.query(q)
  File "/home/user/.local/lib/python3.6/site-packages/MySQLdb/connections.py", line 239, in query
    _mysql.connection.query(self, query)
sqlalchemy.exc.OperationalError: (MySQLdb._exceptions.OperationalError) (1048, "Column 'name' cannot be null")
[SQL: INSERT INTO stock (name, energy, carbohydrates, sugars, fats, saturates, protein, fibre, salt) VALUES (%s, %s, %s, %s, %s, %s, %s, %s, %s)]
[parameters: (None, None, None, None, None, None, None, None, None)]
(Background on this error at: http://sqlalche.me/e/e3q8)
DEBUG:scrapy.core.engine:Crawled (200) <GET https://groceries.asda.com/product/910000539461 via http://0.0.0.0:8050/render.html> (referer: None)
ERROR:scrapy.core.scraper:Error processing {'Carbohydrate': '58.5g',
 'Date': datetime.datetime(2020, 5, 6, 9, 21, 39, 997539),
 'Energy': '2042kJ',
 'Fat': '26.0g',
 'Name': 'Bounty Coconut Milk Chocolate Twin Bars Multipack',
 'Price': '£1.50',
 'Protein': '3.8g',
 'Salt': '0.26g',
 'Saturates': '21.4g',
 'Sugars': '47.9g',
 'Supermarket': 'Asda',
 'item_url': 'https://groceries.asda.com/product/910000539461'}
Traceback (most recent call last):
  File "/home/user/.local/lib/python3.6/site-packages/sqlalchemy/engine/base.py", line 1248, in _execute_context
    cursor, statement, parameters, context
  File "/home/user/.local/lib/python3.6/site-packages/sqlalchemy/engine/default.py", line 590, in do_execute
    cursor.execute(statement, parameters)
  File "/home/user/.local/lib/python3.6/site-packages/MySQLdb/cursors.py", line 209, in execute
    res = self._query(query)
  File "/home/user/.local/lib/python3.6/site-packages/MySQLdb/cursors.py", line 315, in _query
    db.query(q)
  File "/home/user/.local/lib/python3.6/site-packages/MySQLdb/connections.py", line 239, in query
    _mysql.connection.query(self, query)
MySQLdb._exceptions.OperationalError: (1048, "Column 'name' cannot be null")

The above exception was the direct cause of the following exception:

Traceback (most recent call last):
  File "/home/user/.local/lib/python3.6/site-packages/twisted/internet/defer.py", line 654, in _runCallbacks
    current.result = callback(current.result, *args, **kw)
  File "/home/user/.local/lib/python3.6/site-packages/scrapy/utils/defer.py", line 154, in f
    return deferred_from_coro(coro_f(*coro_args, **coro_kwargs))
  File "/home/user/Documents/PythonScripts/shopscrap/shopscrap/pipelines.py", line 98, in process_item
    session.flush()
  File "/home/user/.local/lib/python3.6/site-packages/sqlalchemy/orm/session.py", line 2496, in flush
    self._flush(objects)
  File "/home/user/.local/lib/python3.6/site-packages/sqlalchemy/orm/session.py", line 2637, in _flush
    transaction.rollback(_capture_exception=True)
  File "/home/user/.local/lib/python3.6/site-packages/sqlalchemy/util/langhelpers.py", line 69, in __exit__
    exc_value, with_traceback=exc_tb,
  File "/home/user/.local/lib/python3.6/site-packages/sqlalchemy/util/compat.py", line 178, in raise_
    raise exception
  File "/home/user/.local/lib/python3.6/site-packages/sqlalchemy/orm/session.py", line 2597, in _flush
    flush_context.execute()
  File "/home/user/.local/lib/python3.6/site-packages/sqlalchemy/orm/unitofwork.py", line 422, in execute
    rec.execute(self)
  File "/home/user/.local/lib/python3.6/site-packages/sqlalchemy/orm/unitofwork.py", line 589, in execute
    uow,
  File "/home/user/.local/lib/python3.6/site-packages/sqlalchemy/orm/persistence.py", line 245, in save_obj
    insert,
  File "/home/user/.local/lib/python3.6/site-packages/sqlalchemy/orm/persistence.py", line 1136, in _emit_insert_statements
    statement, params
  File "/home/user/.local/lib/python3.6/site-packages/sqlalchemy/engine/base.py", line 984, in execute
    return meth(self, multiparams, params)
  File "/home/user/.local/lib/python3.6/site-packages/sqlalchemy/sql/elements.py", line 293, in _execute_on_connection
    return connection._execute_clauseelement(self, multiparams, params)
  File "/home/user/.local/lib/python3.6/site-packages/sqlalchemy/engine/base.py", line 1103, in _execute_clauseelement
    distilled_params,
  File "/home/user/.local/lib/python3.6/site-packages/sqlalchemy/engine/base.py", line 1288, in _execute_context
    e, statement, parameters, cursor, context
  File "/home/user/.local/lib/python3.6/site-packages/sqlalchemy/engine/base.py", line 1482, in _handle_dbapi_exception
    sqlalchemy_exception, with_traceback=exc_info[2], from_=e
  File "/home/user/.local/lib/python3.6/site-packages/sqlalchemy/util/compat.py", line 178, in raise_
    raise exception
  File "/home/user/.local/lib/python3.6/site-packages/sqlalchemy/engine/base.py", line 1248, in _execute_context
    cursor, statement, parameters, context
  File "/home/user/.local/lib/python3.6/site-packages/sqlalchemy/engine/default.py", line 590, in do_execute
    cursor.execute(statement, parameters)
  File "/home/user/.local/lib/python3.6/site-packages/MySQLdb/cursors.py", line 209, in execute
    res = self._query(query)
  File "/home/user/.local/lib/python3.6/site-packages/MySQLdb/cursors.py", line 315, in _query
    db.query(q)
  File "/home/user/.local/lib/python3.6/site-packages/MySQLdb/connections.py", line 239, in query
    _mysql.connection.query(self, query)
sqlalchemy.exc.OperationalError: (MySQLdb._exceptions.OperationalError) (1048, "Column 'name' cannot be null")
[SQL: INSERT INTO stock (name, energy, carbohydrates, sugars, fats, saturates, protein, fibre, salt) VALUES (%s, %s, %s, %s, %s, %s, %s, %s, %s)]
[parameters: (None, None, None, None, None, None, None, None, None)]
(Background on this error at: http://sqlalche.me/e/e3q8)
DEBUG:scrapy.core.engine:Crawled (200) <GET https://groceries.asda.com/product/910001192935 via http://0.0.0.0:8050/render.html> (referer: None)
ERROR:scrapy.core.scraper:Error processing {'Carbohydrate': '56.0g',
 'Date': datetime.datetime(2020, 5, 6, 9, 21, 40, 304287),
 'Energy': '2280kJ',
 'Fat': '32.4g',
 'Name': 'Galaxy Smooth Milk Chocolate Bars Multipack',
 'Price': '£1.50',
 'Protein': '6.7g',
 'Salt': '0.25g',
 'Saturates': '19.6g',
 'Sugars': '55.4g',
 'Supermarket': 'Asda',
 'item_url': 'https://groceries.asda.com/product/910001192935'}
Traceback (most recent call last):
  File "/home/user/.local/lib/python3.6/site-packages/sqlalchemy/engine/base.py", line 1248, in _execute_context
    cursor, statement, parameters, context
  File "/home/user/.local/lib/python3.6/site-packages/sqlalchemy/engine/default.py", line 590, in do_execute
    cursor.execute(statement, parameters)
  File "/home/user/.local/lib/python3.6/site-packages/MySQLdb/cursors.py", line 209, in execute
    res = self._query(query)
  File "/home/user/.local/lib/python3.6/site-packages/MySQLdb/cursors.py", line 315, in _query
    db.query(q)
  File "/home/user/.local/lib/python3.6/site-packages/MySQLdb/connections.py", line 239, in query
    _mysql.connection.query(self, query)
MySQLdb._exceptions.OperationalError: (1048, "Column 'name' cannot be null")

The above exception was the direct cause of the following exception:

Traceback (most recent call last):
  File "/home/user/.local/lib/python3.6/site-packages/twisted/internet/defer.py", line 654, in _runCallbacks
    current.result = callback(current.result, *args, **kw)
  File "/home/user/.local/lib/python3.6/site-packages/scrapy/utils/defer.py", line 154, in f
    return deferred_from_coro(coro_f(*coro_args, **coro_kwargs))
  File "/home/user/Documents/PythonScripts/shopscrap/shopscrap/pipelines.py", line 98, in process_item
    session.flush()
  File "/home/user/.local/lib/python3.6/site-packages/sqlalchemy/orm/session.py", line 2496, in flush
    self._flush(objects)
  File "/home/user/.local/lib/python3.6/site-packages/sqlalchemy/orm/session.py", line 2637, in _flush
    transaction.rollback(_capture_exception=True)
  File "/home/user/.local/lib/python3.6/site-packages/sqlalchemy/util/langhelpers.py", line 69, in __exit__
    exc_value, with_traceback=exc_tb,
  File "/home/user/.local/lib/python3.6/site-packages/sqlalchemy/util/compat.py", line 178, in raise_
    raise exception
  File "/home/user/.local/lib/python3.6/site-packages/sqlalchemy/orm/session.py", line 2597, in _flush
    flush_context.execute()
  File "/home/user/.local/lib/python3.6/site-packages/sqlalchemy/orm/unitofwork.py", line 422, in execute
    rec.execute(self)
  File "/home/user/.local/lib/python3.6/site-packages/sqlalchemy/orm/unitofwork.py", line 589, in execute
    uow,
  File "/home/user/.local/lib/python3.6/site-packages/sqlalchemy/orm/persistence.py", line 245, in save_obj
    insert,
  File "/home/user/.local/lib/python3.6/site-packages/sqlalchemy/orm/persistence.py", line 1136, in _emit_insert_statements
    statement, params
  File "/home/user/.local/lib/python3.6/site-packages/sqlalchemy/engine/base.py", line 984, in execute
    return meth(self, multiparams, params)
  File "/home/user/.local/lib/python3.6/site-packages/sqlalchemy/sql/elements.py", line 293, in _execute_on_connection
    return connection._execute_clauseelement(self, multiparams, params)
  File "/home/user/.local/lib/python3.6/site-packages/sqlalchemy/engine/base.py", line 1103, in _execute_clauseelement
    distilled_params,
  File "/home/user/.local/lib/python3.6/site-packages/sqlalchemy/engine/base.py", line 1288, in _execute_context
    e, statement, parameters, cursor, context
  File "/home/user/.local/lib/python3.6/site-packages/sqlalchemy/engine/base.py", line 1482, in _handle_dbapi_exception
    sqlalchemy_exception, with_traceback=exc_info[2], from_=e
  File "/home/user/.local/lib/python3.6/site-packages/sqlalchemy/util/compat.py", line 178, in raise_
    raise exception
  File "/home/user/.local/lib/python3.6/site-packages/sqlalchemy/engine/base.py", line 1248, in _execute_context
    cursor, statement, parameters, context
  File "/home/user/.local/lib/python3.6/site-packages/sqlalchemy/engine/default.py", line 590, in do_execute
    cursor.execute(statement, parameters)
  File "/home/user/.local/lib/python3.6/site-packages/MySQLdb/cursors.py", line 209, in execute
    res = self._query(query)
  File "/home/user/.local/lib/python3.6/site-packages/MySQLdb/cursors.py", line 315, in _query
    db.query(q)
  File "/home/user/.local/lib/python3.6/site-packages/MySQLdb/connections.py", line 239, in query
    _mysql.connection.query(self, query)
sqlalchemy.exc.OperationalError: (MySQLdb._exceptions.OperationalError) (1048, "Column 'name' cannot be null")
[SQL: INSERT INTO stock (name, energy, carbohydrates, sugars, fats, saturates, protein, fibre, salt) VALUES (%s, %s, %s, %s, %s, %s, %s, %s, %s)]
[parameters: (None, None, None, None, None, None, None, None, None)]
(Background on this error at: http://sqlalche.me/e/e3q8)
DEBUG:scrapy.core.engine:Crawled (200) <GET https://groceries.asda.com/product/68021675 via http://0.0.0.0:8050/render.html> (referer: None)
ERROR:scrapy.core.scraper:Error processing {'Carbohydrate': '58.7g',
 'Date': datetime.datetime(2020, 5, 6, 9, 21, 40, 737794),
 'Energy': '2211kJ',
 'Fat': '29.1g',
 'Name': 'Galaxy Ripple Chocolate Bars Multipack',
 'Price': '£1.50',
 'Protein': '7.1g',
 'Salt': '0.31g',
 'Saturates': '17.2g',
 'Sugars': '58.2g',
 'Supermarket': 'Asda',
 'item_url': 'https://groceries.asda.com/product/68021675'}
Traceback (most recent call last):
  File "/home/user/.local/lib/python3.6/site-packages/sqlalchemy/engine/base.py", line 1248, in _execute_context
    cursor, statement, parameters, context
  File "/home/user/.local/lib/python3.6/site-packages/sqlalchemy/engine/default.py", line 590, in do_execute
    cursor.execute(statement, parameters)
  File "/home/user/.local/lib/python3.6/site-packages/MySQLdb/cursors.py", line 209, in execute
    res = self._query(query)
  File "/home/user/.local/lib/python3.6/site-packages/MySQLdb/cursors.py", line 315, in _query
    db.query(q)
  File "/home/user/.local/lib/python3.6/site-packages/MySQLdb/connections.py", line 239, in query
    _mysql.connection.query(self, query)
MySQLdb._exceptions.OperationalError: (1048, "Column 'name' cannot be null")

The above exception was the direct cause of the following exception:

Traceback (most recent call last):
  File "/home/user/.local/lib/python3.6/site-packages/twisted/internet/defer.py", line 654, in _runCallbacks
    current.result = callback(current.result, *args, **kw)
  File "/home/user/.local/lib/python3.6/site-packages/scrapy/utils/defer.py", line 154, in f
    return deferred_from_coro(coro_f(*coro_args, **coro_kwargs))
  File "/home/user/Documents/PythonScripts/shopscrap/shopscrap/pipelines.py", line 98, in process_item
    session.flush()
  File "/home/user/.local/lib/python3.6/site-packages/sqlalchemy/orm/session.py", line 2496, in flush
    self._flush(objects)
  File "/home/user/.local/lib/python3.6/site-packages/sqlalchemy/orm/session.py", line 2637, in _flush
    transaction.rollback(_capture_exception=True)
  File "/home/user/.local/lib/python3.6/site-packages/sqlalchemy/util/langhelpers.py", line 69, in __exit__
    exc_value, with_traceback=exc_tb,
  File "/home/user/.local/lib/python3.6/site-packages/sqlalchemy/util/compat.py", line 178, in raise_
    raise exception
  File "/home/user/.local/lib/python3.6/site-packages/sqlalchemy/orm/session.py", line 2597, in _flush
    flush_context.execute()
  File "/home/user/.local/lib/python3.6/site-packages/sqlalchemy/orm/unitofwork.py", line 422, in execute
    rec.execute(self)
  File "/home/user/.local/lib/python3.6/site-packages/sqlalchemy/orm/unitofwork.py", line 589, in execute
    uow,
  File "/home/user/.local/lib/python3.6/site-packages/sqlalchemy/orm/persistence.py", line 245, in save_obj
    insert,
  File "/home/user/.local/lib/python3.6/site-packages/sqlalchemy/orm/persistence.py", line 1136, in _emit_insert_statements
    statement, params
  File "/home/user/.local/lib/python3.6/site-packages/sqlalchemy/engine/base.py", line 984, in execute
    return meth(self, multiparams, params)
  File "/home/user/.local/lib/python3.6/site-packages/sqlalchemy/sql/elements.py", line 293, in _execute_on_connection
    return connection._execute_clauseelement(self, multiparams, params)
  File "/home/user/.local/lib/python3.6/site-packages/sqlalchemy/engine/base.py", line 1103, in _execute_clauseelement
    distilled_params,
  File "/home/user/.local/lib/python3.6/site-packages/sqlalchemy/engine/base.py", line 1288, in _execute_context
    e, statement, parameters, cursor, context
  File "/home/user/.local/lib/python3.6/site-packages/sqlalchemy/engine/base.py", line 1482, in _handle_dbapi_exception
    sqlalchemy_exception, with_traceback=exc_info[2], from_=e
  File "/home/user/.local/lib/python3.6/site-packages/sqlalchemy/util/compat.py", line 178, in raise_
    raise exception
  File "/home/user/.local/lib/python3.6/site-packages/sqlalchemy/engine/base.py", line 1248, in _execute_context
    cursor, statement, parameters, context
  File "/home/user/.local/lib/python3.6/site-packages/sqlalchemy/engine/default.py", line 590, in do_execute
    cursor.execute(statement, parameters)
  File "/home/user/.local/lib/python3.6/site-packages/MySQLdb/cursors.py", line 209, in execute
    res = self._query(query)
  File "/home/user/.local/lib/python3.6/site-packages/MySQLdb/cursors.py", line 315, in _query
    db.query(q)
  File "/home/user/.local/lib/python3.6/site-packages/MySQLdb/connections.py", line 239, in query
    _mysql.connection.query(self, query)
sqlalchemy.exc.OperationalError: (MySQLdb._exceptions.OperationalError) (1048, "Column 'name' cannot be null")
[SQL: INSERT INTO stock (name, energy, carbohydrates, sugars, fats, saturates, protein, fibre, salt) VALUES (%s, %s, %s, %s, %s, %s, %s, %s, %s)]
[parameters: (None, None, None, None, None, None, None, None, None)]
(Background on this error at: http://sqlalche.me/e/e3q8)
DEBUG:scrapy.core.engine:Crawled (200) <GET https://groceries.asda.com/product/23779 via http://0.0.0.0:8050/render.html> (referer: None)
ERROR:scrapy.core.scraper:Error processing {'Carbohydrate': '9.8g',
 'Date': datetime.datetime(2020, 5, 6, 9, 21, 42, 872956),
 'Energy': '310kJ/',
 'Fat': '1.8g',
 'Fibre': '<0.5g',
 'Name': "Colman's Parsley Sauce Mix",
 'Price': '£0.80',
 'Protein': '4.2g',
 'Salt': '0.8g',
 'Saturates': '1g',
 'Sugars': '5.3g',
 'Supermarket': 'Asda',
 'item_url': 'https://groceries.asda.com/product/23779'}
Traceback (most recent call last):
  File "/home/user/.local/lib/python3.6/site-packages/sqlalchemy/engine/base.py", line 1248, in _execute_context
    cursor, statement, parameters, context
  File "/home/user/.local/lib/python3.6/site-packages/sqlalchemy/engine/default.py", line 590, in do_execute
    cursor.execute(statement, parameters)
  File "/home/user/.local/lib/python3.6/site-packages/MySQLdb/cursors.py", line 209, in execute
    res = self._query(query)
  File "/home/user/.local/lib/python3.6/site-packages/MySQLdb/cursors.py", line 315, in _query
    db.query(q)
  File "/home/user/.local/lib/python3.6/site-packages/MySQLdb/connections.py", line 239, in query
    _mysql.connection.query(self, query)
MySQLdb._exceptions.OperationalError: (1048, "Column 'name' cannot be null")

The above exception was the direct cause of the following exception:

Traceback (most recent call last):
  File "/home/user/.local/lib/python3.6/site-packages/twisted/internet/defer.py", line 654, in _runCallbacks
    current.result = callback(current.result, *args, **kw)
  File "/home/user/.local/lib/python3.6/site-packages/scrapy/utils/defer.py", line 154, in f
    return deferred_from_coro(coro_f(*coro_args, **coro_kwargs))
  File "/home/user/Documents/PythonScripts/shopscrap/shopscrap/pipelines.py", line 98, in process_item
    session.flush()
  File "/home/user/.local/lib/python3.6/site-packages/sqlalchemy/orm/session.py", line 2496, in flush
    self._flush(objects)
  File "/home/user/.local/lib/python3.6/site-packages/sqlalchemy/orm/session.py", line 2637, in _flush
    transaction.rollback(_capture_exception=True)
  File "/home/user/.local/lib/python3.6/site-packages/sqlalchemy/util/langhelpers.py", line 69, in __exit__
    exc_value, with_traceback=exc_tb,
  File "/home/user/.local/lib/python3.6/site-packages/sqlalchemy/util/compat.py", line 178, in raise_
    raise exception
  File "/home/user/.local/lib/python3.6/site-packages/sqlalchemy/orm/session.py", line 2597, in _flush
    flush_context.execute()
  File "/home/user/.local/lib/python3.6/site-packages/sqlalchemy/orm/unitofwork.py", line 422, in execute
    rec.execute(self)
  File "/home/user/.local/lib/python3.6/site-packages/sqlalchemy/orm/unitofwork.py", line 589, in execute
    uow,
  File "/home/user/.local/lib/python3.6/site-packages/sqlalchemy/orm/persistence.py", line 245, in save_obj
    insert,
  File "/home/user/.local/lib/python3.6/site-packages/sqlalchemy/orm/persistence.py", line 1136, in _emit_insert_statements
    statement, params
  File "/home/user/.local/lib/python3.6/site-packages/sqlalchemy/engine/base.py", line 984, in execute
    return meth(self, multiparams, params)
  File "/home/user/.local/lib/python3.6/site-packages/sqlalchemy/sql/elements.py", line 293, in _execute_on_connection
    return connection._execute_clauseelement(self, multiparams, params)
  File "/home/user/.local/lib/python3.6/site-packages/sqlalchemy/engine/base.py", line 1103, in _execute_clauseelement
    distilled_params,
  File "/home/user/.local/lib/python3.6/site-packages/sqlalchemy/engine/base.py", line 1288, in _execute_context
    e, statement, parameters, cursor, context
  File "/home/user/.local/lib/python3.6/site-packages/sqlalchemy/engine/base.py", line 1482, in _handle_dbapi_exception
    sqlalchemy_exception, with_traceback=exc_info[2], from_=e
  File "/home/user/.local/lib/python3.6/site-packages/sqlalchemy/util/compat.py", line 178, in raise_
    raise exception
  File "/home/user/.local/lib/python3.6/site-packages/sqlalchemy/engine/base.py", line 1248, in _execute_context
    cursor, statement, parameters, context
  File "/home/user/.local/lib/python3.6/site-packages/sqlalchemy/engine/default.py", line 590, in do_execute
    cursor.execute(statement, parameters)
  File "/home/user/.local/lib/python3.6/site-packages/MySQLdb/cursors.py", line 209, in execute
    res = self._query(query)
  File "/home/user/.local/lib/python3.6/site-packages/MySQLdb/cursors.py", line 315, in _query
    db.query(q)
  File "/home/user/.local/lib/python3.6/site-packages/MySQLdb/connections.py", line 239, in query
    _mysql.connection.query(self, query)
sqlalchemy.exc.OperationalError: (MySQLdb._exceptions.OperationalError) (1048, "Column 'name' cannot be null")
[SQL: INSERT INTO stock (name, energy, carbohydrates, sugars, fats, saturates, protein, fibre, salt) VALUES (%s, %s, %s, %s, %s, %s, %s, %s, %s)]
[parameters: (None, None, None, None, None, None, None, None, None)]
(Background on this error at: http://sqlalche.me/e/e3q8)
DEBUG:scrapy.core.engine:Crawled (200) <GET https://groceries.asda.com/product/910001935884 via http://0.0.0.0:8050/render.html> (referer: None)
ERROR:scrapy.core.scraper:Error processing {'Carbohydrate': '11.9',
 'Date': datetime.datetime(2020, 5, 6, 9, 21, 43, 71357),
 'Energy': '223/53',
 'Name': 'Ribena Blackcurrant Squash',
 'Price': '£3.75',
 'Salt': '0.15',
 'Sugars': '11.5',
 'Supermarket': 'Asda',
 'item_url': 'https://groceries.asda.com/product/910001935884'}
Traceback (most recent call last):
  File "/home/user/.local/lib/python3.6/site-packages/sqlalchemy/engine/base.py", line 1248, in _execute_context
    cursor, statement, parameters, context
  File "/home/user/.local/lib/python3.6/site-packages/sqlalchemy/engine/default.py", line 590, in do_execute
    cursor.execute(statement, parameters)
  File "/home/user/.local/lib/python3.6/site-packages/MySQLdb/cursors.py", line 209, in execute
    res = self._query(query)
  File "/home/user/.local/lib/python3.6/site-packages/MySQLdb/cursors.py", line 315, in _query
    db.query(q)
  File "/home/user/.local/lib/python3.6/site-packages/MySQLdb/connections.py", line 239, in query
    _mysql.connection.query(self, query)
MySQLdb._exceptions.OperationalError: (1048, "Column 'name' cannot be null")

The above exception was the direct cause of the following exception:

Traceback (most recent call last):
  File "/home/user/.local/lib/python3.6/site-packages/twisted/internet/defer.py", line 654, in _runCallbacks
    current.result = callback(current.result, *args, **kw)
  File "/home/user/.local/lib/python3.6/site-packages/scrapy/utils/defer.py", line 154, in f
    return deferred_from_coro(coro_f(*coro_args, **coro_kwargs))
  File "/home/user/Documents/PythonScripts/shopscrap/shopscrap/pipelines.py", line 98, in process_item
    session.flush()
  File "/home/user/.local/lib/python3.6/site-packages/sqlalchemy/orm/session.py", line 2496, in flush
    self._flush(objects)
  File "/home/user/.local/lib/python3.6/site-packages/sqlalchemy/orm/session.py", line 2637, in _flush
    transaction.rollback(_capture_exception=True)
  File "/home/user/.local/lib/python3.6/site-packages/sqlalchemy/util/langhelpers.py", line 69, in __exit__
    exc_value, with_traceback=exc_tb,
  File "/home/user/.local/lib/python3.6/site-packages/sqlalchemy/util/compat.py", line 178, in raise_
    raise exception
  File "/home/user/.local/lib/python3.6/site-packages/sqlalchemy/orm/session.py", line 2597, in _flush
    flush_context.execute()
  File "/home/user/.local/lib/python3.6/site-packages/sqlalchemy/orm/unitofwork.py", line 422, in execute
    rec.execute(self)
  File "/home/user/.local/lib/python3.6/site-packages/sqlalchemy/orm/unitofwork.py", line 589, in execute
    uow,
  File "/home/user/.local/lib/python3.6/site-packages/sqlalchemy/orm/persistence.py", line 245, in save_obj
    insert,
  File "/home/user/.local/lib/python3.6/site-packages/sqlalchemy/orm/persistence.py", line 1136, in _emit_insert_statements
    statement, params
  File "/home/user/.local/lib/python3.6/site-packages/sqlalchemy/engine/base.py", line 984, in execute
    return meth(self, multiparams, params)
  File "/home/user/.local/lib/python3.6/site-packages/sqlalchemy/sql/elements.py", line 293, in _execute_on_connection
    return connection._execute_clauseelement(self, multiparams, params)
  File "/home/user/.local/lib/python3.6/site-packages/sqlalchemy/engine/base.py", line 1103, in _execute_clauseelement
    distilled_params,
  File "/home/user/.local/lib/python3.6/site-packages/sqlalchemy/engine/base.py", line 1288, in _execute_context
    e, statement, parameters, cursor, context
  File "/home/user/.local/lib/python3.6/site-packages/sqlalchemy/engine/base.py", line 1482, in _handle_dbapi_exception
    sqlalchemy_exception, with_traceback=exc_info[2], from_=e
  File "/home/user/.local/lib/python3.6/site-packages/sqlalchemy/util/compat.py", line 178, in raise_
    raise exception
  File "/home/user/.local/lib/python3.6/site-packages/sqlalchemy/engine/base.py", line 1248, in _execute_context
    cursor, statement, parameters, context
  File "/home/user/.local/lib/python3.6/site-packages/sqlalchemy/engine/default.py", line 590, in do_execute
    cursor.execute(statement, parameters)
  File "/home/user/.local/lib/python3.6/site-packages/MySQLdb/cursors.py", line 209, in execute
    res = self._query(query)
  File "/home/user/.local/lib/python3.6/site-packages/MySQLdb/cursors.py", line 315, in _query
    db.query(q)
  File "/home/user/.local/lib/python3.6/site-packages/MySQLdb/connections.py", line 239, in query
    _mysql.connection.query(self, query)
sqlalchemy.exc.OperationalError: (MySQLdb._exceptions.OperationalError) (1048, "Column 'name' cannot be null")
[SQL: INSERT INTO stock (name, energy, carbohydrates, sugars, fats, saturates, protein, fibre, salt) VALUES (%s, %s, %s, %s, %s, %s, %s, %s, %s)]
[parameters: (None, None, None, None, None, None, None, None, None)]
(Background on this error at: http://sqlalche.me/e/e3q8)
INFO:scrapy.crawler:Received SIGINT, shutting down gracefully. Send again to force 
INFO:scrapy.core.engine:Closing spider (shutdown)
INFO:scrapy.crawler:Received SIGINT twice, forcing unclean shutdown
DEBUG:scrapy.downloadermiddlewares.retry:Retrying <GET https://groceries.asda.com/product/1000039942582 via http://0.0.0.0:8050/render.html> (failed 1 times): [<twisted.python.failure.Failure twisted.internet.error.ConnectionLost: Connection to the other side was lost in a non-clean fashion: Connection lost.>]
DEBUG:scrapy.downloadermiddlewares.retry:Retrying <GET https://groceries.asda.com/product/910000400000 via http://0.0.0.0:8050/render.html> (failed 1 times): [<twisted.python.failure.Failure twisted.internet.error.ConnectionLost: Connection to the other side was lost in a non-clean fashion: Connection lost.>]
DEBUG:scrapy.downloadermiddlewares.retry:Retrying <GET https://groceries.asda.com/product/78840573 via http://0.0.0.0:8050/render.html> (failed 1 times): [<twisted.python.failure.Failure twisted.internet.error.ConnectionLost: Connection to the other side was lost in a non-clean fashion: Connection lost.>]
DEBUG:scrapy.downloadermiddlewares.retry:Retrying <GET https://groceries.asda.com/product/910000026780 via http://0.0.0.0:8050/render.html> (failed 1 times): [<twisted.python.failure.Failure twisted.internet.error.ConnectionLost: Connection to the other side was lost in a non-clean fashion: Connection lost.>]
DEBUG:scrapy.downloadermiddlewares.retry:Retrying <GET https://groceries.asda.com/product/910000254290 via http://0.0.0.0:8050/render.html> (failed 1 times): [<twisted.python.failure.Failure twisted.internet.error.ConnectionLost: Connection to the other side was lost in a non-clean fashion: Connection lost.>]
DEBUG:scrapy.downloadermiddlewares.retry:Retrying <GET https://groceries.asda.com/product/1000161632988 via http://0.0.0.0:8050/render.html> (failed 1 times): [<twisted.python.failure.Failure twisted.internet.error.ConnectionLost: Connection to the other side was lost in a non-clean fashion: Connection lost.>]
DEBUG:scrapy.downloadermiddlewares.retry:Retrying <GET https://groceries.asda.com/product/444083 via http://0.0.0.0:8050/render.html> (failed 1 times): [<twisted.python.failure.Failure twisted.internet.error.ConnectionLost: Connection to the other side was lost in a non-clean fashion: Connection lost.>]
DEBUG:scrapy.downloadermiddlewares.retry:Retrying <GET https://groceries.asda.com/product/1000203231946 via http://0.0.0.0:8050/render.html> (failed 1 times): [<twisted.python.failure.Failure twisted.internet.error.ConnectionLost: Connection to the other side was lost in a non-clean fashion: Connection lost.>]
WARNING:root:Spider warnings
INFO:scrapy.utils.log:Scrapy 2.0.1 started (bot: shopscrap)
INFO:scrapy.utils.log:Versions: lxml 4.5.0.0, libxml2 2.9.10, cssselect 1.1.0, parsel 1.5.2, w3lib 1.21.0, Twisted 20.3.0, Python 3.6.9 (default, Apr 18 2020, 01:56:04) - [GCC 8.4.0], pyOpenSSL 19.1.0 (OpenSSL 1.1.1f  31 Mar 2020), cryptography 2.9, Platform Linux-5.3.0-51-generic-x86_64-with-Ubuntu-18.04-bionic
DEBUG:scrapy.utils.log:Using reactor: twisted.internet.epollreactor.EPollReactor
INFO:scrapy.crawler:Overridden settings:
{'BOT_NAME': 'shopscrap',
 'DUPEFILTER_CLASS': 'scrapy_splash.SplashAwareDupeFilter',
 'HTTPCACHE_STORAGE': 'scrapy_splash.SplashAwareFSCacheStorage',
 'NEWSPIDER_MODULE': 'shopscrap.spiders',
 'SPIDER_MODULES': ['shopscrap.spiders'],
 'USER_AGENT': 'Mozilla/5.0 (X11; Linux x86_64) AppleWebKit/537.36 (KHTML, '
               'like Gecko) Brave Chrome/80.0.3987.163 Safari/537.36'}
INFO:scrapy.extensions.telnet:Telnet Password: 78c46e0198a607c3
INFO:scrapy.middleware:Enabled extensions:
['scrapy.extensions.corestats.CoreStats',
 'scrapy.extensions.telnet.TelnetConsole',
 'scrapy.extensions.memusage.MemoryUsage',
 'scrapy.extensions.logstats.LogStats']
INFO:scrapy.middleware:Enabled downloader middlewares:
['scrapy.downloadermiddlewares.httpauth.HttpAuthMiddleware',
 'scrapy.downloadermiddlewares.downloadtimeout.DownloadTimeoutMiddleware',
 'scrapy.downloadermiddlewares.defaultheaders.DefaultHeadersMiddleware',
 'scrapy.downloadermiddlewares.useragent.UserAgentMiddleware',
 'scrapy.downloadermiddlewares.retry.RetryMiddleware',
 'scrapy.downloadermiddlewares.redirect.MetaRefreshMiddleware',
 'scrapy.downloadermiddlewares.redirect.RedirectMiddleware',
 'scrapy.downloadermiddlewares.cookies.CookiesMiddleware',
 'scrapy_splash.SplashCookiesMiddleware',
 'scrapy_splash.SplashMiddleware',
 'scrapy.downloadermiddlewares.httpproxy.HttpProxyMiddleware',
 'scrapy.downloadermiddlewares.httpcompression.HttpCompressionMiddleware',
 'scrapy.downloadermiddlewares.stats.DownloaderStats']
INFO:scrapy.middleware:Enabled spider middlewares:
['scrapy.spidermiddlewares.httperror.HttpErrorMiddleware',
 'scrapy_splash.SplashDeduplicateArgsMiddleware',
 'scrapy.spidermiddlewares.offsite.OffsiteMiddleware',
 'scrapy.spidermiddlewares.referer.RefererMiddleware',
 'scrapy.spidermiddlewares.urllength.UrlLengthMiddleware',
 'scrapy.spidermiddlewares.depth.DepthMiddleware']
INFO:scrapy.middleware:Enabled item pipelines:
['shopscrap.pipelines.ShopScrapdb']
INFO:scrapy.core.engine:Spider opened
INFO:scrapy.extensions.logstats:Crawled 0 pages (at 0 pages/min), scraped 0 items (at 0 items/min)
INFO:scrapy.extensions.telnet:Telnet console listening on 127.0.0.1:6029
WARNING:py.warnings:/home/user/.local/lib/python3.6/site-packages/scrapy_splash/request.py:41: ScrapyDeprecationWarning: Call to deprecated function to_native_str. Use to_unicode instead.
  url = to_native_str(url)

DEBUG:scrapy.core.engine:Crawled (200) <GET https://groceries.asda.com/product/cornflakes-honey-nut/kelloggs-crunchy-nut-corn-flakes/19140/ via http://0.0.0.0:8050/render.html> (referer: None)
DEBUG:scrapy.core.scraper:Scraped from <200 https://groceries.asda.com/product/cornflakes-honey-nut/kelloggs-crunchy-nut-corn-flakes/19140/>
{'Carbohydrate': '82g',
 'Date': datetime.datetime(2020, 5, 6, 9, 22, 39, 286845),
 'Energy': '1683kJ',
 'Fat': '4.5g',
 'Fibre': '2.5g',
 'Name': "Kellogg's Crunchy Nut Corn Flakes",
 'Price': '£2.00',
 'Protein': '6g',
 'Salt': '0.75g',
 'Saturates': '0.7g',
 'Sugars': '35g',
 'Supermarket': 'Asda',
 'item_url': 'https://groceries.asda.com/product/cornflakes-honey-nut/kelloggs-crunchy-nut-corn-flakes/19140/'}
DEBUG:scrapy.core.engine:Crawled (200) <GET https://groceries.asda.com/product/25857 via http://0.0.0.0:8050/render.html> (referer: None)
DEBUG:scrapy.core.engine:Crawled (200) <GET https://groceries.asda.com/product/910000212250 via http://0.0.0.0:8050/render.html> (referer: None)
DEBUG:scrapy.core.engine:Crawled (200) <GET https://groceries.asda.com/product/910000057722 via http://0.0.0.0:8050/render.html> (referer: None)
DEBUG:scrapy.core.engine:Crawled (200) <GET https://groceries.asda.com/product/80975593 via http://0.0.0.0:8050/render.html> (referer: None)
DEBUG:scrapy.core.scraper:Scraped from <200 https://groceries.asda.com/product/25857>
{'Carbohydrate': '41.2 g',
 'Date': datetime.datetime(2020, 5, 6, 9, 22, 50, 522761),
 'Energy': '954 kJ / 226 kcal',
 'Fat': '3.5 g',
 'Fibre': '1.5 g',
 'Name': 'Old El Paso Mexican Original Smoky BBQ Fajita Kit',
 'Price': '£3.18',
 'Protein': '6.6 g',
 'Salt': '1.99 g',
 'Saturates': '0.8 g',
 'Sugars': '6.2 g',
 'Supermarket': 'Asda',
 'item_url': 'https://groceries.asda.com/product/25857'}
DEBUG:scrapy.core.scraper:Scraped from <200 https://groceries.asda.com/product/910000212250>
{'Carbohydrate': '1.4 g',
 'Date': datetime.datetime(2020, 5, 6, 9, 22, 50, 594976),
 'Energy': '726 kcal',
 'Fat': '79 g',
 'Name': "Hellmann's Real Squeezy Mayonnaise",
 'Price': '£2.00',
 'Protein': '1.1 g',
 'Salt': '1.5 g',
 'Saturates': '6.3 g',
 'Sugars': '1.3 g',
 'Supermarket': 'Asda',
 'item_url': 'https://groceries.asda.com/product/910000212250'}
DEBUG:scrapy.core.scraper:Scraped from <200 https://groceries.asda.com/product/910000057722>
{'Carbohydrate': '1.3 g',
 'Date': datetime.datetime(2020, 5, 6, 9, 22, 50, 614936),
 'Energy': '721 kcal',
 'Fat': '79 g',
 'Name': "Hellmann's Real Mayonnaise",
 'Price': '£3.00',
 'Protein': '1.1 g',
 'Salt': '1.5 g',
 'Saturates': '6.2 g',
 'Sugars': '1.3 g',
 'Supermarket': 'Asda',
 'item_url': 'https://groceries.asda.com/product/910000057722'}
DEBUG:scrapy.core.scraper:Scraped from <200 https://groceries.asda.com/product/80975593>
{'Carbohydrate': '53.5',
 'Date': datetime.datetime(2020, 5, 6, 9, 22, 50, 638846),
 'Energy': '2360/566',
 'Fat': '35',
 'Name': 'Kinder Chocolate Bar 16 Pack',
 'Price': '£1.50',
 'Protein': '8.7',
 'Salt': '0.313',
 'Supermarket': 'Asda',
 'item_url': 'https://groceries.asda.com/product/80975593'}
DEBUG:scrapy.dupefilters:Filtered duplicate request: <GET https://groceries.asda.com/product/910000212250> - no more duplicates will be shown (see DUPEFILTER_DEBUG to show all duplicates)
DEBUG:scrapy.core.engine:Crawled (200) <GET https://groceries.asda.com/product/1639642 via http://0.0.0.0:8050/render.html> (referer: None)
DEBUG:scrapy.core.engine:Crawled (200) <GET https://groceries.asda.com/product/910000396129 via http://0.0.0.0:8050/render.html> (referer: None)
DEBUG:scrapy.core.scraper:Scraped from <200 https://groceries.asda.com/product/1639642>
{'Carbohydrate': '64.9g',
 'Date': datetime.datetime(2020, 5, 6, 9, 22, 50, 829527),
 'Energy': '2065kJ',
 'Fat': '23.7g',
 'Name': 'Twix Chocolate Biscuit Fingers Multipack',
 'Price': '£2.00',
 'Protein': '4.4g',
 'Salt': '0.41g',
 'Saturates': '13.7g',
 'Sugars': '49.1g',
 'Supermarket': 'Asda',
 'item_url': 'https://groceries.asda.com/product/1639642'}
DEBUG:scrapy.core.scraper:Scraped from <200 https://groceries.asda.com/product/910000396129>
{'Carbohydrate': '86g',
 'Date': datetime.datetime(2020, 5, 6, 9, 22, 50, 858570),
 'Energy': '387kcal',
 'Fat': '1.2g',
 'Fibre': '2.0g',
 'Name': "Kellogg's Rice Krispies",
 'Price': '£3.00',
 'Protein': '7g',
 'Salt': '1g',
 'Saturates': '0.4g',
 'Sugars': '7.9g',
 'Supermarket': 'Asda',
 'item_url': 'https://groceries.asda.com/product/910000396129'}
DEBUG:scrapy.core.engine:Crawled (200) <GET https://groceries.asda.com/product/1217550 via http://0.0.0.0:8050/render.html> (referer: None)
DEBUG:scrapy.core.scraper:Scraped from <200 https://groceries.asda.com/product/1217550>
{'Carbohydrate': '79g',
 'Date': datetime.datetime(2020, 5, 6, 9, 22, 51, 120501),
 'Energy': '1588kJ',
 'Fat': '1.5g',
 'Fibre': '4.5g',
 'Name': "Kellogg's Special K Original",
 'Price': '£3.98',
 'Protein': '9g',
 'Salt': '1g',
 'Saturates': '0.3g',
 'Sugars': '15g',
 'Supermarket': 'Asda',
 'item_url': 'https://groceries.asda.com/product/1217550'}
DEBUG:scrapy.core.engine:Crawled (200) <GET https://groceries.asda.com/product/910000020309 via http://0.0.0.0:8050/render.html> (referer: None)
DEBUG:scrapy.core.scraper:Scraped from <200 https://groceries.asda.com/product/910000020309>
{'Carbohydrate': '1.4 g',
 'Date': datetime.datetime(2020, 5, 6, 9, 22, 52, 463861),
 'Energy': '726 kcal',
 'Fat': '79 g',
 'Name': "Hellmann's Squeezy Real Mayonnaise",
 'Price': '£1.99',
 'Protein': '1.1 g',
 'Salt': '1.5 g',
 'Saturates': '6.3 g',
 'Sugars': '1.3 g',
 'Supermarket': 'Asda',
 'item_url': 'https://groceries.asda.com/product/910000020309'}
INFO:scrapy.crawler:Received SIGINT, shutting down gracefully. Send again to force 
INFO:scrapy.core.engine:Closing spider (shutdown)
INFO:scrapy.crawler:Received SIGINT twice, forcing unclean shutdown
DEBUG:scrapy.downloadermiddlewares.retry:Retrying <GET https://groceries.asda.com/product/910000026780 via http://0.0.0.0:8050/render.html> (failed 1 times): [<twisted.python.failure.Failure twisted.internet.error.ConnectionLost: Connection to the other side was lost in a non-clean fashion: Connection lost.>]
DEBUG:scrapy.downloadermiddlewares.retry:Retrying <GET https://groceries.asda.com/product/910000043501 via http://0.0.0.0:8050/render.html> (failed 1 times): [<twisted.python.failure.Failure twisted.internet.error.ConnectionLost: Connection to the other side was lost in a non-clean fashion: Connection lost.>]
DEBUG:scrapy.downloadermiddlewares.retry:Retrying <GET https://groceries.asda.com/product/910001192935 via http://0.0.0.0:8050/render.html> (failed 1 times): [<twisted.python.failure.Failure twisted.internet.error.ConnectionLost: Connection to the other side was lost in a non-clean fashion: Connection lost.>]
DEBUG:scrapy.downloadermiddlewares.retry:Retrying <GET https://groceries.asda.com/product/19140 via http://0.0.0.0:8050/render.html> (failed 1 times): [<twisted.python.failure.Failure twisted.internet.error.ConnectionLost: Connection to the other side was lost in a non-clean fashion: Connection lost.>]
DEBUG:scrapy.downloadermiddlewares.retry:Retrying <GET https://groceries.asda.com/product/910000539461 via http://0.0.0.0:8050/render.html> (failed 1 times): [<twisted.python.failure.Failure twisted.internet.error.ConnectionLost: Connection to the other side was lost in a non-clean fashion: Connection lost.>]
DEBUG:scrapy.downloadermiddlewares.retry:Retrying <GET https://groceries.asda.com/product/910000261256 via http://0.0.0.0:8050/render.html> (failed 1 times): [<twisted.python.failure.Failure twisted.internet.error.ConnectionLost: Connection to the other side was lost in a non-clean fashion: Connection lost.>]
DEBUG:scrapy.downloadermiddlewares.retry:Retrying <GET https://groceries.asda.com/product/24076 via http://0.0.0.0:8050/render.html> (failed 1 times): [<twisted.python.failure.Failure twisted.internet.error.ConnectionLost: Connection to the other side was lost in a non-clean fashion: Connection lost.>]
DEBUG:scrapy.downloadermiddlewares.retry:Retrying <GET https://groceries.asda.com/product/68021675 via http://0.0.0.0:8050/render.html> (failed 1 times): [<twisted.python.failure.Failure twisted.internet.error.ConnectionLost: Connection to the other side was lost in a non-clean fashion: Connection lost.>]
WARNING:root:Spider warnings
INFO:scrapy.utils.log:Scrapy 2.0.1 started (bot: shopscrap)
INFO:scrapy.utils.log:Versions: lxml 4.5.0.0, libxml2 2.9.10, cssselect 1.1.0, parsel 1.5.2, w3lib 1.21.0, Twisted 20.3.0, Python 3.6.9 (default, Apr 18 2020, 01:56:04) - [GCC 8.4.0], pyOpenSSL 19.1.0 (OpenSSL 1.1.1f  31 Mar 2020), cryptography 2.9, Platform Linux-5.3.0-51-generic-x86_64-with-Ubuntu-18.04-bionic
DEBUG:scrapy.utils.log:Using reactor: twisted.internet.epollreactor.EPollReactor
INFO:scrapy.crawler:Overridden settings:
{'BOT_NAME': 'shopscrap',
 'DUPEFILTER_CLASS': 'scrapy_splash.SplashAwareDupeFilter',
 'HTTPCACHE_STORAGE': 'scrapy_splash.SplashAwareFSCacheStorage',
 'NEWSPIDER_MODULE': 'shopscrap.spiders',
 'SPIDER_MODULES': ['shopscrap.spiders'],
 'USER_AGENT': 'Mozilla/5.0 (X11; Linux x86_64) AppleWebKit/537.36 (KHTML, '
               'like Gecko) Brave Chrome/80.0.3987.163 Safari/537.36'}
INFO:scrapy.extensions.telnet:Telnet Password: 95a7841b138fffd5
INFO:scrapy.middleware:Enabled extensions:
['scrapy.extensions.corestats.CoreStats',
 'scrapy.extensions.telnet.TelnetConsole',
 'scrapy.extensions.memusage.MemoryUsage',
 'scrapy.extensions.logstats.LogStats']
INFO:scrapy.middleware:Enabled downloader middlewares:
['scrapy.downloadermiddlewares.httpauth.HttpAuthMiddleware',
 'scrapy.downloadermiddlewares.downloadtimeout.DownloadTimeoutMiddleware',
 'scrapy.downloadermiddlewares.defaultheaders.DefaultHeadersMiddleware',
 'scrapy.downloadermiddlewares.useragent.UserAgentMiddleware',
 'scrapy.downloadermiddlewares.retry.RetryMiddleware',
 'scrapy.downloadermiddlewares.redirect.MetaRefreshMiddleware',
 'scrapy.downloadermiddlewares.redirect.RedirectMiddleware',
 'scrapy.downloadermiddlewares.cookies.CookiesMiddleware',
 'scrapy_splash.SplashCookiesMiddleware',
 'scrapy_splash.SplashMiddleware',
 'scrapy.downloadermiddlewares.httpproxy.HttpProxyMiddleware',
 'scrapy.downloadermiddlewares.httpcompression.HttpCompressionMiddleware',
 'scrapy.downloadermiddlewares.stats.DownloaderStats']
INFO:scrapy.middleware:Enabled spider middlewares:
['scrapy.spidermiddlewares.httperror.HttpErrorMiddleware',
 'scrapy_splash.SplashDeduplicateArgsMiddleware',
 'scrapy.spidermiddlewares.offsite.OffsiteMiddleware',
 'scrapy.spidermiddlewares.referer.RefererMiddleware',
 'scrapy.spidermiddlewares.urllength.UrlLengthMiddleware',
 'scrapy.spidermiddlewares.depth.DepthMiddleware']
INFO:scrapy.middleware:Enabled item pipelines:
['shopscrap.pipelines.ShopScrapdb']
INFO:scrapy.core.engine:Spider opened
INFO:scrapy.extensions.logstats:Crawled 0 pages (at 0 pages/min), scraped 0 items (at 0 items/min)
INFO:scrapy.extensions.telnet:Telnet console listening on 127.0.0.1:6029
WARNING:py.warnings:/home/user/.local/lib/python3.6/site-packages/scrapy_splash/request.py:41: ScrapyDeprecationWarning: Call to deprecated function to_native_str. Use to_unicode instead.
  url = to_native_str(url)

DEBUG:scrapy.core.engine:Crawled (200) <GET https://groceries.asda.com/product/cornflakes-honey-nut/kelloggs-crunchy-nut-corn-flakes/19140/ via http://0.0.0.0:8050/render.html> (referer: None)
ERROR:scrapy.core.scraper:Error processing {'Carbohydrate': '82g',
 'Date': datetime.datetime(2020, 5, 6, 9, 26, 4, 264682),
 'Energy': '1683kJ',
 'Fat': '4.5g',
 'Fibre': '2.5g',
 'Name': "Kellogg's Crunchy Nut Corn Flakes",
 'Price': '£2.00',
 'Protein': '6g',
 'Salt': '0.75g',
 'Saturates': '0.7g',
 'Sugars': '35g',
 'Supermarket': 'Asda',
 'item_url': 'https://groceries.asda.com/product/cornflakes-honey-nut/kelloggs-crunchy-nut-corn-flakes/19140/'}
Traceback (most recent call last):
  File "/home/user/.local/lib/python3.6/site-packages/sqlalchemy/engine/base.py", line 1248, in _execute_context
    cursor, statement, parameters, context
  File "/home/user/.local/lib/python3.6/site-packages/sqlalchemy/engine/default.py", line 590, in do_execute
    cursor.execute(statement, parameters)
  File "/home/user/.local/lib/python3.6/site-packages/MySQLdb/cursors.py", line 209, in execute
    res = self._query(query)
  File "/home/user/.local/lib/python3.6/site-packages/MySQLdb/cursors.py", line 315, in _query
    db.query(q)
  File "/home/user/.local/lib/python3.6/site-packages/MySQLdb/connections.py", line 239, in query
    _mysql.connection.query(self, query)
MySQLdb._exceptions.OperationalError: (1048, "Column 'name' cannot be null")

The above exception was the direct cause of the following exception:

Traceback (most recent call last):
  File "/home/user/.local/lib/python3.6/site-packages/twisted/internet/defer.py", line 654, in _runCallbacks
    current.result = callback(current.result, *args, **kw)
  File "/home/user/.local/lib/python3.6/site-packages/scrapy/utils/defer.py", line 154, in f
    return deferred_from_coro(coro_f(*coro_args, **coro_kwargs))
  File "/home/user/Documents/PythonScripts/shopscrap/shopscrap/pipelines.py", line 100, in process_item
    session.flush()
  File "/home/user/.local/lib/python3.6/site-packages/sqlalchemy/orm/session.py", line 2496, in flush
    self._flush(objects)
  File "/home/user/.local/lib/python3.6/site-packages/sqlalchemy/orm/session.py", line 2637, in _flush
    transaction.rollback(_capture_exception=True)
  File "/home/user/.local/lib/python3.6/site-packages/sqlalchemy/util/langhelpers.py", line 69, in __exit__
    exc_value, with_traceback=exc_tb,
  File "/home/user/.local/lib/python3.6/site-packages/sqlalchemy/util/compat.py", line 178, in raise_
    raise exception
  File "/home/user/.local/lib/python3.6/site-packages/sqlalchemy/orm/session.py", line 2597, in _flush
    flush_context.execute()
  File "/home/user/.local/lib/python3.6/site-packages/sqlalchemy/orm/unitofwork.py", line 422, in execute
    rec.execute(self)
  File "/home/user/.local/lib/python3.6/site-packages/sqlalchemy/orm/unitofwork.py", line 589, in execute
    uow,
  File "/home/user/.local/lib/python3.6/site-packages/sqlalchemy/orm/persistence.py", line 245, in save_obj
    insert,
  File "/home/user/.local/lib/python3.6/site-packages/sqlalchemy/orm/persistence.py", line 1136, in _emit_insert_statements
    statement, params
  File "/home/user/.local/lib/python3.6/site-packages/sqlalchemy/engine/base.py", line 984, in execute
    return meth(self, multiparams, params)
  File "/home/user/.local/lib/python3.6/site-packages/sqlalchemy/sql/elements.py", line 293, in _execute_on_connection
    return connection._execute_clauseelement(self, multiparams, params)
  File "/home/user/.local/lib/python3.6/site-packages/sqlalchemy/engine/base.py", line 1103, in _execute_clauseelement
    distilled_params,
  File "/home/user/.local/lib/python3.6/site-packages/sqlalchemy/engine/base.py", line 1288, in _execute_context
    e, statement, parameters, cursor, context
  File "/home/user/.local/lib/python3.6/site-packages/sqlalchemy/engine/base.py", line 1482, in _handle_dbapi_exception
    sqlalchemy_exception, with_traceback=exc_info[2], from_=e
  File "/home/user/.local/lib/python3.6/site-packages/sqlalchemy/util/compat.py", line 178, in raise_
    raise exception
  File "/home/user/.local/lib/python3.6/site-packages/sqlalchemy/engine/base.py", line 1248, in _execute_context
    cursor, statement, parameters, context
  File "/home/user/.local/lib/python3.6/site-packages/sqlalchemy/engine/default.py", line 590, in do_execute
    cursor.execute(statement, parameters)
  File "/home/user/.local/lib/python3.6/site-packages/MySQLdb/cursors.py", line 209, in execute
    res = self._query(query)
  File "/home/user/.local/lib/python3.6/site-packages/MySQLdb/cursors.py", line 315, in _query
    db.query(q)
  File "/home/user/.local/lib/python3.6/site-packages/MySQLdb/connections.py", line 239, in query
    _mysql.connection.query(self, query)
sqlalchemy.exc.OperationalError: (MySQLdb._exceptions.OperationalError) (1048, "Column 'name' cannot be null")
[SQL: INSERT INTO stock (name, energy, carbohydrates, sugars, fats, saturates, protein, fibre, salt) VALUES (%s, %s, %s, %s, %s, %s, %s, %s, %s)]
[parameters: (None, None, None, None, None, None, None, None, None)]
(Background on this error at: http://sqlalche.me/e/e3q8)
INFO:scrapy.crawler:Received SIGINT, shutting down gracefully. Send again to force 
INFO:scrapy.core.engine:Closing spider (shutdown)
INFO:scrapy.crawler:Received SIGINT twice, forcing unclean shutdown
DEBUG:scrapy.downloadermiddlewares.retry:Retrying <GET https://groceries.asda.com/product/910000396129 via http://0.0.0.0:8050/render.html> (failed 1 times): [<twisted.python.failure.Failure twisted.internet.error.ConnectionLost: Connection to the other side was lost in a non-clean fashion: Connection lost.>]
DEBUG:scrapy.downloadermiddlewares.retry:Retrying <GET https://groceries.asda.com/product/25857 via http://0.0.0.0:8050/render.html> (failed 1 times): [<twisted.python.failure.Failure twisted.internet.error.ConnectionLost: Connection to the other side was lost in a non-clean fashion: Connection lost.>]
DEBUG:scrapy.downloadermiddlewares.retry:Retrying <GET https://groceries.asda.com/product/80975593 via http://0.0.0.0:8050/render.html> (failed 1 times): [<twisted.python.failure.Failure twisted.internet.error.ConnectionLost: Connection to the other side was lost in a non-clean fashion: Connection lost.>]
DEBUG:scrapy.downloadermiddlewares.retry:Retrying <GET https://groceries.asda.com/product/910000020309 via http://0.0.0.0:8050/render.html> (failed 1 times): [<twisted.python.failure.Failure twisted.internet.error.ConnectionLost: Connection to the other side was lost in a non-clean fashion: Connection lost.>]
DEBUG:scrapy.downloadermiddlewares.retry:Retrying <GET https://groceries.asda.com/product/1217550 via http://0.0.0.0:8050/render.html> (failed 1 times): [<twisted.python.failure.Failure twisted.internet.error.ConnectionLost: Connection to the other side was lost in a non-clean fashion: Connection lost.>]
DEBUG:scrapy.downloadermiddlewares.retry:Retrying <GET https://groceries.asda.com/product/910000057722 via http://0.0.0.0:8050/render.html> (failed 1 times): [<twisted.python.failure.Failure twisted.internet.error.ConnectionLost: Connection to the other side was lost in a non-clean fashion: Connection lost.>]
DEBUG:scrapy.downloadermiddlewares.retry:Retrying <GET https://groceries.asda.com/product/24076 via http://0.0.0.0:8050/render.html> (failed 1 times): [<twisted.python.failure.Failure twisted.internet.error.ConnectionLost: Connection to the other side was lost in a non-clean fashion: Connection lost.>]
DEBUG:scrapy.downloadermiddlewares.retry:Retrying <GET https://groceries.asda.com/product/1639642 via http://0.0.0.0:8050/render.html> (failed 1 times): [<twisted.python.failure.Failure twisted.internet.error.ConnectionLost: Connection to the other side was lost in a non-clean fashion: Connection lost.>]
